Workbook

Sheet INDICADORES
A2: INDICADORES DE ACCIDENTABILIDAD | F2: Acumulado | I2: Acumulado | L2: Acumulado | O2: Acumulado | AV2: OBJETIVO 2024
C3: ENERO | F3: FEBRERO | I3: MARZO | L3: ABRIL | O3: MAYO | R3: JUNIO | U3: JULIO | X3: AGOSTO | AA3: SEPTIEMBRE | AD3: OCTUBRE | AG3: NOVIEMBRE | AJ3: DICIEMBRE | AN3: OBJETIVOS 2024 | AR3: RESULTADO 2023 | AV3: IF | AZ3: IS | BD3: TIR
A4: SOCIEDAD | B4: PLANTAS | C4: IF | D4: IS | E4: TIR | F4: IF | G4: IS | H4: TIR | I4: IF | J4: IS | K4: TIR | L4: IF | M4: IS | N4: TIR | O4: IF | P4: IS | Q4: TIR | R4: IF | S4: IS | T4: TIR | U4: IF | V4: IS | W4: TIR | X4: IF | Y4: IS | Z4: TIR | AA4: IF | AB4: IS | AC4: TIR | AD4: IF | AE4: IS | AF4: TIR | AG4: IF | AH4: IS | AI4: TIR | AJ4: IF | AK4: IS | AL4: TIR | AN4: IF | AO4: IS | AP4: TIR | AR4: IF | AS4: IS | AT4: TIR | AV4: MAX | AW4: ESP. | AX4: MIN | AZ4: MAX | BA4: ESP. | BB4: MIN | BD4: MAX | BE4: ESP. | BF4: MIN
A5: ALICORP SAA | B5: MOL. FAUCETT | C5: =(ACCIDENTES!C5/HH!F5)*1000000 -> 0 | D5: =(ACCIDENTES!D5/HH!F5)*1000000 -> 0 | E5: =(ACCIDENTES!F5/HH!F5)*1000000 -> 0 | F5: =((ACCIDENTES!C5+ACCIDENTES!H5)/(HH!F5+HH!J5))*1000000 -> 0 | G5: =((ACCIDENTES!D5+ACCIDENTES!I5)/(HH!F5+HH!J5))*1000000 -> 0 | H5: =((ACCIDENTES!F5+ACCIDENTES!K5)/(HH!F5+HH!J5))*1000000 -> 0 | I5: =((ACCIDENTES!C5+ACCIDENTES!H5+ACCIDENTES!M5)/(HH!F5+HH!J5+HH!N5))*1000000 -> 0 | J5: =((ACCIDENTES!D5+ACCIDENTES!I5+ACCIDENTES!N5)/(HH!F5+HH!J5+HH!N5))*1000000 -> 0 | K5: =((ACCIDENTES!F5+ACCIDENTES!K5+ACCIDENTES!P5)/(HH!J5+HH!N5+HH!F5))*1000000 -> 0 | L5: =((ACCIDENTES!C5+ACCIDENTES!H5+ACCIDENTES!M5+ACCIDENTES!R5)/(HH!F5+HH!J5+HH!N5+HH!R5))*1000000 -> 0 | M5: =((ACCIDENTES!D5+ACCIDENTES!I5+ACCIDENTES!N5+ACCIDENTES!S5)/(HH!F5+HH!J5+HH!N5+HH!R5))*1000000 -> 0 | N5: =((ACCIDENTES!F5+ACCIDENTES!K5+ACCIDENTES!P5+ACCIDENTES!U5)/(HH!F5+HH!J5+HH!N5+HH!R5))*1000000 -> 0 | O5: =((ACCIDENTES!C5+ACCIDENTES!H5+ACCIDENTES!M5+ACCIDENTES!R5+ACCIDENTES!W5)/(HH!F5+HH!J5+HH!N5+HH!R5+HH!V5))*1000000 -> 5.3313145 | P5: =(((ACCIDENTES!D5+ACCIDENTES!I5+ACCIDENTES!N5+ACCIDENTES!S5+ACCIDENTES!X5)/(HH!F5+HH!J5+HH!N5+HH!R5+HH!V5))*1000000) -> 5.3313145 | Q5: =((ACCIDENTES!F5+ACCIDENTES!K5+ACCIDENTES!P5+ACCIDENTES!U5+ACCIDENTES!Z5)/(HH!F5+HH!J5+HH!N5+HH!R5+HH!V5))*1000000 -> 5.3313145 | R5: =(ACCIDENTES!C5+ACCIDENTES!H5+ACCIDENTES!M5+ACCIDENTES!R5+ACCIDENTES!W5+ACCIDENTES!AB5)*1000000/(HH!F5+HH!J5+HH!N5+HH!R5+HH!V5+HH!Z5) -> 4.4452446 | S5: =(ACCIDENTES!D5+ACCIDENTES!I5+ACCIDENTES!N5+ACCIDENTES!S5+ACCIDENTES!X5+ACCIDENTES!AC5)*1000000/(HH!F5+HH!J5+HH!N5+HH!R5+HH!V5+HH!Z5) -> 4.4452446 | T5: =(ACCIDENTES!F5+ACCIDENTES!K5+ACCIDENTES!P5+ACCIDENTES!U5+ACCIDENTES!Z5+ACCIDENTES!AE5)*1000000/(HH!F5+HH!J5+HH!N5+HH!R5+HH!V5+HH!Z5) -> 4.4452446 | U5: =((ACCIDENTES!C5+ACCIDENTES!H5+ACCIDENTES!M5+ACCIDENTES!R5+ACCIDENTES!W5+ACCIDENTES!AB5+ACCIDENTES!AG5)/(HH!F5+HH!J5+HH!N5+HH!R5+HH!V5+HH!Z5+HH!AD5))*1000000 -> 3.8092263 | V5: =((ACCIDENTES!D5+ACCIDENTES!I5+ACCIDENTES!N5+ACCIDENTES!S5+ACCIDENTES!X5+ACCIDENTES!AC5+ACCIDENTES!AH5)/(HH!F5+HH!J5+HH!N5+HH!R5+HH!V5+HH!Z5+HH!AD5))*1000000 -> 3.8092263 | W5: =((ACCIDENTES!F5+ACCIDENTES!K5+ACCIDENTES!P5+ACCIDENTES!U5+ACCIDENTES!Z5+ACCIDENTES!AE5+ACCIDENTES!AJ5)/(HH!F5+HH!J5+HH!N5+HH!R5+HH!V5+HH!Z5+HH!AD5))*1000000 -> 3.8092263 | X5: =((ACCIDENTES!C5+ACCIDENTES!H5+ACCIDENTES!M5+ACCIDENTES!R5+ACCIDENTES!W5+ACCIDENTES!AB5+ACCIDENTES!AG5+ACCIDENTES!AL5)/(HH!F5+HH!J5+HH!N5+HH!R5+HH!V5+HH!Z5+HH!AD5+HH!AH5))*1000000 -> 3.3293991 | Y5: =((ACCIDENTES!D5+ACCIDENTES!I5+ACCIDENTES!N5+ACCIDENTES!S5+ACCIDENTES!X5+ACCIDENTES!AC5+ACCIDENTES!AH5+ACCIDENTES!AM5)/(HH!F5+HH!J5+HH!N5+HH!R5+HH!V5+HH!Z5+HH!AD5+HH!AH5))*1000000 -> 3.3293991 | Z5: =((ACCIDENTES!F5+ACCIDENTES!K5+ACCIDENTES!P5+ACCIDENTES!U5+ACCIDENTES!Z5+ACCIDENTES!AE5+ACCIDENTES!AJ5+ACCIDENTES!AO5)/(HH!F5+HH!J5+HH!N5+HH!R5+HH!V5+HH!Z5+HH!AD5+HH!AH5))*1000000 -> 3.3293991 | AA5: =((ACCIDENTES!AQ5+ACCIDENTES!AL5+ACCIDENTES!AG5+ACCIDENTES!AB5+ACCIDENTES!W5+ACCIDENTES!R5+ACCIDENTES!M5+ACCIDENTES!H5+ACCIDENTES!C5)/(HH!AL5+HH!AH5+HH!AD5+HH!Z5+HH!V5+HH!R5+HH!N5+HH!J5+HH!F5))*1000000 -> 2.9500396 | AB5: =((ACCIDENTES!AR5+ACCIDENTES!AM5+ACCIDENTES!AH5+ACCIDENTES!AC5+ACCIDENTES!X5+ACCIDENTES!S5+ACCIDENTES!N5+ACCIDENTES!I5+ACCIDENTES!D5)/(HH!AL5+HH!AH5+HH!AD5+HH!Z5+HH!V5+HH!R5+HH!N5+HH!J5+HH!F5))*1000000 -> 2.9500396 | AC5: =((ACCIDENTES!F5+ACCIDENTES!K5+ACCIDENTES!P5+ACCIDENTES!U5+ACCIDENTES!Z5+ACCIDENTES!AE5+ACCIDENTES!AJ5+ACCIDENTES!AO5+ACCIDENTES!AT5)/(HH!F5+HH!J5+HH!N5+HH!R5+HH!V5+HH!Z5+HH!AD5+HH!AH5+HH!AL5))*1000000 -> 2.9500396 | AD5: =((ACCIDENTES!AV5+ACCIDENTES!AQ5+ACCIDENTES!AL5+ACCIDENTES!AG5+ACCIDENTES!AB5+ACCIDENTES!W5+ACCIDENTES!R5+ACCIDENTES!M5+ACCIDENTES!H5+ACCIDENTES!C5)/(HH!F5+HH!J5+HH!N5+HH!R5+HH!V5+HH!Z5+HH!AD5+HH!AH5+HH!AL5+HH!AP5))*1000000 -> 2.642542 | AE5: =((ACCIDENTES!D5+ACCIDENTES!I5+ACCIDENTES!N5+ACCIDENTES!S5+ACCIDENTES!X5+ACCIDENTES!AC5+ACCIDENTES!AH5+ACCIDENTES!AM5+ACCIDENTES!AR5+ACCIDENTES!AW5)/(HH!AP5+HH!AL5+HH!AH5+HH!AD5+HH!Z5+HH!V5+HH!R5+HH!N5+HH!J5+HH!F5))*1000000 -> 2.642542 | AF5: =((ACCIDENTES!AY5+ACCIDENTES!AT5+ACCIDENTES!AO5+ACCIDENTES!AJ5+ACCIDENTES!AE5+ACCIDENTES!Z5+ACCIDENTES!U5+ACCIDENTES!P5+ACCIDENTES!K5+ACCIDENTES!F5)/(HH!F5+HH!J5+HH!N5+HH!R5+HH!V5+HH!Z5+HH!AD5+HH!AH5+HH!AL5+HH!AP5))*1000000 -> 2.642542 | AG5: =((ACCIDENTES!BA5+ACCIDENTES!AV5+ACCIDENTES!AQ5+ACCIDENTES!AL5+ACCIDENTES!AG5+ACCIDENTES!AB5+ACCIDENTES!W5+ACCIDENTES!R5+ACCIDENTES!M5+ACCIDENTES!H5+ACCIDENTES!C5)/(HH!AT5+HH!AP5+HH!AL5+HH!AH5+HH!AD5+HH!Z5+HH!V5+HH!R5+HH!N5+HH!J5+HH!F5))*1000000 -> 2.5192693 | AH5: =((ACCIDENTES!D5+ACCIDENTES!I5+ACCIDENTES!N5+ACCIDENTES!S5+ACCIDENTES!X5+ACCIDENTES!AC5+ACCIDENTES!AH5+ACCIDENTES!AM5+ACCIDENTES!AR5+ACCIDENTES!AW5+ACCIDENTES!BB5)/(HH!F5+HH!J5+HH!N5+HH!R5+HH!V5+HH!Z5+HH!AD5+HH!AH5+HH!AL5+HH!AP5+HH!AT5))*1000000 -> 2.5192693 | AI5: =((ACCIDENTES!BD5+ACCIDENTES!AY5+ACCIDENTES!AT5+ACCIDENTES!AO5+ACCIDENTES!AJ5+ACCIDENTES!AE5+ACCIDENTES!Z5+ACCIDENTES!U5+ACCIDENTES!P5+ACCIDENTES!K5+ACCIDENTES!F5)/(HH!F5+HH!J5+HH!N5+HH!R5+HH!V5+HH!Z5+HH!AD5+HH!AH5+HH!AL5+HH!AP5+HH!AT5))*1000000 -> 2.5192693 | AJ5: =(ACCIDENTES!BK5/HH!BB5)*1000000 -> 2.2915519 | AK5: =(ACCIDENTES!BL5/HH!BB5)*1000000 -> 2.2915519 | AL5: =(ACCIDENTES!BN5/HH!BB5)*1000000 -> 2.2915519 | AN5: =AW5 -> 6.7726259 | AO5: =BA5 -> 169.31565 | AR5: 9.6751799 | AS5: 2875.9472 | AT5: 2.9 | AV5: 5.805108 | AW5: 6.7726259 | AX5: 7.7401439 | AZ5: 145.1277 | BA5: 169.31565 | BB5: 193.5036
A6: ALICORP SAA | B6: MOL. CALLAO | C6: =(ACCIDENTES!C6/HH!F6)*1000000 -> 0 | D6: =(ACCIDENTES!D6/HH!F6)*1000000 -> 0 | E6: =(ACCIDENTES!F6/HH!F6)*1000000 -> 0 | F6: =((ACCIDENTES!C6+ACCIDENTES!H6)/(HH!F6+HH!J6))*1000000 -> 0 | G6: =((ACCIDENTES!D6+ACCIDENTES!I6)/(HH!F6+HH!J6))*1000000 -> 0 | H6: =((ACCIDENTES!F6+ACCIDENTES!K6)/(HH!F6+HH!J6))*1000000 -> 0 | I6: =((ACCIDENTES!C6+ACCIDENTES!H6+ACCIDENTES!M6)/(HH!F6+HH!J6+HH!N6))*1000000 -> 0 | J6: =((ACCIDENTES!D6+ACCIDENTES!I6+ACCIDENTES!N6)/(HH!F6+HH!J6+HH!N6))*1000000 -> 0 | K6: =((ACCIDENTES!F6+ACCIDENTES!K6+ACCIDENTES!P6)/(HH!J6+HH!N6+HH!F6))*1000000 -> 0 | L6: =((ACCIDENTES!C6+ACCIDENTES!H6+ACCIDENTES!M6+ACCIDENTES!R6)/(HH!F6+HH!J6+HH!N6+HH!R6))*1000000 -> 0 | M6: =((ACCIDENTES!D6+ACCIDENTES!I6+ACCIDENTES!N6+ACCIDENTES!S6)/(HH!F6+HH!J6+HH!N6+HH!R6))*1000000 -> 0 | N6: =((ACCIDENTES!F6+ACCIDENTES!K6+ACCIDENTES!P6+ACCIDENTES!U6)/(HH!F6+HH!J6+HH!N6+HH!R6))*1000000 -> 5.5433909 | O6: =((ACCIDENTES!C6+ACCIDENTES!H6+ACCIDENTES!M6+ACCIDENTES!R6+ACCIDENTES!W6)/(HH!F6+HH!J6+HH!N6+HH!R6+HH!V6))*1000000 -> 0 | P6: =(((ACCIDENTES!D6+ACCIDENTES!I6+ACCIDENTES!N6+ACCIDENTES!S6+ACCIDENTES!X6)/(HH!F6+HH!J6+HH!N6+HH!R6+HH!V6))*1000000) -> 0 | Q6: =((ACCIDENTES!F6+ACCIDENTES!K6+ACCIDENTES!P6+ACCIDENTES!U6+ACCIDENTES!Z6)/(HH!F6+HH!J6+HH!N6+HH!R6+HH!V6))*1000000 -> 4.3877161 | R6: =(ACCIDENTES!C6+ACCIDENTES!H6+ACCIDENTES!M6+ACCIDENTES!R6+ACCIDENTES!W6+ACCIDENTES!AB6)*1000000/(HH!F6+HH!J6+HH!N6+HH!R6+HH!V6+HH!Z6) -> 3.6430337 | S6: =(ACCIDENTES!D6+ACCIDENTES!I6+ACCIDENTES!N6+ACCIDENTES!S6+ACCIDENTES!X6+ACCIDENTES!AC6)*1000000/(HH!F6+HH!J6+HH!N6+HH!R6+HH!V6+HH!Z6) -> 94.718876 | T6: =(ACCIDENTES!F6+ACCIDENTES!K6+ACCIDENTES!P6+ACCIDENTES!U6+ACCIDENTES!Z6+ACCIDENTES!AE6)*1000000/(HH!F6+HH!J6+HH!N6+HH!R6+HH!V6+HH!Z6) -> 7.2860674 | U6: =((ACCIDENTES!C6+ACCIDENTES!H6+ACCIDENTES!M6+ACCIDENTES!R6+ACCIDENTES!W6+ACCIDENTES!AB6+ACCIDENTES!AG6)/(HH!F6+HH!J6+HH!N6+HH!R6+HH!V6+HH!Z6+HH!AD6))*1000000 -> 3.1203098 | V6: =((ACCIDENTES!D6+ACCIDENTES!I6+ACCIDENTES!N6+ACCIDENTES!S6+ACCIDENTES!X6+ACCIDENTES!AC6+ACCIDENTES!AH6)/(HH!F6+HH!J6+HH!N6+HH!R6+HH!V6+HH!Z6+HH!AD6))*1000000 -> 81.128054 | W6: =((ACCIDENTES!F6+ACCIDENTES!K6+ACCIDENTES!P6+ACCIDENTES!U6+ACCIDENTES!Z6+ACCIDENTES!AE6+ACCIDENTES!AJ6)/(HH!F6+HH!J6+HH!N6+HH!R6+HH!V6+HH!Z6+HH!AD6))*1000000 -> 6.2406196 | X6: =((ACCIDENTES!C6+ACCIDENTES!H6+ACCIDENTES!M6+ACCIDENTES!R6+ACCIDENTES!W6+ACCIDENTES!AB6+ACCIDENTES!AG6+ACCIDENTES!AL6)/(HH!F6+HH!J6+HH!N6+HH!R6+HH!V6+HH!Z6+HH!AD6+HH!AH6))*1000000 -> 2.7276199 | Y6: =((ACCIDENTES!D6+ACCIDENTES!I6+ACCIDENTES!N6+ACCIDENTES!S6+ACCIDENTES!X6+ACCIDENTES!AC6+ACCIDENTES!AH6+ACCIDENTES!AM6)/(HH!F6+HH!J6+HH!N6+HH!R6+HH!V6+HH!Z6+HH!AD6+HH!AH6))*1000000 -> 70.918117 | Z6: =((ACCIDENTES!F6+ACCIDENTES!K6+ACCIDENTES!P6+ACCIDENTES!U6+ACCIDENTES!Z6+ACCIDENTES!AE6+ACCIDENTES!AJ6+ACCIDENTES!AO6)/(HH!F6+HH!J6+HH!N6+HH!R6+HH!V6+HH!Z6+HH!AD6+HH!AH6))*1000000 -> 8.1828596 | AA6: =((ACCIDENTES!AQ6+ACCIDENTES!AL6+ACCIDENTES!AG6+ACCIDENTES!AB6+ACCIDENTES!W6+ACCIDENTES!R6+ACCIDENTES!M6+ACCIDENTES!H6+ACCIDENTES!C6)/(HH!AL6+HH!AH6+HH!AD6+HH!Z6+HH!V6+HH!R6+HH!N6+HH!J6+HH!F6))*1000000 -> 2.4167038 | AB6: =((ACCIDENTES!AR6+ACCIDENTES!AM6+ACCIDENTES!AH6+ACCIDENTES!AC6+ACCIDENTES!X6+ACCIDENTES!S6+ACCIDENTES!N6+ACCIDENTES!I6+ACCIDENTES!D6)/(HH!AL6+HH!AH6+HH!AD6+HH!Z6+HH!V6+HH!R6+HH!N6+HH!J6+HH!F6))*1000000 -> 62.834298 | AC6: =((ACCIDENTES!F6+ACCIDENTES!K6+ACCIDENTES!P6+ACCIDENTES!U6+ACCIDENTES!Z6+ACCIDENTES!AE6+ACCIDENTES!AJ6+ACCIDENTES!AO6+ACCIDENTES!AT6)/(HH!F6+HH!J6+HH!N6+HH!R6+HH!V6+HH!Z6+HH!AD6+HH!AH6+HH!AL6))*1000000 -> 7.2501113 | AD6: =((ACCIDENTES!AV6+ACCIDENTES!AQ6+ACCIDENTES!AL6+ACCIDENTES!AG6+ACCIDENTES!AB6+ACCIDENTES!W6+ACCIDENTES!R6+ACCIDENTES!M6+ACCIDENTES!H6+ACCIDENTES!C6)/(HH!F6+HH!J6+HH!N6+HH!R6+HH!V6+HH!Z6+HH!AD6+HH!AH6+HH!AL6+HH!AP6))*1000000 -> 2.1645291 | AE6: =((ACCIDENTES!D6+ACCIDENTES!I6+ACCIDENTES!N6+ACCIDENTES!S6+ACCIDENTES!X6+ACCIDENTES!AC6+ACCIDENTES!AH6+ACCIDENTES!AM6+ACCIDENTES!AR6+ACCIDENTES!AW6)/(HH!AP6+HH!AL6+HH!AH6+HH!AD6+HH!Z6+HH!V6+HH!R6+HH!N6+HH!J6+HH!F6))*1000000 -> 56.277757 | AF6: =((ACCIDENTES!AY6+ACCIDENTES!AT6+ACCIDENTES!AO6+ACCIDENTES!AJ6+ACCIDENTES!AE6+ACCIDENTES!Z6+ACCIDENTES!U6+ACCIDENTES!P6+ACCIDENTES!K6+ACCIDENTES!F6)/(HH!F6+HH!J6+HH!N6+HH!R6+HH!V6+HH!Z6+HH!AD6+HH!AH6+HH!AL6+HH!AP6))*1000000 -> 6.4935873 | AG6: =((ACCIDENTES!BA6+ACCIDENTES!AV6+ACCIDENTES!AQ6+ACCIDENTES!AL6+ACCIDENTES!AG6+ACCIDENTES!AB6+ACCIDENTES!W6+ACCIDENTES!R6+ACCIDENTES!M6+ACCIDENTES!H6+ACCIDENTES!C6)/(HH!AT6+HH!AP6+HH!AL6+HH!AH6+HH!AD6+HH!Z6+HH!V6+HH!R6+HH!N6+HH!J6+HH!F6))*1000000 -> 1.9630447 | AH6: =((ACCIDENTES!D6+ACCIDENTES!I6+ACCIDENTES!N6+ACCIDENTES!S6+ACCIDENTES!X6+ACCIDENTES!AC6+ACCIDENTES!AH6+ACCIDENTES!AM6+ACCIDENTES!AR6+ACCIDENTES!AW6+ACCIDENTES!BB6)/(HH!F6+HH!J6+HH!N6+HH!R6+HH!V6+HH!Z6+HH!AD6+HH!AH6+HH!AL6+HH!AP6+HH!AT6))*1000000 -> 51.039162 | AI6: =((ACCIDENTES!BD6+ACCIDENTES!AY6+ACCIDENTES!AT6+ACCIDENTES!AO6+ACCIDENTES!AJ6+ACCIDENTES!AE6+ACCIDENTES!Z6+ACCIDENTES!U6+ACCIDENTES!P6+ACCIDENTES!K6+ACCIDENTES!F6)/(HH!F6+HH!J6+HH!N6+HH!R6+HH!V6+HH!Z6+HH!AD6+HH!AH6+HH!AL6+HH!AP6+HH!AT6))*1000000 -> 7.8521788 | AJ6: =(ACCIDENTES!BK6/HH!BB6)*1000000 -> 1.800031 | AK6: =(ACCIDENTES!BL6/HH!BB6)*1000000 -> 46.800805 | AL6: =(ACCIDENTES!BN6/HH!BB6)*1000000 -> 7.2001238 | AN6: =AW6 -> 13.169767 | AO6: =BA6 -> 147.35403 | AR6: 20.261179 | AS6: 327.86272 | AT6: 4.8 | AV6: 10.13059 | AW6: 13.169767 | AX6: 14.182826 | AZ6: 128.93478 | BA6: 147.35403 | BB6: 165.77329
A7: ALICORP SAA | B7: GALLETERIA&INSTANT. | C7: =(ACCIDENTES!C7/HH!F7)*1000000 -> 0 | D7: =(ACCIDENTES!D7/HH!F7)*1000000 -> 0 | E7: =(ACCIDENTES!F7/HH!F7)*1000000 -> 38.287287 | F7: =((ACCIDENTES!C7+ACCIDENTES!H7)/(HH!F7+HH!J7))*1000000 -> 12.982616 | G7: =((ACCIDENTES!D7+ACCIDENTES!I7)/(HH!F7+HH!J7))*1000000 -> 207.72185 | H7: =((ACCIDENTES!F7+ACCIDENTES!K7)/(HH!F7+HH!J7))*1000000 -> 32.456539 | I7: =((ACCIDENTES!C7+ACCIDENTES!H7+ACCIDENTES!M7)/(HH!F7+HH!J7+HH!N7))*1000000 -> 12.909625 | J7: =((ACCIDENTES!D7+ACCIDENTES!I7+ACCIDENTES!N7)/(HH!F7+HH!J7+HH!N7))*1000000 -> 172.12833 | K7: =((ACCIDENTES!F7+ACCIDENTES!K7+ACCIDENTES!P7)/(HH!J7+HH!N7+HH!F7))*1000000 -> 25.81925 | L7: =((ACCIDENTES!C7+ACCIDENTES!H7+ACCIDENTES!M7+ACCIDENTES!R7)/(HH!F7+HH!J7+HH!N7+HH!R7))*1000000 -> 9.550202 | M7: =((ACCIDENTES!D7+ACCIDENTES!I7+ACCIDENTES!N7+ACCIDENTES!S7)/(HH!F7+HH!J7+HH!N7+HH!R7))*1000000 -> 127.33603 | N7: =((ACCIDENTES!F7+ACCIDENTES!K7+ACCIDENTES!P7+ACCIDENTES!U7)/(HH!F7+HH!J7+HH!N7+HH!R7))*1000000 -> 22.283805 | O7: =((ACCIDENTES!C7+ACCIDENTES!H7+ACCIDENTES!M7+ACCIDENTES!R7+ACCIDENTES!W7)/(HH!F7+HH!J7+HH!N7+HH!R7+HH!V7))*1000000 -> 7.7560569 | P7: =(((ACCIDENTES!D7+ACCIDENTES!I7+ACCIDENTES!N7+ACCIDENTES!S7+ACCIDENTES!X7)/(HH!F7+HH!J7+HH!N7+HH!R7+HH!V7))*1000000) -> 103.41409 | Q7: =((ACCIDENTES!F7+ACCIDENTES!K7+ACCIDENTES!P7+ACCIDENTES!U7+ACCIDENTES!Z7)/(HH!F7+HH!J7+HH!N7+HH!R7+HH!V7))*1000000 -> 20.682818 | R7: =(ACCIDENTES!C7+ACCIDENTES!H7+ACCIDENTES!M7+ACCIDENTES!R7+ACCIDENTES!W7+ACCIDENTES!AB7)*1000000/(HH!F7+HH!J7+HH!N7+HH!R7+HH!V7+HH!Z7) -> 6.5829248 | S7: =(ACCIDENTES!D7+ACCIDENTES!I7+ACCIDENTES!N7+ACCIDENTES!S7+ACCIDENTES!X7+ACCIDENTES!AC7)*1000000/(HH!F7+HH!J7+HH!N7+HH!R7+HH!V7+HH!Z7) -> 87.772331 | T7: =(ACCIDENTES!F7+ACCIDENTES!K7+ACCIDENTES!P7+ACCIDENTES!U7+ACCIDENTES!Z7+ACCIDENTES!AE7)*1000000/(HH!F7+HH!J7+HH!N7+HH!R7+HH!V7+HH!Z7) -> 21.943083 | U7: =((ACCIDENTES!C7+ACCIDENTES!H7+ACCIDENTES!M7+ACCIDENTES!R7+ACCIDENTES!W7+ACCIDENTES!AB7+ACCIDENTES!AG7)/(HH!F7+HH!J7+HH!N7+HH!R7+HH!V7+HH!Z7+HH!AD7))*1000000 -> 5.6781781 | V7: =((ACCIDENTES!D7+ACCIDENTES!I7+ACCIDENTES!N7+ACCIDENTES!S7+ACCIDENTES!X7+ACCIDENTES!AC7+ACCIDENTES!AH7)/(HH!F7+HH!J7+HH!N7+HH!R7+HH!V7+HH!Z7+HH!AD7))*1000000 -> 75.709042 | W7: =((ACCIDENTES!F7+ACCIDENTES!K7+ACCIDENTES!P7+ACCIDENTES!U7+ACCIDENTES!Z7+ACCIDENTES!AE7+ACCIDENTES!AJ7)/(HH!F7+HH!J7+HH!N7+HH!R7+HH!V7+HH!Z7+HH!AD7))*1000000 -> 20.819986 | X7: =((ACCIDENTES!C7+ACCIDENTES!H7+ACCIDENTES!M7+ACCIDENTES!R7+ACCIDENTES!W7+ACCIDENTES!AB7+ACCIDENTES!AG7+ACCIDENTES!AL7)/(HH!F7+HH!J7+HH!N7+HH!R7+HH!V7+HH!Z7+HH!AD7+HH!AH7))*1000000 -> 4.999546 | Y7: =((ACCIDENTES!D7+ACCIDENTES!I7+ACCIDENTES!N7+ACCIDENTES!S7+ACCIDENTES!X7+ACCIDENTES!AC7+ACCIDENTES!AH7+ACCIDENTES!AM7)/(HH!F7+HH!J7+HH!N7+HH!R7+HH!V7+HH!Z7+HH!AD7+HH!AH7))*1000000 -> 66.660614 | Z7: =((ACCIDENTES!F7+ACCIDENTES!K7+ACCIDENTES!P7+ACCIDENTES!U7+ACCIDENTES!Z7+ACCIDENTES!AE7+ACCIDENTES!AJ7+ACCIDENTES!AO7)/(HH!F7+HH!J7+HH!N7+HH!R7+HH!V7+HH!Z7+HH!AD7+HH!AH7))*1000000 -> 21.6647 | AA7: =((ACCIDENTES!AQ7+ACCIDENTES!AL7+ACCIDENTES!AG7+ACCIDENTES!AB7+ACCIDENTES!W7+ACCIDENTES!R7+ACCIDENTES!M7+ACCIDENTES!H7+ACCIDENTES!C7)/(HH!AL7+HH!AH7+HH!AD7+HH!Z7+HH!V7+HH!R7+HH!N7+HH!J7+HH!F7))*1000000 -> 7.3893939 | AB7: =((ACCIDENTES!AR7+ACCIDENTES!AM7+ACCIDENTES!AH7+ACCIDENTES!AC7+ACCIDENTES!X7+ACCIDENTES!S7+ACCIDENTES!N7+ACCIDENTES!I7+ACCIDENTES!D7)/(HH!AL7+HH!AH7+HH!AD7+HH!Z7+HH!V7+HH!R7+HH!N7+HH!J7+HH!F7))*1000000 -> 96.062121 | AC7: =((ACCIDENTES!F7+ACCIDENTES!K7+ACCIDENTES!P7+ACCIDENTES!U7+ACCIDENTES!Z7+ACCIDENTES!AE7+ACCIDENTES!AJ7+ACCIDENTES!AO7+ACCIDENTES!AT7)/(HH!F7+HH!J7+HH!N7+HH!R7+HH!V7+HH!Z7+HH!AD7+HH!AH7+HH!AL7))*1000000 -> 26.601818 | AD7: =((ACCIDENTES!AV7+ACCIDENTES!AQ7+ACCIDENTES!AL7+ACCIDENTES!AG7+ACCIDENTES!AB7+ACCIDENTES!W7+ACCIDENTES!R7+ACCIDENTES!M7+ACCIDENTES!H7+ACCIDENTES!C7)/(HH!F7+HH!J7+HH!N7+HH!R7+HH!V7+HH!Z7+HH!AD7+HH!AH7+HH!AL7+HH!AP7))*1000000 -> 9.3181822 | AE7: =((ACCIDENTES!D7+ACCIDENTES!I7+ACCIDENTES!N7+ACCIDENTES!S7+ACCIDENTES!X7+ACCIDENTES!AC7+ACCIDENTES!AH7+ACCIDENTES!AM7+ACCIDENTES!AR7+ACCIDENTES!AW7)/(HH!AP7+HH!AL7+HH!AH7+HH!AD7+HH!Z7+HH!V7+HH!R7+HH!N7+HH!J7+HH!F7))*1000000 -> 126.46104 | AF7: =((ACCIDENTES!AY7+ACCIDENTES!AT7+ACCIDENTES!AO7+ACCIDENTES!AJ7+ACCIDENTES!AE7+ACCIDENTES!Z7+ACCIDENTES!U7+ACCIDENTES!P7+ACCIDENTES!K7+ACCIDENTES!F7)/(HH!F7+HH!J7+HH!N7+HH!R7+HH!V7+HH!Z7+HH!AD7+HH!AH7+HH!AL7+HH!AP7))*1000000 -> 30.616884 | AG7: =((ACCIDENTES!BA7+ACCIDENTES!AV7+ACCIDENTES!AQ7+ACCIDENTES!AL7+ACCIDENTES!AG7+ACCIDENTES!AB7+ACCIDENTES!W7+ACCIDENTES!R7+ACCIDENTES!M7+ACCIDENTES!H7+ACCIDENTES!C7)/(HH!AT7+HH!AP7+HH!AL7+HH!AH7+HH!AD7+HH!Z7+HH!V7+HH!R7+HH!N7+HH!J7+HH!F7))*1000000 -> 8.4877963 | AH7: =((ACCIDENTES!D7+ACCIDENTES!I7+ACCIDENTES!N7+ACCIDENTES!S7+ACCIDENTES!X7+ACCIDENTES!AC7+ACCIDENTES!AH7+ACCIDENTES!AM7+ACCIDENTES!AR7+ACCIDENTES!AW7+ACCIDENTES!BB7)/(HH!F7+HH!J7+HH!N7+HH!R7+HH!V7+HH!Z7+HH!AD7+HH!AH7+HH!AL7+HH!AP7+HH!AT7))*1000000 -> 115.19152 | AI7: =((ACCIDENTES!BD7+ACCIDENTES!AY7+ACCIDENTES!AT7+ACCIDENTES!AO7+ACCIDENTES!AJ7+ACCIDENTES!AE7+ACCIDENTES!Z7+ACCIDENTES!U7+ACCIDENTES!P7+ACCIDENTES!K7+ACCIDENTES!F7)/(HH!F7+HH!J7+HH!N7+HH!R7+HH!V7+HH!Z7+HH!AD7+HH!AH7+HH!AL7+HH!AP7+HH!AT7))*1000000 -> 29.101016 | AJ7: =(ACCIDENTES!BK7/HH!BB7)*1000000 -> 7.9250384 | AK7: =(ACCIDENTES!BL7/HH!BB7)*1000000 -> 107.55409 | AL7: =(ACCIDENTES!BN7/HH!BB7)*1000000 -> 28.303708 | AN7: =AW7 -> 7.8338549 | AO7: =BA7 -> 44.866623 | AR7: 11.191221 | AS7: un | AT7: 3.3 | AV7: 6.7147328 | AW7: 7.8338549 | AX7: 8.952977 | AZ7: 38.457106 | BA7: 44.866623 | BB7: 51.276141
A8: ALICORP SAA | B8: FIDEERIA LIMA | C8: =(ACCIDENTES!C8/HH!F8)*1000000 -> 0 | D8: =(ACCIDENTES!D8/HH!F8)*1000000 -> 0 | E8: =(ACCIDENTES!F8/HH!F8)*1000000 -> 0 | F8: =((ACCIDENTES!C8+ACCIDENTES!H8)/(HH!F8+HH!J8))*1000000 -> 0 | G8: =((ACCIDENTES!D8+ACCIDENTES!I8)/(HH!F8+HH!J8))*1000000 -> 0 | H8: =((ACCIDENTES!F8+ACCIDENTES!K8)/(HH!F8+HH!J8))*1000000 -> 0 | I8: =((ACCIDENTES!C8+ACCIDENTES!H8+ACCIDENTES!M8)/(HH!F8+HH!J8+HH!N8))*1000000 -> 0 | J8: =((ACCIDENTES!D8+ACCIDENTES!I8+ACCIDENTES!N8)/(HH!F8+HH!J8+HH!N8))*1000000 -> 0 | K8: =((ACCIDENTES!F8+ACCIDENTES!K8+ACCIDENTES!P8)/(HH!J8+HH!N8+HH!F8))*1000000 -> 0 | L8: =((ACCIDENTES!C8+ACCIDENTES!H8+ACCIDENTES!M8+ACCIDENTES!R8)/(HH!F8+HH!J8+HH!N8+HH!R8))*1000000 -> 0 | M8: =((ACCIDENTES!D8+ACCIDENTES!I8+ACCIDENTES!N8+ACCIDENTES!S8)/(HH!F8+HH!J8+HH!N8+HH!R8))*1000000 -> 0 | N8: =((ACCIDENTES!F8+ACCIDENTES!K8+ACCIDENTES!P8+ACCIDENTES!U8)/(HH!F8+HH!J8+HH!N8+HH!R8))*1000000 -> 0 | O8: =((ACCIDENTES!C8+ACCIDENTES!H8+ACCIDENTES!M8+ACCIDENTES!R8+ACCIDENTES!W8)/(HH!F8+HH!J8+HH!N8+HH!R8+HH!V8))*1000000 -> 0 | P8: =(((ACCIDENTES!D8+ACCIDENTES!I8+ACCIDENTES!N8+ACCIDENTES!S8+ACCIDENTES!X8)/(HH!F8+HH!J8+HH!N8+HH!R8+HH!V8))*1000000) -> 0 | Q8: =((ACCIDENTES!F8+ACCIDENTES!K8+ACCIDENTES!P8+ACCIDENTES!U8+ACCIDENTES!Z8)/(HH!F8+HH!J8+HH!N8+HH!R8+HH!V8))*1000000 -> 0 | R8: =(ACCIDENTES!C8+ACCIDENTES!H8+ACCIDENTES!M8+ACCIDENTES!R8+ACCIDENTES!W8+ACCIDENTES!AB8)*1000000/(HH!F8+HH!J8+HH!N8+HH!R8+HH!V8+HH!Z8) -> 0 | S8: =(ACCIDENTES!D8+ACCIDENTES!I8+ACCIDENTES!N8+ACCIDENTES!S8+ACCIDENTES!X8+ACCIDENTES!AC8)*1000000/(HH!F8+HH!J8+HH!N8+HH!R8+HH!V8+HH!Z8) -> 0 | T8: =(ACCIDENTES!F8+ACCIDENTES!K8+ACCIDENTES!P8+ACCIDENTES!U8+ACCIDENTES!Z8+ACCIDENTES!AE8)*1000000/(HH!F8+HH!J8+HH!N8+HH!R8+HH!V8+HH!Z8) -> 0 | U8: =((ACCIDENTES!C8+ACCIDENTES!H8+ACCIDENTES!M8+ACCIDENTES!R8+ACCIDENTES!W8+ACCIDENTES!AB8+ACCIDENTES!AG8)/(HH!F8+HH!J8+HH!N8+HH!R8+HH!V8+HH!Z8+HH!AD8))*1000000 -> 0 | V8: =((ACCIDENTES!D8+ACCIDENTES!I8+ACCIDENTES!N8+ACCIDENTES!S8+ACCIDENTES!X8+ACCIDENTES!AC8+ACCIDENTES!AH8)/(HH!F8+HH!J8+HH!N8+HH!R8+HH!V8+HH!Z8+HH!AD8))*1000000 -> 0 | W8: =((ACCIDENTES!F8+ACCIDENTES!K8+ACCIDENTES!P8+ACCIDENTES!U8+ACCIDENTES!Z8+ACCIDENTES!AE8+ACCIDENTES!AJ8)/(HH!F8+HH!J8+HH!N8+HH!R8+HH!V8+HH!Z8+HH!AD8))*1000000 -> 0 | X8: =((ACCIDENTES!C8+ACCIDENTES!H8+ACCIDENTES!M8+ACCIDENTES!R8+ACCIDENTES!W8+ACCIDENTES!AB8+ACCIDENTES!AG8+ACCIDENTES!AL8)/(HH!F8+HH!J8+HH!N8+HH!R8+HH!V8+HH!Z8+HH!AD8+HH!AH8))*1000000 -> 3.5616024 | Y8: =((ACCIDENTES!D8+ACCIDENTES!I8+ACCIDENTES!N8+ACCIDENTES!S8+ACCIDENTES!X8+ACCIDENTES!AC8+ACCIDENTES!AH8+ACCIDENTES!AM8)/(HH!F8+HH!J8+HH!N8+HH!R8+HH!V8+HH!Z8+HH!AD8+HH!AH8))*1000000 -> 334.79062 | Z8: =((ACCIDENTES!F8+ACCIDENTES!K8+ACCIDENTES!P8+ACCIDENTES!U8+ACCIDENTES!Z8+ACCIDENTES!AE8+ACCIDENTES!AJ8+ACCIDENTES!AO8)/(HH!F8+HH!J8+HH!N8+HH!R8+HH!V8+HH!Z8+HH!AD8+HH!AH8))*1000000 -> 3.5616024 | AA8: =((ACCIDENTES!AQ8+ACCIDENTES!AL8+ACCIDENTES!AG8+ACCIDENTES!AB8+ACCIDENTES!W8+ACCIDENTES!R8+ACCIDENTES!M8+ACCIDENTES!H8+ACCIDENTES!C8)/(HH!AL8+HH!AH8+HH!AD8+HH!Z8+HH!V8+HH!R8+HH!N8+HH!J8+HH!F8))*1000000 -> 3.1662102 | AB8: =((ACCIDENTES!AR8+ACCIDENTES!AM8+ACCIDENTES!AH8+ACCIDENTES!AC8+ACCIDENTES!X8+ACCIDENTES!S8+ACCIDENTES!N8+ACCIDENTES!I8+ACCIDENTES!D8)/(HH!AL8+HH!AH8+HH!AD8+HH!Z8+HH!V8+HH!R8+HH!N8+HH!J8+HH!F8))*1000000 -> 297.62376 | AC8: =((ACCIDENTES!F8+ACCIDENTES!K8+ACCIDENTES!P8+ACCIDENTES!U8+ACCIDENTES!Z8+ACCIDENTES!AE8+ACCIDENTES!AJ8+ACCIDENTES!AO8+ACCIDENTES!AT8)/(HH!F8+HH!J8+HH!N8+HH!R8+HH!V8+HH!Z8+HH!AD8+HH!AH8+HH!AL8))*1000000 -> 3.1662102 | AD8: =((ACCIDENTES!AV8+ACCIDENTES!AQ8+ACCIDENTES!AL8+ACCIDENTES!AG8+ACCIDENTES!AB8+ACCIDENTES!W8+ACCIDENTES!R8+ACCIDENTES!M8+ACCIDENTES!H8+ACCIDENTES!C8)/(HH!F8+HH!J8+HH!N8+HH!R8+HH!V8+HH!Z8+HH!AD8+HH!AH8+HH!AL8+HH!AP8))*1000000 -> 5.6870043 | AE8: =((ACCIDENTES!D8+ACCIDENTES!I8+ACCIDENTES!N8+ACCIDENTES!S8+ACCIDENTES!X8+ACCIDENTES!AC8+ACCIDENTES!AH8+ACCIDENTES!AM8+ACCIDENTES!AR8+ACCIDENTES!AW8)/(HH!AP8+HH!AL8+HH!AH8+HH!AD8+HH!Z8+HH!V8+HH!R8+HH!N8+HH!J8+HH!F8))*1000000 -> 272.97621 | AF8: =((ACCIDENTES!AY8+ACCIDENTES!AT8+ACCIDENTES!AO8+ACCIDENTES!AJ8+ACCIDENTES!AE8+ACCIDENTES!Z8+ACCIDENTES!U8+ACCIDENTES!P8+ACCIDENTES!K8+ACCIDENTES!F8)/(HH!F8+HH!J8+HH!N8+HH!R8+HH!V8+HH!Z8+HH!AD8+HH!AH8+HH!AL8+HH!AP8))*1000000 -> 5.6870043 | AG8: =((ACCIDENTES!BA8+ACCIDENTES!AV8+ACCIDENTES!AQ8+ACCIDENTES!AL8+ACCIDENTES!AG8+ACCIDENTES!AB8+ACCIDENTES!W8+ACCIDENTES!R8+ACCIDENTES!M8+ACCIDENTES!H8+ACCIDENTES!C8)/(HH!AT8+HH!AP8+HH!AL8+HH!AH8+HH!AD8+HH!Z8+HH!V8+HH!R8+HH!N8+HH!J8+HH!F8))*1000000 -> 7.7352183 | AH8: =((ACCIDENTES!D8+ACCIDENTES!I8+ACCIDENTES!N8+ACCIDENTES!S8+ACCIDENTES!X8+ACCIDENTES!AC8+ACCIDENTES!AH8+ACCIDENTES!AM8+ACCIDENTES!AR8+ACCIDENTES!AW8+ACCIDENTES!BB8)/(HH!F8+HH!J8+HH!N8+HH!R8+HH!V8+HH!Z8+HH!AD8+HH!AH8+HH!AL8+HH!AP8+HH!AT8))*1000000 -> 252.6838 | AI8: =((ACCIDENTES!BD8+ACCIDENTES!AY8+ACCIDENTES!AT8+ACCIDENTES!AO8+ACCIDENTES!AJ8+ACCIDENTES!AE8+ACCIDENTES!Z8+ACCIDENTES!U8+ACCIDENTES!P8+ACCIDENTES!K8+ACCIDENTES!F8)/(HH!F8+HH!J8+HH!N8+HH!R8+HH!V8+HH!Z8+HH!AD8+HH!AH8+HH!AL8+HH!AP8+HH!AT8))*1000000 -> 7.7352183 | AJ8: =(ACCIDENTES!BK8/HH!BB8)*1000000 -> 9.523322 | AK8: =(ACCIDENTES!BL8/HH!BB8)*1000000 -> 235.70222 | AL8: =(ACCIDENTES!BN8/HH!BB8)*1000000 -> 9.523322 | AN8: =AW8 -> 0 | AO8: =BA8 -> 0 | AR8: 0 | AS8: 0 | AT8: 0.5 | AV8: 0 | AW8: 0 | AX8: 2.4706816 | AZ8: 0 | BA8: 0 | BB8: 61.76704
A9: ALICORP SAA | B9: COPSA | C9: =(ACCIDENTES!C9/HH!F9)*1000000 -> 6.168845 | D9: =(ACCIDENTES!D9/HH!F9)*1000000 -> 1110.3921 | E9: =(ACCIDENTES!F9/HH!F9)*1000000 -> 6.168845 | F9: =((ACCIDENTES!C9+ACCIDENTES!H9)/(HH!F9+HH!J9))*1000000 -> 3.1556796 | G9: =((ACCIDENTES!D9+ACCIDENTES!I9)/(HH!F9+HH!J9))*1000000 -> 568.02233 | H9: =((ACCIDENTES!F9+ACCIDENTES!K9)/(HH!F9+HH!J9))*1000000 -> 3.1556796 | I9: =((ACCIDENTES!C9+ACCIDENTES!H9+ACCIDENTES!M9)/(HH!F9+HH!J9+HH!N9))*1000000 -> 2.113398 | J9: =((ACCIDENTES!D9+ACCIDENTES!I9+ACCIDENTES!N9)/(HH!F9+HH!J9+HH!N9))*1000000 -> 380.41163 | K9: =((ACCIDENTES!F9+ACCIDENTES!K9+ACCIDENTES!P9)/(HH!J9+HH!N9+HH!F9))*1000000 -> 2.113398 | L9: =((ACCIDENTES!C9+ACCIDENTES!H9+ACCIDENTES!M9+ACCIDENTES!R9)/(HH!F9+HH!J9+HH!N9+HH!R9))*1000000 -> 1.561831 | M9: =((ACCIDENTES!D9+ACCIDENTES!I9+ACCIDENTES!N9+ACCIDENTES!S9)/(HH!F9+HH!J9+HH!N9+HH!R9))*1000000 -> 281.12958 | N9: =((ACCIDENTES!F9+ACCIDENTES!K9+ACCIDENTES!P9+ACCIDENTES!U9)/(HH!F9+HH!J9+HH!N9+HH!R9))*1000000 -> 4.6854929 | O9: =((ACCIDENTES!C9+ACCIDENTES!H9+ACCIDENTES!M9+ACCIDENTES!R9+ACCIDENTES!W9)/(HH!F9+HH!J9+HH!N9+HH!R9+HH!V9))*1000000 -> 1.2359177 | P9: =(((ACCIDENTES!D9+ACCIDENTES!I9+ACCIDENTES!N9+ACCIDENTES!S9+ACCIDENTES!X9)/(HH!F9+HH!J9+HH!N9+HH!R9+HH!V9))*1000000) -> 222.46519 | Q9: =((ACCIDENTES!F9+ACCIDENTES!K9+ACCIDENTES!P9+ACCIDENTES!U9+ACCIDENTES!Z9)/(HH!F9+HH!J9+HH!N9+HH!R9+HH!V9))*1000000 -> 3.7077532 | R9: =(ACCIDENTES!C9+ACCIDENTES!H9+ACCIDENTES!M9+ACCIDENTES!R9+ACCIDENTES!W9+ACCIDENTES!AB9)*1000000/(HH!F9+HH!J9+HH!N9+HH!R9+HH!V9+HH!Z9) -> 1.0301838 | S9: =(ACCIDENTES!D9+ACCIDENTES!I9+ACCIDENTES!N9+ACCIDENTES!S9+ACCIDENTES!X9+ACCIDENTES!AC9)*1000000/(HH!F9+HH!J9+HH!N9+HH!R9+HH!V9+HH!Z9) -> 185.43309 | T9: =(ACCIDENTES!F9+ACCIDENTES!K9+ACCIDENTES!P9+ACCIDENTES!U9+ACCIDENTES!Z9+ACCIDENTES!AE9)*1000000/(HH!F9+HH!J9+HH!N9+HH!R9+HH!V9+HH!Z9) -> 3.0905515 | U9: =((ACCIDENTES!C9+ACCIDENTES!H9+ACCIDENTES!M9+ACCIDENTES!R9+ACCIDENTES!W9+ACCIDENTES!AB9+ACCIDENTES!AG9)/(HH!F9+HH!J9+HH!N9+HH!R9+HH!V9+HH!Z9+HH!AD9))*1000000 -> 0.88413183 | V9: =((ACCIDENTES!D9+ACCIDENTES!I9+ACCIDENTES!N9+ACCIDENTES!S9+ACCIDENTES!X9+ACCIDENTES!AC9+ACCIDENTES!AH9)/(HH!F9+HH!J9+HH!N9+HH!R9+HH!V9+HH!Z9+HH!AD9))*1000000 -> 159.14373 | W9: =((ACCIDENTES!F9+ACCIDENTES!K9+ACCIDENTES!P9+ACCIDENTES!U9+ACCIDENTES!Z9+ACCIDENTES!AE9+ACCIDENTES!AJ9)/(HH!F9+HH!J9+HH!N9+HH!R9+HH!V9+HH!Z9+HH!AD9))*1000000 -> 3.5365273 | X9: =((ACCIDENTES!C9+ACCIDENTES!H9+ACCIDENTES!M9+ACCIDENTES!R9+ACCIDENTES!W9+ACCIDENTES!AB9+ACCIDENTES!AG9+ACCIDENTES!AL9)/(HH!F9+HH!J9+HH!N9+HH!R9+HH!V9+HH!Z9+HH!AD9+HH!AH9))*1000000 -> 1.5491452 | Y9: =((ACCIDENTES!D9+ACCIDENTES!I9+ACCIDENTES!N9+ACCIDENTES!S9+ACCIDENTES!X9+ACCIDENTES!AC9+ACCIDENTES!AH9+ACCIDENTES!AM9)/(HH!F9+HH!J9+HH!N9+HH!R9+HH!V9+HH!Z9+HH!AD9+HH!AH9))*1000000 -> 244.76494 | Z9: =((ACCIDENTES!F9+ACCIDENTES!K9+ACCIDENTES!P9+ACCIDENTES!U9+ACCIDENTES!Z9+ACCIDENTES!AE9+ACCIDENTES!AJ9+ACCIDENTES!AO9)/(HH!F9+HH!J9+HH!N9+HH!R9+HH!V9+HH!Z9+HH!AD9+HH!AH9))*1000000 -> 3.872863 | AA9: =((ACCIDENTES!AQ9+ACCIDENTES!AL9+ACCIDENTES!AG9+ACCIDENTES!AB9+ACCIDENTES!W9+ACCIDENTES!R9+ACCIDENTES!M9+ACCIDENTES!H9+ACCIDENTES!C9)/(HH!AL9+HH!AH9+HH!AD9+HH!Z9+HH!V9+HH!R9+HH!N9+HH!J9+HH!F9))*1000000 -> 4.129047 | AB9: =((ACCIDENTES!AR9+ACCIDENTES!AM9+ACCIDENTES!AH9+ACCIDENTES!AC9+ACCIDENTES!X9+ACCIDENTES!S9+ACCIDENTES!N9+ACCIDENTES!I9+ACCIDENTES!D9)/(HH!AL9+HH!AH9+HH!AD9+HH!Z9+HH!V9+HH!R9+HH!N9+HH!J9+HH!F9))*1000000 -> 227.78576 | AC9: =((ACCIDENTES!F9+ACCIDENTES!K9+ACCIDENTES!P9+ACCIDENTES!U9+ACCIDENTES!Z9+ACCIDENTES!AE9+ACCIDENTES!AJ9+ACCIDENTES!AO9+ACCIDENTES!AT9)/(HH!F9+HH!J9+HH!N9+HH!R9+HH!V9+HH!Z9+HH!AD9+HH!AH9+HH!AL9))*1000000 -> 7.5699196 | AD9: =((ACCIDENTES!AV9+ACCIDENTES!AQ9+ACCIDENTES!AL9+ACCIDENTES!AG9+ACCIDENTES!AB9+ACCIDENTES!W9+ACCIDENTES!R9+ACCIDENTES!M9+ACCIDENTES!H9+ACCIDENTES!C9)/(HH!F9+HH!J9+HH!N9+HH!R9+HH!V9+HH!Z9+HH!AD9+HH!AH9+HH!AL9+HH!AP9))*1000000 -> 4.3202921 | AE9: =((ACCIDENTES!D9+ACCIDENTES!I9+ACCIDENTES!N9+ACCIDENTES!S9+ACCIDENTES!X9+ACCIDENTES!AC9+ACCIDENTES!AH9+ACCIDENTES!AM9+ACCIDENTES!AR9+ACCIDENTES!AW9)/(HH!AP9+HH!AL9+HH!AH9+HH!AD9+HH!Z9+HH!V9+HH!R9+HH!N9+HH!J9+HH!F9))*1000000 -> 209.22558 | AF9: =((ACCIDENTES!AY9+ACCIDENTES!AT9+ACCIDENTES!AO9+ACCIDENTES!AJ9+ACCIDENTES!AE9+ACCIDENTES!Z9+ACCIDENTES!U9+ACCIDENTES!P9+ACCIDENTES!K9+ACCIDENTES!F9)/(HH!F9+HH!J9+HH!N9+HH!R9+HH!V9+HH!Z9+HH!AD9+HH!AH9+HH!AL9+HH!AP9))*1000000 -> 7.4062151 | AG9: =((ACCIDENTES!BA9+ACCIDENTES!AV9+ACCIDENTES!AQ9+ACCIDENTES!AL9+ACCIDENTES!AG9+ACCIDENTES!AB9+ACCIDENTES!W9+ACCIDENTES!R9+ACCIDENTES!M9+ACCIDENTES!H9+ACCIDENTES!C9)/(HH!AT9+HH!AP9+HH!AL9+HH!AH9+HH!AD9+HH!Z9+HH!V9+HH!R9+HH!N9+HH!J9+HH!F9))*1000000 -> 3.920495 | AH9: =((ACCIDENTES!D9+ACCIDENTES!I9+ACCIDENTES!N9+ACCIDENTES!S9+ACCIDENTES!X9+ACCIDENTES!AC9+ACCIDENTES!AH9+ACCIDENTES!AM9+ACCIDENTES!AR9+ACCIDENTES!AW9+ACCIDENTES!BB9)/(HH!F9+HH!J9+HH!N9+HH!R9+HH!V9+HH!Z9+HH!AD9+HH!AH9+HH!AL9+HH!AP9+HH!AT9))*1000000 -> 189.86397 | AI9: =((ACCIDENTES!BD9+ACCIDENTES!AY9+ACCIDENTES!AT9+ACCIDENTES!AO9+ACCIDENTES!AJ9+ACCIDENTES!AE9+ACCIDENTES!Z9+ACCIDENTES!U9+ACCIDENTES!P9+ACCIDENTES!K9+ACCIDENTES!F9)/(HH!F9+HH!J9+HH!N9+HH!R9+HH!V9+HH!Z9+HH!AD9+HH!AH9+HH!AL9+HH!AP9+HH!AT9))*1000000 -> 7.8409901 | AJ9: =(ACCIDENTES!BK9/HH!BB9)*1000000 -> 3.584975 | AK9: =(ACCIDENTES!BL9/HH!BB9)*1000000 -> 173.61522 | AL9: =(ACCIDENTES!BN9/HH!BB9)*1000000 -> 7.6820893 | AN9: =AW9 -> 2.4177655 | AO9: =BA9 -> 20.853227 | AR9: 3.6236357 | AS9: 31.253858 | AT9: 1.3 | AV9: 2.0723704 | AW9: 2.4177655 | AX9: 2.7631606 | AZ9: 17.874195 | BA9: 20.853227 | BB9: 23.83226
A10: ALICORP SAA | B10: DETERGENTES | C10: =(ACCIDENTES!C10/HH!F10)*1000000 -> 28.67548 | D10: =(ACCIDENTES!D10/HH!F10)*1000000 -> 5161.5863 | E10: =(ACCIDENTES!F10/HH!F10)*1000000 -> 28.67548 | F10: =((ACCIDENTES!C10+ACCIDENTES!H10)/(HH!F10+HH!J10))*1000000 -> 14.166112 | G10: =((ACCIDENTES!D10+ACCIDENTES!I10)/(HH!F10+HH!J10))*1000000 -> 2549.9001 | H10: =((ACCIDENTES!F10+ACCIDENTES!K10)/(HH!F10+HH!J10))*1000000 -> 14.166112 | I10: =((ACCIDENTES!C10+ACCIDENTES!H10+ACCIDENTES!M10)/(HH!F10+HH!J10+HH!N10))*1000000 -> 18.585288 | J10: =((ACCIDENTES!D10+ACCIDENTES!I10+ACCIDENTES!N10)/(HH!F10+HH!J10+HH!N10))*1000000 -> 1728.4318 | K10: =((ACCIDENTES!F10+ACCIDENTES!K10+ACCIDENTES!P10)/(HH!J10+HH!N10+HH!F10))*1000000 -> 18.585288 | L10: =((ACCIDENTES!C10+ACCIDENTES!H10+ACCIDENTES!M10+ACCIDENTES!R10)/(HH!F10+HH!J10+HH!N10+HH!R10))*1000000 -> 13.84984 | M10: =((ACCIDENTES!D10+ACCIDENTES!I10+ACCIDENTES!N10+ACCIDENTES!S10)/(HH!F10+HH!J10+HH!N10+HH!R10))*1000000 -> 1288.0351 | N10: =((ACCIDENTES!F10+ACCIDENTES!K10+ACCIDENTES!P10+ACCIDENTES!U10)/(HH!F10+HH!J10+HH!N10+HH!R10))*1000000 -> 20.77476 | O10: =((ACCIDENTES!C10+ACCIDENTES!H10+ACCIDENTES!M10+ACCIDENTES!R10+ACCIDENTES!W10)/(HH!F10+HH!J10+HH!N10+HH!R10+HH!V10))*1000000 -> 11.189719 | P10: =(((ACCIDENTES!D10+ACCIDENTES!I10+ACCIDENTES!N10+ACCIDENTES!S10+ACCIDENTES!X10)/(HH!F10+HH!J10+HH!N10+HH!R10+HH!V10))*1000000) -> 1040.6439 | Q10: =((ACCIDENTES!F10+ACCIDENTES!K10+ACCIDENTES!P10+ACCIDENTES!U10+ACCIDENTES!Z10)/(HH!F10+HH!J10+HH!N10+HH!R10+HH!V10))*1000000 -> 16.784578 | R10: =(ACCIDENTES!C10+ACCIDENTES!H10+ACCIDENTES!M10+ACCIDENTES!R10+ACCIDENTES!W10+ACCIDENTES!AB10)*1000000/(HH!F10+HH!J10+HH!N10+HH!R10+HH!V10+HH!Z10) -> 9.4057008 | S10: =(ACCIDENTES!D10+ACCIDENTES!I10+ACCIDENTES!N10+ACCIDENTES!S10+ACCIDENTES!X10+ACCIDENTES!AC10)*1000000/(HH!F10+HH!J10+HH!N10+HH!R10+HH!V10+HH!Z10) -> 874.73017 | T10: =(ACCIDENTES!F10+ACCIDENTES!K10+ACCIDENTES!P10+ACCIDENTES!U10+ACCIDENTES!Z10+ACCIDENTES!AE10)*1000000/(HH!F10+HH!J10+HH!N10+HH!R10+HH!V10+HH!Z10) -> 14.108551 | U10: =((ACCIDENTES!C10+ACCIDENTES!H10+ACCIDENTES!M10+ACCIDENTES!R10+ACCIDENTES!W10+ACCIDENTES!AB10+ACCIDENTES!AG10)/(HH!F10+HH!J10+HH!N10+HH!R10+HH!V10+HH!Z10+HH!AD10))*1000000 -> 8.0772019 | V10: =((ACCIDENTES!D10+ACCIDENTES!I10+ACCIDENTES!N10+ACCIDENTES!S10+ACCIDENTES!X10+ACCIDENTES!AC10+ACCIDENTES!AH10)/(HH!F10+HH!J10+HH!N10+HH!R10+HH!V10+HH!Z10+HH!AD10))*1000000 -> 751.17978 | W10: =((ACCIDENTES!F10+ACCIDENTES!K10+ACCIDENTES!P10+ACCIDENTES!U10+ACCIDENTES!Z10+ACCIDENTES!AE10+ACCIDENTES!AJ10)/(HH!F10+HH!J10+HH!N10+HH!R10+HH!V10+HH!Z10+HH!AD10))*1000000 -> 12.115803 | X10: =((ACCIDENTES!C10+ACCIDENTES!H10+ACCIDENTES!M10+ACCIDENTES!R10+ACCIDENTES!W10+ACCIDENTES!AB10+ACCIDENTES!AG10+ACCIDENTES!AL10)/(HH!F10+HH!J10+HH!N10+HH!R10+HH!V10+HH!Z10+HH!AD10+HH!AH10))*1000000 -> 7.1067271 | Y10: =((ACCIDENTES!D10+ACCIDENTES!I10+ACCIDENTES!N10+ACCIDENTES!S10+ACCIDENTES!X10+ACCIDENTES!AC10+ACCIDENTES!AH10+ACCIDENTES!AM10)/(HH!F10+HH!J10+HH!N10+HH!R10+HH!V10+HH!Z10+HH!AD10+HH!AH10))*1000000 -> 660.92562 | Z10: =((ACCIDENTES!F10+ACCIDENTES!K10+ACCIDENTES!P10+ACCIDENTES!U10+ACCIDENTES!Z10+ACCIDENTES!AE10+ACCIDENTES!AJ10+ACCIDENTES!AO10)/(HH!F10+HH!J10+HH!N10+HH!R10+HH!V10+HH!Z10+HH!AD10+HH!AH10))*1000000 -> 10.660091 | AA10: =((ACCIDENTES!AQ10+ACCIDENTES!AL10+ACCIDENTES!AG10+ACCIDENTES!AB10+ACCIDENTES!W10+ACCIDENTES!R10+ACCIDENTES!M10+ACCIDENTES!H10+ACCIDENTES!C10)/(HH!AL10+HH!AH10+HH!AD10+HH!Z10+HH!V10+HH!R10+HH!N10+HH!J10+HH!F10))*1000000 -> 6.3459427 | AB10: =((ACCIDENTES!AR10+ACCIDENTES!AM10+ACCIDENTES!AH10+ACCIDENTES!AC10+ACCIDENTES!X10+ACCIDENTES!S10+ACCIDENTES!N10+ACCIDENTES!I10+ACCIDENTES!D10)/(HH!AL10+HH!AH10+HH!AD10+HH!Z10+HH!V10+HH!R10+HH!N10+HH!J10+HH!F10))*1000000 -> 590.17267 | AC10: =((ACCIDENTES!F10+ACCIDENTES!K10+ACCIDENTES!P10+ACCIDENTES!U10+ACCIDENTES!Z10+ACCIDENTES!AE10+ACCIDENTES!AJ10+ACCIDENTES!AO10+ACCIDENTES!AT10)/(HH!F10+HH!J10+HH!N10+HH!R10+HH!V10+HH!Z10+HH!AD10+HH!AH10+HH!AL10))*1000000 -> 9.5189141 | AD10: =((ACCIDENTES!AV10+ACCIDENTES!AQ10+ACCIDENTES!AL10+ACCIDENTES!AG10+ACCIDENTES!AB10+ACCIDENTES!W10+ACCIDENTES!R10+ACCIDENTES!M10+ACCIDENTES!H10+ACCIDENTES!C10)/(HH!F10+HH!J10+HH!N10+HH!R10+HH!V10+HH!Z10+HH!AD10+HH!AH10+HH!AL10+HH!AP10))*1000000 -> 5.6945176 | AE10: =((ACCIDENTES!D10+ACCIDENTES!I10+ACCIDENTES!N10+ACCIDENTES!S10+ACCIDENTES!X10+ACCIDENTES!AC10+ACCIDENTES!AH10+ACCIDENTES!AM10+ACCIDENTES!AR10+ACCIDENTES!AW10)/(HH!AP10+HH!AL10+HH!AH10+HH!AD10+HH!Z10+HH!V10+HH!R10+HH!N10+HH!J10+HH!F10))*1000000 -> 529.59014 | AF10: =((ACCIDENTES!AY10+ACCIDENTES!AT10+ACCIDENTES!AO10+ACCIDENTES!AJ10+ACCIDENTES!AE10+ACCIDENTES!Z10+ACCIDENTES!U10+ACCIDENTES!P10+ACCIDENTES!K10+ACCIDENTES!F10)/(HH!F10+HH!J10+HH!N10+HH!R10+HH!V10+HH!Z10+HH!AD10+HH!AH10+HH!AL10+HH!AP10))*1000000 -> 8.5417764 | AG10: =((ACCIDENTES!BA10+ACCIDENTES!AV10+ACCIDENTES!AQ10+ACCIDENTES!AL10+ACCIDENTES!AG10+ACCIDENTES!AB10+ACCIDENTES!W10+ACCIDENTES!R10+ACCIDENTES!M10+ACCIDENTES!H10+ACCIDENTES!C10)/(HH!AT10+HH!AP10+HH!AL10+HH!AH10+HH!AD10+HH!Z10+HH!V10+HH!R10+HH!N10+HH!J10+HH!F10))*1000000 -> 5.1820318 | AH10: =((ACCIDENTES!D10+ACCIDENTES!I10+ACCIDENTES!N10+ACCIDENTES!S10+ACCIDENTES!X10+ACCIDENTES!AC10+ACCIDENTES!AH10+ACCIDENTES!AM10+ACCIDENTES!AR10+ACCIDENTES!AW10+ACCIDENTES!BB10)/(HH!F10+HH!J10+HH!N10+HH!R10+HH!V10+HH!Z10+HH!AD10+HH!AH10+HH!AL10+HH!AP10+HH!AT10))*1000000 -> 481.92896 | AI10: =((ACCIDENTES!BD10+ACCIDENTES!AY10+ACCIDENTES!AT10+ACCIDENTES!AO10+ACCIDENTES!AJ10+ACCIDENTES!AE10+ACCIDENTES!Z10+ACCIDENTES!U10+ACCIDENTES!P10+ACCIDENTES!K10+ACCIDENTES!F10)/(HH!F10+HH!J10+HH!N10+HH!R10+HH!V10+HH!Z10+HH!AD10+HH!AH10+HH!AL10+HH!AP10+HH!AT10))*1000000 -> 7.7730477 | AJ10: =(ACCIDENTES!BK10/HH!BB10)*1000000 -> 4.7549761 | AK10: =(ACCIDENTES!BL10/HH!BB10)*1000000 -> 442.21278 | AL10: =(ACCIDENTES!BN10/HH!BB10)*1000000 -> 7.1324641 | AN10: =AW10 -> 7.4660139 | AO10: =BA10 -> 99.546852 | AR10: 10.665734 | AS10: 142.20979 | AT10: 2.1 | AV10: 6.3994405 | AW10: 7.4660139 | AX10: 8.5325873 | AZ10: 85.325873 | BA10: 99.546852 | BB10: 113.76783
A11: ALICORP SAA | B11: SIDSUR | C11: =(ACCIDENTES!C11/HH!F11)*1000000 -> 0 | D11: =(ACCIDENTES!D11/HH!F11)*1000000 -> 0 | E11: =(ACCIDENTES!F11/HH!F11)*1000000 -> 0 | F11: =((ACCIDENTES!C11+ACCIDENTES!H11)/(HH!F11+HH!J11))*1000000 -> 0 | G11: =((ACCIDENTES!D11+ACCIDENTES!I11)/(HH!F11+HH!J11))*1000000 -> 0 | H11: =((ACCIDENTES!F11+ACCIDENTES!K11)/(HH!F11+HH!J11))*1000000 -> 0 | I11: =((ACCIDENTES!C11+ACCIDENTES!H11+ACCIDENTES!M11)/(HH!F11+HH!J11+HH!N11))*1000000 -> 0 | J11: =((ACCIDENTES!D11+ACCIDENTES!I11+ACCIDENTES!N11)/(HH!F11+HH!J11+HH!N11))*1000000 -> 0 | K11: =((ACCIDENTES!F11+ACCIDENTES!K11+ACCIDENTES!P11)/(HH!J11+HH!N11+HH!F11))*1000000 -> 26.161163 | L11: =((ACCIDENTES!C11+ACCIDENTES!H11+ACCIDENTES!M11+ACCIDENTES!R11)/(HH!F11+HH!J11+HH!N11+HH!R11))*1000000 -> 3.9100684 | M11: =((ACCIDENTES!D11+ACCIDENTES!I11+ACCIDENTES!N11+ACCIDENTES!S11)/(HH!F11+HH!J11+HH!N11+HH!R11))*1000000 -> 465.29814 | N11: =((ACCIDENTES!F11+ACCIDENTES!K11+ACCIDENTES!P11+ACCIDENTES!U11)/(HH!F11+HH!J11+HH!N11+HH!R11))*1000000 -> 23.460411 | O11: =((ACCIDENTES!C11+ACCIDENTES!H11+ACCIDENTES!M11+ACCIDENTES!R11+ACCIDENTES!W11)/(HH!F11+HH!J11+HH!N11+HH!R11+HH!V11))*1000000 -> 9.3479057 | P11: =(((ACCIDENTES!D11+ACCIDENTES!I11+ACCIDENTES!N11+ACCIDENTES!S11+ACCIDENTES!X11)/(HH!F11+HH!J11+HH!N11+HH!R11+HH!V11))*1000000) -> 414.42382 | Q11: =((ACCIDENTES!F11+ACCIDENTES!K11+ACCIDENTES!P11+ACCIDENTES!U11+ACCIDENTES!Z11)/(HH!F11+HH!J11+HH!N11+HH!R11+HH!V11))*1000000 -> 24.927748 | R11: =(ACCIDENTES!C11+ACCIDENTES!H11+ACCIDENTES!M11+ACCIDENTES!R11+ACCIDENTES!W11+ACCIDENTES!AB11)*1000000/(HH!F11+HH!J11+HH!N11+HH!R11+HH!V11+HH!Z11) -> 7.8560252 | S11: =(ACCIDENTES!D11+ACCIDENTES!I11+ACCIDENTES!N11+ACCIDENTES!S11+ACCIDENTES!X11+ACCIDENTES!AC11)*1000000/(HH!F11+HH!J11+HH!N11+HH!R11+HH!V11+HH!Z11) -> 348.28379 | T11: =(ACCIDENTES!F11+ACCIDENTES!K11+ACCIDENTES!P11+ACCIDENTES!U11+ACCIDENTES!Z11+ACCIDENTES!AE11)*1000000/(HH!F11+HH!J11+HH!N11+HH!R11+HH!V11+HH!Z11) -> 20.949401 | U11: =((ACCIDENTES!C11+ACCIDENTES!H11+ACCIDENTES!M11+ACCIDENTES!R11+ACCIDENTES!W11+ACCIDENTES!AB11+ACCIDENTES!AG11)/(HH!F11+HH!J11+HH!N11+HH!R11+HH!V11+HH!Z11+HH!AD11))*1000000 -> 6.7009757 | V11: =((ACCIDENTES!D11+ACCIDENTES!I11+ACCIDENTES!N11+ACCIDENTES!S11+ACCIDENTES!X11+ACCIDENTES!AC11+ACCIDENTES!AH11)/(HH!F11+HH!J11+HH!N11+HH!R11+HH!V11+HH!Z11+HH!AD11))*1000000 -> 297.07659 | W11: =((ACCIDENTES!F11+ACCIDENTES!K11+ACCIDENTES!P11+ACCIDENTES!U11+ACCIDENTES!Z11+ACCIDENTES!AE11+ACCIDENTES!AJ11)/(HH!F11+HH!J11+HH!N11+HH!R11+HH!V11+HH!Z11+HH!AD11))*1000000 -> 24.570244 | X11: =((ACCIDENTES!C11+ACCIDENTES!H11+ACCIDENTES!M11+ACCIDENTES!R11+ACCIDENTES!W11+ACCIDENTES!AB11+ACCIDENTES!AG11+ACCIDENTES!AL11)/(HH!F11+HH!J11+HH!N11+HH!R11+HH!V11+HH!Z11+HH!AD11+HH!AH11))*1000000 -> 5.8743362 | Y11: =((ACCIDENTES!D11+ACCIDENTES!I11+ACCIDENTES!N11+ACCIDENTES!S11+ACCIDENTES!X11+ACCIDENTES!AC11+ACCIDENTES!AH11+ACCIDENTES!AM11)/(HH!F11+HH!J11+HH!N11+HH!R11+HH!V11+HH!Z11+HH!AD11+HH!AH11))*1000000 -> 260.4289 | Z11: =((ACCIDENTES!F11+ACCIDENTES!K11+ACCIDENTES!P11+ACCIDENTES!U11+ACCIDENTES!Z11+ACCIDENTES!AE11+ACCIDENTES!AJ11+ACCIDENTES!AO11)/(HH!F11+HH!J11+HH!N11+HH!R11+HH!V11+HH!Z11+HH!AD11+HH!AH11))*1000000 -> 23.497345 | AA11: =((ACCIDENTES!AQ11+ACCIDENTES!AL11+ACCIDENTES!AG11+ACCIDENTES!AB11+ACCIDENTES!W11+ACCIDENTES!R11+ACCIDENTES!M11+ACCIDENTES!H11+ACCIDENTES!C11)/(HH!AL11+HH!AH11+HH!AD11+HH!Z11+HH!V11+HH!R11+HH!N11+HH!J11+HH!F11))*1000000 -> 5.203721 | AB11: =((ACCIDENTES!AR11+ACCIDENTES!AM11+ACCIDENTES!AH11+ACCIDENTES!AC11+ACCIDENTES!X11+ACCIDENTES!S11+ACCIDENTES!N11+ACCIDENTES!I11+ACCIDENTES!D11)/(HH!AL11+HH!AH11+HH!AD11+HH!Z11+HH!V11+HH!R11+HH!N11+HH!J11+HH!F11))*1000000 -> 230.6983 | AC11: =((ACCIDENTES!F11+ACCIDENTES!K11+ACCIDENTES!P11+ACCIDENTES!U11+ACCIDENTES!Z11+ACCIDENTES!AE11+ACCIDENTES!AJ11+ACCIDENTES!AO11+ACCIDENTES!AT11)/(HH!F11+HH!J11+HH!N11+HH!R11+HH!V11+HH!Z11+HH!AD11+HH!AH11+HH!AL11))*1000000 -> 20.814884 | AD11: =((ACCIDENTES!AV11+ACCIDENTES!AQ11+ACCIDENTES!AL11+ACCIDENTES!AG11+ACCIDENTES!AB11+ACCIDENTES!W11+ACCIDENTES!R11+ACCIDENTES!M11+ACCIDENTES!H11+ACCIDENTES!C11)/(HH!F11+HH!J11+HH!N11+HH!R11+HH!V11+HH!Z11+HH!AD11+HH!AH11+HH!AL11+HH!AP11))*1000000 -> 4.6728278 | AE11: =((ACCIDENTES!D11+ACCIDENTES!I11+ACCIDENTES!N11+ACCIDENTES!S11+ACCIDENTES!X11+ACCIDENTES!AC11+ACCIDENTES!AH11+ACCIDENTES!AM11+ACCIDENTES!AR11+ACCIDENTES!AW11)/(HH!AP11+HH!AL11+HH!AH11+HH!AD11+HH!Z11+HH!V11+HH!R11+HH!N11+HH!J11+HH!F11))*1000000 -> 207.16203 | AF11: =((ACCIDENTES!AY11+ACCIDENTES!AT11+ACCIDENTES!AO11+ACCIDENTES!AJ11+ACCIDENTES!AE11+ACCIDENTES!Z11+ACCIDENTES!U11+ACCIDENTES!P11+ACCIDENTES!K11+ACCIDENTES!F11)/(HH!F11+HH!J11+HH!N11+HH!R11+HH!V11+HH!Z11+HH!AD11+HH!AH11+HH!AL11+HH!AP11))*1000000 -> 20.24892 | AG11: =((ACCIDENTES!BA11+ACCIDENTES!AV11+ACCIDENTES!AQ11+ACCIDENTES!AL11+ACCIDENTES!AG11+ACCIDENTES!AB11+ACCIDENTES!W11+ACCIDENTES!R11+ACCIDENTES!M11+ACCIDENTES!H11+ACCIDENTES!C11)/(HH!AT11+HH!AP11+HH!AL11+HH!AH11+HH!AD11+HH!Z11+HH!V11+HH!R11+HH!N11+HH!J11+HH!F11))*1000000 -> 4.2546158 | AH11: =((ACCIDENTES!D11+ACCIDENTES!I11+ACCIDENTES!N11+ACCIDENTES!S11+ACCIDENTES!X11+ACCIDENTES!AC11+ACCIDENTES!AH11+ACCIDENTES!AM11+ACCIDENTES!AR11+ACCIDENTES!AW11+ACCIDENTES!BB11)/(HH!F11+HH!J11+HH!N11+HH!R11+HH!V11+HH!Z11+HH!AD11+HH!AH11+HH!AL11+HH!AP11+HH!AT11))*1000000 -> 188.6213 | AI11: =((ACCIDENTES!BD11+ACCIDENTES!AY11+ACCIDENTES!AT11+ACCIDENTES!AO11+ACCIDENTES!AJ11+ACCIDENTES!AE11+ACCIDENTES!Z11+ACCIDENTES!U11+ACCIDENTES!P11+ACCIDENTES!K11+ACCIDENTES!F11)/(HH!F11+HH!J11+HH!N11+HH!R11+HH!V11+HH!Z11+HH!AD11+HH!AH11+HH!AL11+HH!AP11+HH!AT11))*1000000 -> 19.854874 | AJ11: =(ACCIDENTES!BK11/HH!BB11)*1000000 -> 3.9318117 | AK11: =(ACCIDENTES!BL11/HH!BB11)*1000000 -> 174.31032 | AL11: =(ACCIDENTES!BN11/HH!BB11)*1000000 -> 18.348455 | AN11: =AW11 -> 3.9376626 | AO11: =BA11 -> 88.597409 | AR11: 5.6252323 | AS11: 198.28944 | AT11: 1.1 | AV11: 3.3751394 | AW11: 3.9376626 | AX11: 4.5001859 | AZ11: 75.940637 | BA11: 88.597409 | BB11: 101.25418
A12: ALICORP SAA | B12: MANUFACTURA ALICORP | C12: =(ACCIDENTES!C12/HH!F12)*1000000 -> 4.3808531 | D12: =(ACCIDENTES!D12/HH!F12)*1000000 -> 788.55355 | E12: =(ACCIDENTES!F12/HH!F12)*1000000 -> 10.952133 | F12: =((ACCIDENTES!C12+ACCIDENTES!H12)/(HH!F12+HH!J12))*1000000 -> 4.4485875 | G12: =((ACCIDENTES!D12+ACCIDENTES!I12)/(HH!F12+HH!J12))*1000000 -> 435.96158 | H12: =((ACCIDENTES!F12+ACCIDENTES!K12)/(HH!F12+HH!J12))*1000000 -> 7.7850281 | I12: =((ACCIDENTES!C12+ACCIDENTES!H12+ACCIDENTES!M12)/(HH!F12+HH!J12+HH!N12))*1000000 -> 4.4390487 | J12: =((ACCIDENTES!D12+ACCIDENTES!I12+ACCIDENTES!N12)/(HH!F12+HH!J12+HH!N12))*1000000 -> 300.37563 | K12: =((ACCIDENTES!F12+ACCIDENTES!K12+ACCIDENTES!P12)/(HH!J12+HH!N12+HH!F12))*1000000 -> 10.35778 | L12: =((ACCIDENTES!C12+ACCIDENTES!H12+ACCIDENTES!M12+ACCIDENTES!R12)/(HH!F12+HH!J12+HH!N12+HH!R12))*1000000 -> 3.8410536 | M12: =((ACCIDENTES!D12+ACCIDENTES!I12+ACCIDENTES!N12+ACCIDENTES!S12)/(HH!F12+HH!J12+HH!N12+HH!R12))*1000000 -> 288.07902 | N12: =((ACCIDENTES!F12+ACCIDENTES!K12+ACCIDENTES!P12+ACCIDENTES!U12)/(HH!F12+HH!J12+HH!N12+HH!R12))*1000000 -> 10.974439 | O12: =((ACCIDENTES!C12+ACCIDENTES!H12+ACCIDENTES!M12+ACCIDENTES!R12+ACCIDENTES!W12)/(HH!F12+HH!J12+HH!N12+HH!R12+HH!V12))*1000000 -> 4.3758451 | P12: =(((ACCIDENTES!D12+ACCIDENTES!I12+ACCIDENTES!N12+ACCIDENTES!S12+ACCIDENTES!X12)/(HH!F12+HH!J12+HH!N12+HH!R12+HH!V12))*1000000) -> 236.29564 | Q12: =((ACCIDENTES!F12+ACCIDENTES!K12+ACCIDENTES!P12+ACCIDENTES!U12+ACCIDENTES!Z12)/(HH!F12+HH!J12+HH!N12+HH!R12+HH!V12))*1000000 -> 10.502028 | R12: =(ACCIDENTES!C12+ACCIDENTES!H12+ACCIDENTES!M12+ACCIDENTES!R12+ACCIDENTES!W12+ACCIDENTES!AB12)*1000000/(HH!F12+HH!J12+HH!N12+HH!R12+HH!V12+HH!Z12) -> 4.029011 | S12: =(ACCIDENTES!D12+ACCIDENTES!I12+ACCIDENTES!N12+ACCIDENTES!S12+ACCIDENTES!X12+ACCIDENTES!AC12)*1000000/(HH!F12+HH!J12+HH!N12+HH!R12+HH!V12+HH!Z12) -> 207.31093 | T12: =(ACCIDENTES!F12+ACCIDENTES!K12+ACCIDENTES!P12+ACCIDENTES!U12+ACCIDENTES!Z12+ACCIDENTES!AE12)*1000000/(HH!F12+HH!J12+HH!N12+HH!R12+HH!V12+HH!Z12) -> 9.8893907 | U12: =((ACCIDENTES!C12+ACCIDENTES!H12+ACCIDENTES!M12+ACCIDENTES!R12+ACCIDENTES!W12+ACCIDENTES!AB12+ACCIDENTES!AG12)/(HH!F12+HH!J12+HH!N12+HH!R12+HH!V12+HH!Z12+HH!AD12))*1000000 -> 3.4557984 | V12: =((ACCIDENTES!D12+ACCIDENTES!I12+ACCIDENTES!N12+ACCIDENTES!S12+ACCIDENTES!X12+ACCIDENTES!AC12+ACCIDENTES!AH12)/(HH!F12+HH!J12+HH!N12+HH!R12+HH!V12+HH!Z12+HH!AD12))*1000000 -> 177.81654 | W12: =((ACCIDENTES!F12+ACCIDENTES!K12+ACCIDENTES!P12+ACCIDENTES!U12+ACCIDENTES!Z12+ACCIDENTES!AE12+ACCIDENTES!AJ12)/(HH!F12+HH!J12+HH!N12+HH!R12+HH!V12+HH!Z12+HH!AD12))*1000000 -> 10.053232 | X12: =((ACCIDENTES!C12+ACCIDENTES!H12+ACCIDENTES!M12+ACCIDENTES!R12+ACCIDENTES!W12+ACCIDENTES!AB12+ACCIDENTES!AG12+ACCIDENTES!AL12)/(HH!F12+HH!J12+HH!N12+HH!R12+HH!V12+HH!Z12+HH!AD12+HH!AH12))*1000000 -> 3.5803248 | Y12: =((ACCIDENTES!D12+ACCIDENTES!I12+ACCIDENTES!N12+ACCIDENTES!S12+ACCIDENTES!X12+ACCIDENTES!AC12+ACCIDENTES!AH12+ACCIDENTES!AM12)/(HH!F12+HH!J12+HH!N12+HH!R12+HH!V12+HH!Z12+HH!AD12+HH!AH12))*1000000 -> 219.22604 | Z12: =((ACCIDENTES!F12+ACCIDENTES!K12+ACCIDENTES!P12+ACCIDENTES!U12+ACCIDENTES!Z12+ACCIDENTES!AE12+ACCIDENTES!AJ12+ACCIDENTES!AO12)/(HH!F12+HH!J12+HH!N12+HH!R12+HH!V12+HH!Z12+HH!AD12+HH!AH12))*1000000 -> 10.465565 | AA12: =((ACCIDENTES!AQ12+ACCIDENTES!AL12+ACCIDENTES!AG12+ACCIDENTES!AB12+ACCIDENTES!W12+ACCIDENTES!R12+ACCIDENTES!M12+ACCIDENTES!H12+ACCIDENTES!C12)/(HH!AL12+HH!AH12+HH!AD12+HH!Z12+HH!V12+HH!R12+HH!N12+HH!J12+HH!F12))*1000000 -> 4.6454335 | AB12: =((ACCIDENTES!AR12+ACCIDENTES!AM12+ACCIDENTES!AH12+ACCIDENTES!AC12+ACCIDENTES!X12+ACCIDENTES!S12+ACCIDENTES!N12+ACCIDENTES!I12+ACCIDENTES!D12)/(HH!AL12+HH!AH12+HH!AD12+HH!Z12+HH!V12+HH!R12+HH!N12+HH!J12+HH!F12))*1000000 -> 204.39908 | AC12: =((ACCIDENTES!F12+ACCIDENTES!K12+ACCIDENTES!P12+ACCIDENTES!U12+ACCIDENTES!Z12+ACCIDENTES!AE12+ACCIDENTES!AJ12+ACCIDENTES!AO12+ACCIDENTES!AT12)/(HH!F12+HH!J12+HH!N12+HH!R12+HH!V12+HH!Z12+HH!AD12+HH!AH12+HH!AL12))*1000000 -> 11.980329 | AD12: =((ACCIDENTES!AV12+ACCIDENTES!AQ12+ACCIDENTES!AL12+ACCIDENTES!AG12+ACCIDENTES!AB12+ACCIDENTES!W12+ACCIDENTES!R12+ACCIDENTES!M12+ACCIDENTES!H12+ACCIDENTES!C12)/(HH!F12+HH!J12+HH!N12+HH!R12+HH!V12+HH!Z12+HH!AD12+HH!AH12+HH!AL12+HH!AP12))*1000000 -> 5.0473999 | AE12: =((ACCIDENTES!D12+ACCIDENTES!I12+ACCIDENTES!N12+ACCIDENTES!S12+ACCIDENTES!X12+ACCIDENTES!AC12+ACCIDENTES!AH12+ACCIDENTES!AM12+ACCIDENTES!AR12+ACCIDENTES!AW12)/(HH!AP12+HH!AL12+HH!AH12+HH!AD12+HH!Z12+HH!V12+HH!R12+HH!N12+HH!J12+HH!F12))*1000000 -> 192.2401 | AF12: =((ACCIDENTES!AY12+ACCIDENTES!AT12+ACCIDENTES!AO12+ACCIDENTES!AJ12+ACCIDENTES!AE12+ACCIDENTES!Z12+ACCIDENTES!U12+ACCIDENTES!P12+ACCIDENTES!K12+ACCIDENTES!F12)/(HH!F12+HH!J12+HH!N12+HH!R12+HH!V12+HH!Z12+HH!AD12+HH!AH12+HH!AL12+HH!AP12))*1000000 -> 12.508774 | AG12: =((ACCIDENTES!BA12+ACCIDENTES!AV12+ACCIDENTES!AQ12+ACCIDENTES!AL12+ACCIDENTES!AG12+ACCIDENTES!AB12+ACCIDENTES!W12+ACCIDENTES!R12+ACCIDENTES!M12+ACCIDENTES!H12+ACCIDENTES!C12)/(HH!AT12+HH!AP12+HH!AL12+HH!AH12+HH!AD12+HH!Z12+HH!V12+HH!R12+HH!N12+HH!J12+HH!F12))*1000000 -> 4.8043647 | AH12: =((ACCIDENTES!D12+ACCIDENTES!I12+ACCIDENTES!N12+ACCIDENTES!S12+ACCIDENTES!X12+ACCIDENTES!AC12+ACCIDENTES!AH12+ACCIDENTES!AM12+ACCIDENTES!AR12+ACCIDENTES!AW12+ACCIDENTES!BB12)/(HH!F12+HH!J12+HH!N12+HH!R12+HH!V12+HH!Z12+HH!AD12+HH!AH12+HH!AL12+HH!AP12+HH!AT12))*1000000 -> 175.75968 | AI12: =((ACCIDENTES!BD12+ACCIDENTES!AY12+ACCIDENTES!AT12+ACCIDENTES!AO12+ACCIDENTES!AJ12+ACCIDENTES!AE12+ACCIDENTES!Z12+ACCIDENTES!U12+ACCIDENTES!P12+ACCIDENTES!K12+ACCIDENTES!F12)/(HH!F12+HH!J12+HH!N12+HH!R12+HH!V12+HH!Z12+HH!AD12+HH!AH12+HH!AL12+HH!AP12+HH!AT12))*1000000 -> 12.611457 | AJ12: =(ACCIDENTES!BK12/HH!BB12)*1000000 -> 4.602829 | AK12: =(ACCIDENTES!BL12/HH!BB12)*1000000 -> 161.83547 | AL12: =(ACCIDENTES!BN12/HH!BB12)*1000000 -> 12.151468 | AN12: =AW12 -> 4.9800589 | AO12: =BA12 -> 58.982296 | AR12: 4.7 | AS12: 170 | AT12: 6.3 | AV12: 4.1574204 | AW12: 4.9800589 | AX12: 5.7850062 | AZ12: 50.808984 | BA12: 58.982296 | BB12: 71.578395
A13: ALICORP SAA | B13: DISTRBUCION LIMA | C13: =(ACCIDENTES!C13/HH!F13)*1000000 -> 0 | D13: =(ACCIDENTES!D13/HH!F13)*1000000 -> 0 | E13: =(ACCIDENTES!F13/HH!F13)*1000000 -> 0 | F13: =((ACCIDENTES!C13+ACCIDENTES!H13)/(HH!F13+HH!J13))*1000000 -> 0 | G13: =((ACCIDENTES!D13+ACCIDENTES!I13)/(HH!F13+HH!J13))*1000000 -> 0 | H13: =((ACCIDENTES!F13+ACCIDENTES!K13)/(HH!F13+HH!J13))*1000000 -> 0 | I13: =((ACCIDENTES!C13+ACCIDENTES!H13+ACCIDENTES!M13)/(HH!F13+HH!J13+HH!N13))*1000000 -> 0 | J13: =((ACCIDENTES!D13+ACCIDENTES!I13+ACCIDENTES!N13)/(HH!F13+HH!J13+HH!N13))*1000000 -> 0 | K13: =((ACCIDENTES!F13+ACCIDENTES!K13+ACCIDENTES!P13)/(HH!J13+HH!N13+HH!F13))*1000000 -> 2.1363204 | L13: =((ACCIDENTES!C13+ACCIDENTES!H13+ACCIDENTES!M13+ACCIDENTES!R13)/(HH!F13+HH!J13+HH!N13+HH!R13))*1000000 -> 0 | M13: =((ACCIDENTES!D13+ACCIDENTES!I13+ACCIDENTES!N13+ACCIDENTES!S13)/(HH!F13+HH!J13+HH!N13+HH!R13))*1000000 -> 0 | N13: =((ACCIDENTES!F13+ACCIDENTES!K13+ACCIDENTES!P13+ACCIDENTES!U13)/(HH!F13+HH!J13+HH!N13+HH!R13))*1000000 -> 1.4273813 | O13: =((ACCIDENTES!C13+ACCIDENTES!H13+ACCIDENTES!M13+ACCIDENTES!R13+ACCIDENTES!W13)/(HH!F13+HH!J13+HH!N13+HH!R13+HH!V13))*1000000 -> 0 | P13: =(((ACCIDENTES!D13+ACCIDENTES!I13+ACCIDENTES!N13+ACCIDENTES!S13+ACCIDENTES!X13)/(HH!F13+HH!J13+HH!N13+HH!R13+HH!V13))*1000000) -> 0 | Q13: =((ACCIDENTES!F13+ACCIDENTES!K13+ACCIDENTES!P13+ACCIDENTES!U13+ACCIDENTES!Z13)/(HH!F13+HH!J13+HH!N13+HH!R13+HH!V13))*1000000 -> 2.1081321 | R13: =(ACCIDENTES!C13+ACCIDENTES!H13+ACCIDENTES!M13+ACCIDENTES!R13+ACCIDENTES!W13+ACCIDENTES!AB13)*1000000/(HH!F13+HH!J13+HH!N13+HH!R13+HH!V13+HH!Z13) -> 0 | S13: =(ACCIDENTES!D13+ACCIDENTES!I13+ACCIDENTES!N13+ACCIDENTES!S13+ACCIDENTES!X13+ACCIDENTES!AC13)*1000000/(HH!F13+HH!J13+HH!N13+HH!R13+HH!V13+HH!Z13) -> 0 | T13: =(ACCIDENTES!F13+ACCIDENTES!K13+ACCIDENTES!P13+ACCIDENTES!U13+ACCIDENTES!Z13+ACCIDENTES!AE13)*1000000/(HH!F13+HH!J13+HH!N13+HH!R13+HH!V13+HH!Z13) -> 1.6756767 | U13: =((ACCIDENTES!C13+ACCIDENTES!H13+ACCIDENTES!M13+ACCIDENTES!R13+ACCIDENTES!W13+ACCIDENTES!AB13+ACCIDENTES!AG13)/(HH!F13+HH!J13+HH!N13+HH!R13+HH!V13+HH!Z13+HH!AD13))*1000000 -> 0 | V13: =((ACCIDENTES!D13+ACCIDENTES!I13+ACCIDENTES!N13+ACCIDENTES!S13+ACCIDENTES!X13+ACCIDENTES!AC13+ACCIDENTES!AH13)/(HH!F13+HH!J13+HH!N13+HH!R13+HH!V13+HH!Z13+HH!AD13))*1000000 -> 0 | W13: =((ACCIDENTES!F13+ACCIDENTES!K13+ACCIDENTES!P13+ACCIDENTES!U13+ACCIDENTES!Z13+ACCIDENTES!AE13+ACCIDENTES!AJ13)/(HH!F13+HH!J13+HH!N13+HH!R13+HH!V13+HH!Z13+HH!AD13))*1000000 -> 1.3922136 | X13: =((ACCIDENTES!C13+ACCIDENTES!H13+ACCIDENTES!M13+ACCIDENTES!R13+ACCIDENTES!W13+ACCIDENTES!AB13+ACCIDENTES!AG13+ACCIDENTES!AL13)/(HH!F13+HH!J13+HH!N13+HH!R13+HH!V13+HH!Z13+HH!AD13+HH!AH13))*1000000 -> 0 | Y13: =((ACCIDENTES!D13+ACCIDENTES!I13+ACCIDENTES!N13+ACCIDENTES!S13+ACCIDENTES!X13+ACCIDENTES!AC13+ACCIDENTES!AH13+ACCIDENTES!AM13)/(HH!F13+HH!J13+HH!N13+HH!R13+HH!V13+HH!Z13+HH!AD13+HH!AH13))*1000000 -> 0 | Z13: =((ACCIDENTES!F13+ACCIDENTES!K13+ACCIDENTES!P13+ACCIDENTES!U13+ACCIDENTES!Z13+ACCIDENTES!AE13+ACCIDENTES!AJ13+ACCIDENTES!AO13)/(HH!F13+HH!J13+HH!N13+HH!R13+HH!V13+HH!Z13+HH!AD13+HH!AH13))*1000000 -> 1.7765832 | AA13: =((ACCIDENTES!AQ13+ACCIDENTES!AL13+ACCIDENTES!AG13+ACCIDENTES!AB13+ACCIDENTES!W13+ACCIDENTES!R13+ACCIDENTES!M13+ACCIDENTES!H13+ACCIDENTES!C13)/(HH!AL13+HH!AH13+HH!AD13+HH!Z13+HH!V13+HH!R13+HH!N13+HH!J13+HH!F13))*1000000 -> 0.51504125 | AB13: =((ACCIDENTES!AR13+ACCIDENTES!AM13+ACCIDENTES!AH13+ACCIDENTES!AC13+ACCIDENTES!X13+ACCIDENTES!S13+ACCIDENTES!N13+ACCIDENTES!I13+ACCIDENTES!D13)/(HH!AL13+HH!AH13+HH!AD13+HH!Z13+HH!V13+HH!R13+HH!N13+HH!J13+HH!F13))*1000000 -> 7.2105776 | AC13: =((ACCIDENTES!F13+ACCIDENTES!K13+ACCIDENTES!P13+ACCIDENTES!U13+ACCIDENTES!Z13+ACCIDENTES!AE13+ACCIDENTES!AJ13+ACCIDENTES!AO13+ACCIDENTES!AT13)/(HH!F13+HH!J13+HH!N13+HH!R13+HH!V13+HH!Z13+HH!AD13+HH!AH13+HH!AL13))*1000000 -> 2.060165 | AD13: =((ACCIDENTES!AV13+ACCIDENTES!AQ13+ACCIDENTES!AL13+ACCIDENTES!AG13+ACCIDENTES!AB13+ACCIDENTES!W13+ACCIDENTES!R13+ACCIDENTES!M13+ACCIDENTES!H13+ACCIDENTES!C13)/(HH!F13+HH!J13+HH!N13+HH!R13+HH!V13+HH!Z13+HH!AD13+HH!AH13+HH!AL13+HH!AP13))*1000000 -> 0.90304929 | AE13: =((ACCIDENTES!D13+ACCIDENTES!I13+ACCIDENTES!N13+ACCIDENTES!S13+ACCIDENTES!X13+ACCIDENTES!AC13+ACCIDENTES!AH13+ACCIDENTES!AM13+ACCIDENTES!AR13+ACCIDENTES!AW13)/(HH!AP13+HH!AL13+HH!AH13+HH!AD13+HH!Z13+HH!V13+HH!R13+HH!N13+HH!J13+HH!F13))*1000000 -> 7.2243943 | AF13: =((ACCIDENTES!AY13+ACCIDENTES!AT13+ACCIDENTES!AO13+ACCIDENTES!AJ13+ACCIDENTES!AE13+ACCIDENTES!Z13+ACCIDENTES!U13+ACCIDENTES!P13+ACCIDENTES!K13+ACCIDENTES!F13)/(HH!F13+HH!J13+HH!N13+HH!R13+HH!V13+HH!Z13+HH!AD13+HH!AH13+HH!AL13+HH!AP13))*1000000 -> 2.2576232 | AG13: =((ACCIDENTES!BA13+ACCIDENTES!AV13+ACCIDENTES!AQ13+ACCIDENTES!AL13+ACCIDENTES!AG13+ACCIDENTES!AB13+ACCIDENTES!W13+ACCIDENTES!R13+ACCIDENTES!M13+ACCIDENTES!H13+ACCIDENTES!C13)/(HH!AT13+HH!AP13+HH!AL13+HH!AH13+HH!AD13+HH!Z13+HH!V13+HH!R13+HH!N13+HH!J13+HH!F13))*1000000 -> 1.2058629 | AH13: =((ACCIDENTES!D13+ACCIDENTES!I13+ACCIDENTES!N13+ACCIDENTES!S13+ACCIDENTES!X13+ACCIDENTES!AC13+ACCIDENTES!AH13+ACCIDENTES!AM13+ACCIDENTES!AR13+ACCIDENTES!AW13+ACCIDENTES!BB13)/(HH!F13+HH!J13+HH!N13+HH!R13+HH!V13+HH!Z13+HH!AD13+HH!AH13+HH!AL13+HH!AP13+HH!AT13))*1000000 -> 14.0684 | AI13: =((ACCIDENTES!BD13+ACCIDENTES!AY13+ACCIDENTES!AT13+ACCIDENTES!AO13+ACCIDENTES!AJ13+ACCIDENTES!AE13+ACCIDENTES!Z13+ACCIDENTES!U13+ACCIDENTES!P13+ACCIDENTES!K13+ACCIDENTES!F13)/(HH!F13+HH!J13+HH!N13+HH!R13+HH!V13+HH!Z13+HH!AD13+HH!AH13+HH!AL13+HH!AP13+HH!AT13))*1000000 -> 2.4117258 | AJ13: =(ACCIDENTES!BK13/HH!BB13)*1000000 -> 1.4487654 | AK13: =(ACCIDENTES!BL13/HH!BB13)*1000000 -> 18.471759 | AL13: =(ACCIDENTES!BN13/HH!BB13)*1000000 -> 2.5353394 | AN13: =AW13 -> 1.7265867 | AO13: =BA13 -> 7.7696402 | AR13: 2.3021156 | AS13: 14.388223 | AT13: 0.5 | AV13: 1.4388223 | AW13: 1.7265867 | AX13: 2.0143512 | AZ13: 5.4675246 | BA13: 7.7696402 | BB13: 10.071756
A14: ALICORP SAA | B14: CD Huachipa | C14: =(ACCIDENTES!C14/HH!F14)*1000000 -> 0 | D14: =(ACCIDENTES!D14/HH!F14)*1000000 -> 0 | E14: =(ACCIDENTES!F14/HH!F14)*1000000 -> 0 | F14: =((ACCIDENTES!C14+ACCIDENTES!H14)/(HH!F14+HH!J14))*1000000 -> 0 | G14: =((ACCIDENTES!D14+ACCIDENTES!I14)/(HH!F14+HH!J14))*1000000 -> 0 | H14: =((ACCIDENTES!F14+ACCIDENTES!K14)/(HH!F14+HH!J14))*1000000 -> 0 | I14: =((ACCIDENTES!C14+ACCIDENTES!H14+ACCIDENTES!M14)/(HH!F14+HH!J14+HH!N14))*1000000 -> 0 | J14: =((ACCIDENTES!D14+ACCIDENTES!I14+ACCIDENTES!N14)/(HH!F14+HH!J14+HH!N14))*1000000 -> 0 | K14: =((ACCIDENTES!F14+ACCIDENTES!K14+ACCIDENTES!P14)/(HH!J14+HH!N14+HH!F14))*1000000 -> 6.9039799 | L14: =((ACCIDENTES!C14+ACCIDENTES!H14+ACCIDENTES!M14+ACCIDENTES!R14)/(HH!F14+HH!J14+HH!N14+HH!R14))*1000000 -> 0 | M14: =((ACCIDENTES!D14+ACCIDENTES!I14+ACCIDENTES!N14+ACCIDENTES!S14)/(HH!F14+HH!J14+HH!N14+HH!R14))*1000000 -> 0 | N14: =((ACCIDENTES!F14+ACCIDENTES!K14+ACCIDENTES!P14+ACCIDENTES!U14)/(HH!F14+HH!J14+HH!N14+HH!R14))*1000000 -> 5.0911883 | O14: =((ACCIDENTES!C14+ACCIDENTES!H14+ACCIDENTES!M14+ACCIDENTES!R14+ACCIDENTES!W14)/(HH!F14+HH!J14+HH!N14+HH!R14+HH!V14))*1000000 -> 0 | P14: =(((ACCIDENTES!D14+ACCIDENTES!I14+ACCIDENTES!N14+ACCIDENTES!S14+ACCIDENTES!X14)/(HH!F14+HH!J14+HH!N14+HH!R14+HH!V14))*1000000) -> 0 | Q14: =((ACCIDENTES!F14+ACCIDENTES!K14+ACCIDENTES!P14+ACCIDENTES!U14+ACCIDENTES!Z14)/(HH!F14+HH!J14+HH!N14+HH!R14+HH!V14))*1000000 -> 3.9217563 | R14: =(ACCIDENTES!C14+ACCIDENTES!H14+ACCIDENTES!M14+ACCIDENTES!R14+ACCIDENTES!W14+ACCIDENTES!AB14)*1000000/(HH!F14+HH!J14+HH!N14+HH!R14+HH!V14+HH!Z14) -> 0 | S14: =(ACCIDENTES!D14+ACCIDENTES!I14+ACCIDENTES!N14+ACCIDENTES!S14+ACCIDENTES!X14+ACCIDENTES!AC14)*1000000/(HH!F14+HH!J14+HH!N14+HH!R14+HH!V14+HH!Z14) -> 0 | T14: =(ACCIDENTES!F14+ACCIDENTES!K14+ACCIDENTES!P14+ACCIDENTES!U14+ACCIDENTES!Z14+ACCIDENTES!AE14)*1000000/(HH!F14+HH!J14+HH!N14+HH!R14+HH!V14+HH!Z14) -> 3.1952679 | U14: =((ACCIDENTES!C14+ACCIDENTES!H14+ACCIDENTES!M14+ACCIDENTES!R14+ACCIDENTES!W14+ACCIDENTES!AB14+ACCIDENTES!AG14)/(HH!F14+HH!J14+HH!N14+HH!R14+HH!V14+HH!Z14+HH!AD14))*1000000 -> 0 | V14: =((ACCIDENTES!D14+ACCIDENTES!I14+ACCIDENTES!N14+ACCIDENTES!S14+ACCIDENTES!X14+ACCIDENTES!AC14+ACCIDENTES!AH14)/(HH!F14+HH!J14+HH!N14+HH!R14+HH!V14+HH!Z14+HH!AD14))*1000000 -> 0 | W14: =((ACCIDENTES!F14+ACCIDENTES!K14+ACCIDENTES!P14+ACCIDENTES!U14+ACCIDENTES!Z14+ACCIDENTES!AE14+ACCIDENTES!AJ14)/(HH!F14+HH!J14+HH!N14+HH!R14+HH!V14+HH!Z14+HH!AD14))*1000000 -> 2.6958698 | X14: =((ACCIDENTES!C14+ACCIDENTES!H14+ACCIDENTES!M14+ACCIDENTES!R14+ACCIDENTES!W14+ACCIDENTES!AB14+ACCIDENTES!AG14+ACCIDENTES!AL14)/(HH!F14+HH!J14+HH!N14+HH!R14+HH!V14+HH!Z14+HH!AD14+HH!AH14))*1000000 -> 0 | Y14: =((ACCIDENTES!D14+ACCIDENTES!I14+ACCIDENTES!N14+ACCIDENTES!S14+ACCIDENTES!X14+ACCIDENTES!AC14+ACCIDENTES!AH14+ACCIDENTES!AM14)/(HH!F14+HH!J14+HH!N14+HH!R14+HH!V14+HH!Z14+HH!AD14+HH!AH14))*1000000 -> 0 | Z14: =((ACCIDENTES!F14+ACCIDENTES!K14+ACCIDENTES!P14+ACCIDENTES!U14+ACCIDENTES!Z14+ACCIDENTES!AE14+ACCIDENTES!AJ14+ACCIDENTES!AO14)/(HH!F14+HH!J14+HH!N14+HH!R14+HH!V14+HH!Z14+HH!AD14+HH!AH14))*1000000 -> 2.3253283 | AA14: =((ACCIDENTES!AQ14+ACCIDENTES!AL14+ACCIDENTES!AG14+ACCIDENTES!AB14+ACCIDENTES!W14+ACCIDENTES!R14+ACCIDENTES!M14+ACCIDENTES!H14+ACCIDENTES!C14)/(HH!AL14+HH!AH14+HH!AD14+HH!Z14+HH!V14+HH!R14+HH!N14+HH!J14+HH!F14))*1000000 -> 0 | AB14: =((ACCIDENTES!AR14+ACCIDENTES!AM14+ACCIDENTES!AH14+ACCIDENTES!AC14+ACCIDENTES!X14+ACCIDENTES!S14+ACCIDENTES!N14+ACCIDENTES!I14+ACCIDENTES!D14)/(HH!AL14+HH!AH14+HH!AD14+HH!Z14+HH!V14+HH!R14+HH!N14+HH!J14+HH!F14))*1000000 -> 0 | AC14: =((ACCIDENTES!F14+ACCIDENTES!K14+ACCIDENTES!P14+ACCIDENTES!U14+ACCIDENTES!Z14+ACCIDENTES!AE14+ACCIDENTES!AJ14+ACCIDENTES!AO14+ACCIDENTES!AT14)/(HH!F14+HH!J14+HH!N14+HH!R14+HH!V14+HH!Z14+HH!AD14+HH!AH14+HH!AL14))*1000000 -> 2.0487362 | AD14: =((ACCIDENTES!AV14+ACCIDENTES!AQ14+ACCIDENTES!AL14+ACCIDENTES!AG14+ACCIDENTES!AB14+ACCIDENTES!W14+ACCIDENTES!R14+ACCIDENTES!M14+ACCIDENTES!H14+ACCIDENTES!C14)/(HH!F14+HH!J14+HH!N14+HH!R14+HH!V14+HH!Z14+HH!AD14+HH!AH14+HH!AL14+HH!AP14))*1000000 -> 0 | AE14: =((ACCIDENTES!D14+ACCIDENTES!I14+ACCIDENTES!N14+ACCIDENTES!S14+ACCIDENTES!X14+ACCIDENTES!AC14+ACCIDENTES!AH14+ACCIDENTES!AM14+ACCIDENTES!AR14+ACCIDENTES!AW14)/(HH!AP14+HH!AL14+HH!AH14+HH!AD14+HH!Z14+HH!V14+HH!R14+HH!N14+HH!J14+HH!F14))*1000000 -> 0 | AF14: =((ACCIDENTES!AY14+ACCIDENTES!AT14+ACCIDENTES!AO14+ACCIDENTES!AJ14+ACCIDENTES!AE14+ACCIDENTES!Z14+ACCIDENTES!U14+ACCIDENTES!P14+ACCIDENTES!K14+ACCIDENTES!F14)/(HH!F14+HH!J14+HH!N14+HH!R14+HH!V14+HH!Z14+HH!AD14+HH!AH14+HH!AL14+HH!AP14))*1000000 -> 1.8309492 | AG14: =((ACCIDENTES!BA14+ACCIDENTES!AV14+ACCIDENTES!AQ14+ACCIDENTES!AL14+ACCIDENTES!AG14+ACCIDENTES!AB14+ACCIDENTES!W14+ACCIDENTES!R14+ACCIDENTES!M14+ACCIDENTES!H14+ACCIDENTES!C14)/(HH!AT14+HH!AP14+HH!AL14+HH!AH14+HH!AD14+HH!Z14+HH!V14+HH!R14+HH!N14+HH!J14+HH!F14))*1000000 -> 0 | AH14: =((ACCIDENTES!D14+ACCIDENTES!I14+ACCIDENTES!N14+ACCIDENTES!S14+ACCIDENTES!X14+ACCIDENTES!AC14+ACCIDENTES!AH14+ACCIDENTES!AM14+ACCIDENTES!AR14+ACCIDENTES!AW14+ACCIDENTES!BB14)/(HH!F14+HH!J14+HH!N14+HH!R14+HH!V14+HH!Z14+HH!AD14+HH!AH14+HH!AL14+HH!AP14+HH!AT14))*1000000 -> 0 | AI14: =((ACCIDENTES!BD14+ACCIDENTES!AY14+ACCIDENTES!AT14+ACCIDENTES!AO14+ACCIDENTES!AJ14+ACCIDENTES!AE14+ACCIDENTES!Z14+ACCIDENTES!U14+ACCIDENTES!P14+ACCIDENTES!K14+ACCIDENTES!F14)/(HH!F14+HH!J14+HH!N14+HH!R14+HH!V14+HH!Z14+HH!AD14+HH!AH14+HH!AL14+HH!AP14+HH!AT14))*1000000 -> 1.6550159 | AJ14: =(ACCIDENTES!BK14/HH!BB14)*1000000 -> 0 | AK14: =(ACCIDENTES!BL14/HH!BB14)*1000000 -> 0 | AL14: =(ACCIDENTES!BN14/HH!BB14)*1000000 -> 1.509929 | AN14: =AW14 -> 0 | AO14: =BA14 -> 0
