Workbook
Name AreaDePersonal: [1]Listas!$E$4:$E$9
Name ClasificacionOSHA: [1]Listas!$L$4:$L$7
Name CRITERIOS_ESTADISTICAS: [2]AUXILIARES!$M$1:$Q$2
Name DESTINO: [2]AUXILIARES!$M$4
Name DIASDMR_ALICORP: '[2]DIAS DMR'!$U$2:$AL$2
Name DIASDMR_NOALICORP: '[2]DIAS DMR'!$AM$2:$BD$2
Name DIASPERD_ALICORP: '[2]DIAS PERDIDOS'!$U$2:$AL$2
Name DIASPERD_NOALICORP: '[2]DIAS PERDIDOS'!$AM$2:$BD$2
Name Doctores: [1]Listas!$A$4:$A$13
Name ENCABEZADO: [2]ACCIDENTES!$A$2:$K$2
Name EntidadNosologica: [1]Listas!$G$4:$G$38
Name GENERADORES_CRITERIOS: [2]AUXILIARES!$N$5:$P$9
Name INDICES: [2]AUXILIARES!$C$2:$F$12
Name LESDMR_ALICORP: '[2]LESIONES CON DMR'!$U$2:$AL$2
Name LESDMR_NOALICORP: '[2]LESIONES CON DMR'!$AM$2:$BD$2
Name LESINCAP_ALICORP: '[2]LESIONES INCAPACITANTES'!$U$2:$AL$2
Name LESINCAP_NOALICORP: '[2]LESIONES INCAPACITANTES'!$AM$2:$BD$2
Name LESNOINCAP_ALICORP: '[2]LESIONES NO INCAPACITANTES'!$U$2:$AK$2
Name LESNOINCAP_NOALICORP: '[2]LESIONES NO INCAPACITANTES'!$AM$2:$BD$2
Name Medicamentos: [1]Medicamentos!$C$6:$C$107
Name MESES: [2]AUXILIARES!$H$2:$H$13
Name OPCIONES: [2]AUXILIARES!$J$9:$J$12
Name Paramedicos: [1]Listas!$C$4:$C$12
Name PLANTAS: [2]AUXILIARES!$A$15:$A$32
Name PROGRAMAS: [2]AUXILIARES!$A$2:$A$12
Name SETEO: [2]AUXILIARES!$K$2:$K$7
Name SubdivisionPersonal: [1]Listas!$J$4:$J$22
Name TipoAccidente: [1]Listas!$N$12:$N$16
Name TipoAtencion: [1]Listas!$N$4:$N$7

Sheet PROGRAMA 2010
A1: Item | B1: Actividad | C1: %Avance | D1: Responsable | E1: Comentarios | F1: P/R | G1: Ene | H1: Feb | I1: Mar | J1: Abr | K1: May | L1: Jun | M1: Jul | N1: Ago | O1: Sep | P1: Oct | Q1: Nov | R1: Dic
A2: 1 | B2: Reestructurar Plan IGP | C2: 1 | D2: J.Briceño/D.Lucana | E2: Agregar a programa de IGP: Sist.Seguridad, Utiles/Materiales, Inv.Herramientas, Casilleros, SSEE (R.Aleman) | F2: P
F3: R
A4: 2 | B4: Charlas Resultados CP 2009 al personal | C4: 1 | D4: Directores/J.Briceño | E4: MSR: 19/04 y 26/04 de 04:00 a 05:00 pm. MFA: 21/04 (02:00 a 03:00 pm y de 03:00 a 04:00 pm) 22/04 (02:00 a 03:00 pm) 28/04 (02:00 a 03:00 pm y de 03:00 a 04:00 pm) MCA: 03/05 8:00 a 09:30 pm 26/04 05:00 a 06:00 pm 03/05 05:00 a 06:00 pm Se modificar'a material de acuerdo a revision con C.Navarro. La charla se acomp;ar'a con un video (Rudi) | F4: P
F5: R
B6: Preparar Material | C6: 1 | F6: P
F7: R
B8: Definir programa de charlas | C8: 1 | F8: P
F9: R
B10: Dictado en MCA | F10: P
F11: R
B12: Dictado en MFA | F12: P
F13: R
B14: Dictado en MSR | F14: P
F15: R
A16: 3 | B16: Revisión del sistema de Permisos de Trabajo | C16: 0.28 | D16: C.Navarro/J.Antezana/J.Briceño | E16: Se presento plan de trabajo al comite ejecutivo (15/03). Se emitio nueva versi'on Normas Contratistas. | F16: P
F17: R
B18: Desarrollar plan de trabajo | C18: 1 | D18: C.Navarro/J.Antezana/J.Briceño | E18: Presentado en Comité Ejecutivo de Febrero el 15/03 | F18: P
F19: R
B20: Actualizar Normas Contratistas | C20: 1 | D20: J.Briceño | E20: Versión 03 del Documento ALI-C-CP-E8-004 (Obselescencia de cartilla Uso EPP Contratista-Visitante) | F20: P
F21: R
B22: Elaborar Manual Contratistas | D22: J.Briceño | E22: Se envió Manual corregido a C.Navarro | F22: P
F23: R
B24: Rediseñar tarjetas Permisos de Trabajo | D24: J.Briceño | E24: Se definieron cambios con Sup.Mnto 11/06 | F24: P
F25: R
B26: Revisar sistema de control acceso | D26: J.Briceño | E26: Se contacto con Programadora (Soledad Castañeda) para reunirnos y revisar sistema | F26: P
F27: R
B28: Revisar Procedimiento de Permisos de Trabajo | C28: 1 | D28: C.Navarro/J.Antezana/J.Briceño | E28: Se acordaron cambios en reunión. | F28: P
F29: R
B30: Capacitar al personal nivel liderazgo en nuevo procedimiento | D30: J.Briceño | F30: P
F31: R
B32: Inducción a Contratistas en nuevo procedimiento | D32: J.Antezana | F32: P
F33: R
B34: Ampliar alcance a demás áreas (Administración, Transportistas, Estibadores) | D34: C.Navarro/J.Antezana/J.Briceño | F34: P
F35: R
B36: Revisar proceso de homologación | D36: C.Navarro/J.Antezana/J.Briceño | F36: P
F37: R
B38: Evaluar sanciones de amonestación escrita a las jefaturas ante incumplimiento | D38: C.Navarro/J.Antezana/J.Briceño | F38: P
F39: R
A40: 4 | B40: Revisión de Identificacion Peligros, Evaluac.Riesgos, Det.Controles Necesarios | C40: 0.16 | D40: C.Navarro/J.Seguridad | E40: Viernes 18/06 se termina piloto de nueva metodología IPER (Lab.Copsa). Se han definido Reglas Generales y Específicas por áreas del MFA para el personal LIMTEK. | F40: P
...

Sheet ENE
B1: TSPM A ENERO 2010
B3: Elem | C3: Indicador | D3: Peso Ponderado | E3: MCA | F3: MFA | G3: MSR | H3: Molinos Lima | I3: OBJ MAX | K3: Mol Lima 2009 | L3: MCA | M3: MFA | N3: MSR | O3: Molinos Lima | Q3: Alicorp | R3: 2009 | T3: Comentarios Mol.Lima
B4: E2 | C4: Asistencia Capacitación | D4: 0.04 | E4: 0.59 | F4: 0.53 | G4: 0.57 | H4: 0.56 | I4: 0.9 | J4: =+I4*D4 -> 0.036 | K4: 0.91 | L4: =+E4*$D$4 -> 0.0236 | M4: =+F4*$D$4 -> 0.0212 | N4: =+G4*$D$4 -> 0.0228 | O4: =+H4*$D$4 -> 0.0224 | Q4: 0.9 | R4: 0.9
B5: E3 | C5: %Cumplimiento IGP´s | D5: 0.04 | E5: 0.5 | F5: 0.8 | G5: 1 | H5: 0.75 | I5: 1 | J5: =+I5*D5 -> 0.04 | K5: 0.9754 | L5: =+E5*D5 -> 0.02 | M5: =+F5*D5 -> 0.032 | N5: =+G5*D5 -> 0.04 | O5: =+H5*D5 -> 0.03 | Q5: 0.7529 | R5: 0.9822
C6: %Identif.Actos Sub.IGP | D6: 0 | E6: 0.36 | F6: 0.25 | G6: 0.67 | H6: 0.3461 | I6: 0.45 | J6: =+I6*D6 -> 0 | K6: 0.3549 | L6: =+E6*D6 -> 0 | M6: =+F6*D6 -> 0 | N6: =+G6*D6 -> 0 | O6: =+H6*D6 -> 0 | Q6: 0.4 | R6: 0.358
B7: E4 | C7: %Cumplimiento ITAR | D7: 0 | E7: 1 | F7: 1 | G7: 1 | H7: 1 | I7: 0.95 | J7: =+I7*D7 -> 0 | K7: 1 | L7: =+E7*D7 -> 0 | M7: =+F7*D7 -> 0 | N7: =+G7*D7 -> 0 | O7: =+H7*D7 -> 0
C8: %Implementación CV | D8: 0 | E8: 0 | F8: 1 | G8: 1 | H8: 0.66 | I8: 1 | J8: =+I8*D8 -> 0 | K8: 1 | L8: =+E8*D8 -> 0 | M8: =+F8*D8 -> 0 | N8: =+G8*D8 -> 0 | O8: =+H8*D8 -> 0
C9: Mapa de riesgo | D9: 0.04 | E9: 1 | F9: 1 | G9: 1 | H9: 1 | I9: 0.95 | J9: =+I9*D9 -> 0.038 | K9: 1 | L9: =+$D$9*E9 -> 0.04 | M9: =+$D$9*F9 -> 0.04 | N9: =+$D$9*G9 -> 0.04 | O9: =+$D$9*H9 -> 0.04 | Q9: 0.97 | R9: 0.97
B10: E5 | C10: Accid.Incapacitantes | E10: 0 | F10: 1 | G10: 0 | H10: 1 | I10: 6 | K10: 7 | Q10: 6 | R10: 36
C11: Accid.DMR | E11: 0 | F11: 0 | G11: 0 | H11: 0 | I11: 0 | K11: 0 | Q11: 0 | R11: 9
C12: Lesión Menor | E12: 0 | F12: 0 | G12: 0 | H12: 0 | I12: 7 | K12: 8 | Q12: 11 | R12: 94
C13: Días de Descanso | E13: 0 | F13: 15 | G13: 0 | H13: 15 | I13: 77 | K13: 6068 | Q13: 51 | R13: 8202
C14: Ind.Frecuencia (1 año) | D14: 0.1 | E14: 6.85 | F14: 10.2 | G14: 0 | H14: 6.39 | I14: 4.75 | J14: =+D14 -> 0.1 | K14: 5.57 | L14: =5.06/E14*D14 -> 0.073868613 | M14: =4.97/F14*D14 -> 0.04872549 | N14: 0.1 | O14: =I14/H14*D14 -> 0.074334898 | Q14: 2.31 | R14: 3.05
C15: Ind.Severidad (1 año) | D15: 0.1 | E15: 10303.79 | F15: 163.21 | G15: 0 | H15: 4860.15 | I15: 60.98 | J15: =+D15 -> 0.1 | K15: 4828.05 | L15: =50.59/E15*D15 -> 0.00049098439 | M15: =96.93/F15*D15 -> 0.059389743 | N15: 0.1 | O15: =I15/H15*D15 -> 0.0012546938 | Q15: 698.45 | R15: 694.94
C16: OSHA incident rate | D16: 0.1 | E16: 1.71 | F16: 5.1 | G16: 0.73 | H16: 2.56 | I16: 2.06 | J16: =+D16 -> 0.1 | K16: 2.55 | L16: =1.35/1.71*D16 -> 0.078947368 | M16: =2.98/F16*D16 -> 0.058431373 | N16: 0.1 | O16: =I16/H16*D16 -> 0.08046875 | Q16: 3.14 | R16: 2.36
C17: Calidad Investigación | D17: 0.08 | E17: 0.66 | F17: 0.82 | G17: 0.79 | H17: 0.69 | I17: 0.85 | J17: =+I17*D17 -> 0.068 | K17: 0.7473 | L17: =+$D$17*E17 -> 0.0528 | M17: =+$D$17*F17 -> 0.0656 | N17: =+$D$17*G17 -> 0.0632 | O17: =+$D$17*H17 -> 0.0552 | R17: 0.743
C18: %Levantamiento ROM´s | D18: 0.08 | E18: 0.69 | F18: 0.47 | G18: 0.38 | H18: 0.5556 | I18: 0.95 | J18: =+I18*D18 -> 0.076 | K18: 0.9129 | L18: =+E18*D18 -> 0.0552 | M18: =+F18*D18 -> 0.0376 | N18: =+G18*D18 -> 0.0304 | O18: =+H18*D18 -> 0.044448 | Q18: 0.52 | R18: 0.934
C19: %Identif.Actos Sub.ROM´s | D19: 0 | E19: 0.58 | F19: 0.62 | G19: 0.25 | H19: 0.44 | I19: 0.85 | J19: =+I19*D19 -> 0 | K19: 0.7812 | L19: =+E19*D19 -> 0 | M19: =+F19*D19 -> 0 | N19: =+G19*D19 -> 0 | O19: =+H19*D19 -> 0 | Q19: 0.47 | R19: 0.57
C20: %Particip.ROM´s (en el Semestre) | D20: 0 | E20: 0.14 | F20: 0.17 | G20: 0.04 | H20: 0.13 | I20: 0.6 | J20: =+I20*D20 -> 0 | K20: 0.7 | L20: =+E20*D20 -> 0 | M20: =+F20*D20 -> 0 | N20: =+G20*D20 -> 0 | O20: =+H20*D20 -> 0 | R20: 0.64
C21: %ROM´s Autofinalizadas | D21: 0 | E21: 0.56 | F21: 0.36 | G21: 0.19 | H21: 0.43 | I21: 0.55 | J21: =+I21*D21 -> 0 | K21: 0.7169 | L21: =+E21*D21 -> 0 | M21: =+F21*D21 -> 0 | N21: =+G21*D21 -> 0 | O21: =+H21*D21 -> 0 | Q21: 0.34
B22: E6 | C22: Cumplimiento Prog.Observ | D22: 0.04 | E22: 1 | F22: 1 | G22: 1 | H22: 1 | I22: 0.95 | J22: =+I22*D22 -> 0.038 | K22: 1 | L22: =+E22*D22 -> 0.04 | M22: =+F22*D22 -> 0.04 | N22: =+G22*D22 -> 0.04 | O22: =+H22*D22 -> 0.04 | R22: 0.95
C23: %Comportam.Seguro | D23: 0.08 | E23: 1 | F23: 0.94 | G23: 1 | H23: 0.99 | I23: 1 | J23: =+I23*D23 -> 0.08 | K23: 0.99 | L23: =+E23*D23 -> 0.08 | M23: =+F23*D23 -> 0.0752 | N23: =+G23*D23 -> 0.08 | O23: =+H23*D23 -> 0.0792 | R23: 0.968
B24: E7 | C24: Evaluación Simulacros | D24: 0.05 | E24: 0.66 | F24: 0.82 | G24: 0.79 | H24: 0.69 | I24: 0.8 | J24: =+I24*D24 -> 0.04 | K24: 0.69 | L24: =+E24*D24 -> 0.033 | M24: =+F24*D24 -> 0.041 | N24: =+G24*D24 -> 0.0395 | O24: =+H24*D24 -> 0.0345 | R24: 0.89
C25: Participación Niv.Lid.Brigadas | D25: 0.02 | E25: 0.67 | F25: 0.83 | G25: 1 | H25: 0.83 | I25: 0.95 | J25: =+I25*D25 -> 0.019 | K25: 0.76 | L25: =+$H$25*$D$25 -> 0.0166 | M25: =+$H$25*$D$25 -> 0.0166 | N25: =+$H$25*$D$25 -> 0.0166 | O25: =+$H$25*$D$25 -> 0.0166 | R25: 0.75
B26: E8 | C26: Efectividad Perm.Trabajo | D26: 0.05 | E26: 1 | F26: 1 | G26: 0.98 | H26: 0.99 | I26: 1 | J26: =+I26*D26 -> 0.05 | K26: 1 | L26: =+E26*D26 -> 0.05 | M26: =+F26*D26 -> 0.05 | N26: =+G26*D26 -> 0.049 | O26: =+H26*D26 -> 0.0495 | R26: 0.977
C27: %Particip.Fiscalización Permisos | D27: 0 | E27: 0.66 | F27: 0.52 | G27: =5/45 -> 0.11111111 | H27: 0.5167 | I27: 0.7 | J27: =+I27*D27 -> 0 | K27: 0.6 | L27: =+E27*D27 -> 0 | M27: =+F27*D27 -> 0 | N27: =+G27*D27 -> 0 | O27: =+H27*D27 -> 0
B28: E11 | C28: %Cumplim.EPP | D28: 0.05 | E28: 0.88 | F28: 1 | G28: 0.84 | H28: 0.91 | I28: 1 | J28: =+I28*D28 -> 0.05 | K28: 0.99 | L28: =+E28*D28 -> 0.044 | M28: =+F28*D28 -> 0.05 | N28: =+G28*D28 -> 0.042 | O28: =+H28*D28 -> 0.0455 | R28: 0.98
B29: E12 | C29: Examen médico Ingresantes | D29: 0.03 | H29: 0.96 | I29: 0.95 | J29: =+I29*D29 -> 0.0285 | K29: 0.96 | L29: =+$H$29*$D$29 -> 0.0288 | M29: =+$H$29*$D$29 -> 0.0288 | N29: =+$H$29*$D$29 -> 0.0288 | O29: =+$H$29*$D$29 -> 0.0288 | Q29: 0.92 | R29: 0.92
C30: Examen preventivo | D30: 0.02 | H30: 0.97 | I30: 0.95 | J30: =+I30*D30 -> 0.019 | K30: 0.97 | L30: =+O30 -> 0.0194 | M30: =+O30 -> 0.0194 | N30: =+O30 -> 0.0194 | O30: =+H30*D30 -> 0.0194 | Q30: 0.98 | R30: 0.98
B31: E19 | C31: Homologación Proveedores | D31: 0.08 | H31: 0.79 | I31: 0.9 | J31: =+I31*D31 -> 0.072 | K31: 0.79 | L31: =+O31 -> 0.0632 | M31: =+O31 -> 0.0632 | N31: =+O31 -> 0.0632 | O31: =+H31*D31 -> 0.0632 | Q31: 0.8 | R31: 0.8
C32: Total %TSPM | D32: =SUM(D4:D31) -> 1 | E32: =+L32 -> 0.71990697 | F32: =+M32 -> 0.74714661 | G32: =+N32 -> 0.8749 | H32: =+O32 -> 0.72880634 | I32: =+J32 -> 0.9545 | J32: =SUM(J4:J31) -> 0.9545 | K32: 0.83395402 | L32: =SUM(L4:L31) -> 0.71990697 | M32: =SUM(M4:M31) -> 0.74714661 | N32: =SUM(N4:N31) -> 0.8749 | O32: =SUM(O4:O31)+0.004 -> 0.72880634 | R32: 0.718

Sheet FEB
B1: TSPM A FEBRERO 2010
B3: Elem | C3: Indicador | D3: Peso Ponderado | E3: MCA | F3: MFA | G3: MSR | H3: Molinos Lima | I3: OBJ MAX | K3: Mol Lima 2009 | L3: MCA | M3: MFA | N3: MSR | O3: Molinos Lima | Q3: Alicorp | R3: 2009 | T3: Comentarios Mol.Lima
B4: E2 | C4: Asistencia Capacitación | D4: 0.04 | E4: 0.69 | F4: 0.55 | G4: 0.76 | H4: 0.6469 | I4: 0.9 | J4: =+I4*D4 -> 0.036 | K4: 0.91 | L4: =+E4*$D$4 -> 0.0276 | M4: =+F4*$D$4 -> 0.022 | N4: =+G4*$D$4 -> 0.0304 | O4: =+H4*$D$4 -> 0.025876 | R4: 0.9
B5: E3 | C5: %Cumplimiento IGP´s | D5: 0.04 | E5: 0.83 | F5: 0.8 | G5: 0.9 | H5: 0.8438 | I5: 1 | J5: =+I5*D5 -> 0.04 | K5: 0.9754 | L5: =+E5*D5 -> 0.0332 | M5: =+F5*D5 -> 0.032 | N5: =+G5*D5 -> 0.036 | O5: =+H5*D5 -> 0.033752 | R5: 0.9822
C6: %Identif.Actos Sub.IGP | D6: 0 | E6: 0.2581 | F6: 0.3 | G6: 0.6471 | H6: 0.3676 | I6: 0.45 | J6: =+I6*D6 -> 0 | K6: 0.3549 | L6: =+E6*D6 -> 0 | M6: =+F6*D6 -> 0 | N6: =+G6*D6 -> 0 | O6: =+H6*D6 -> 0 | R6: 0.358
B7: E4 | C7: %Cumplimiento ITAR | D7: 0 | I7: 0.95 | J7: =+I7*D7 -> 0 | K7: 1 | L7: =+E7*D7 -> 0 | M7: =+F7*D7 -> 0 | N7: =+G7*D7 -> 0 | O7: =+H7*D7 -> 0
C8: %Implementación CV | D8: 0 | I8: 1 | J8: =+I8*D8 -> 0 | K8: 1 | L8: =+E8*D8 -> 0 | M8: =+F8*D8 -> 0 | N8: =+G8*D8 -> 0 | O8: =+H8*D8 -> 0
C9: Mapa de riesgo | D9: 0.04 | E9: 1 | F9: 1 | G9: 1 | H9: 1 | I9: 0.95 | J9: =+I9*D9 -> 0.038 | K9: 1 | L9: =+$D$9*E9 -> 0.04 | M9: =+$D$9*F9 -> 0.04 | N9: =+$D$9*G9 -> 0.04 | O9: =+$D$9*H9 -> 0.04 | R9: 0.97
B10: E5 | C10: Dias sin accidentes | E10: 292 | F10: 33 | G10: 476 | H10: 33
C11: Accid.Incapacitantes | E11: 0 | F11: 1 | G11: 0 | H11: 1 | I11: 6 | K11: 7 | Q11: 9 | R11: 36
C12: Accid.DMR | E12: 0 | F12: 0 | G12: 0 | H12: 0 | I12: 0 | K12: 0 | Q12: 1 | R12: 9
C13: Lesión Menor | E13: 1 | F13: 0 | G13: 0 | H13: 1 | I13: 9 | K13: 8 | Q13: 16 | R13: 94
C14: Días de Descanso | E14: 0 | F14: 54 | G14: 0 | H14: 15 | I14: 150 | K14: 6068 | Q14: 121 | R14: 8202
C15: Ind.Frecuencia (1 año) | D15: 0.1 | E15: 6.85 | F15: 7.65 | G15: 0 | H15: 5.67 | I15: 4.77 | J15: =+D15 -> 0.1 | K15: 5.57 | L15: =5.09/E15*D15 -> 0.074306569 | M15: =5.13/F15*D15 -> 0.067058824 | N15: =3.61/3.61*D15 -> 0.1 | O15: =I15/H15*D15 -> 0.084126984 | Q15: 3.21 | R15: 3.05 | T15: Con 7 accid. Incapac.2009 (4 MCA y 2 MFA) + 1 MFA 2010
C16: Ind.Severidad (1 año) | D16: 0.1 | E16: 10303.79 | F16: 163.21 | G16: 0 | H16: 4917.1 | I16: 119.3 | J16: =+D16 -> 0.1 | K16: 4828.05 | L16: =128.25/E16*D16 -> 0.0012446876 | M16: =128.25/F16*D16 -> 0.078579744 | N16: =90.19/90.19*D16 -> 0.1 | O16: =I16/H16*D16 -> 0.0024262268 | Q16: 717.5 | R16: 694.94
C17: OSHA incident rate | D17: 0.1 | E17: 1.71 | F17: 4.59 | G17: 0.73 | H17: 2.43 | I17: 2.39 | J17: =+D17 -> 0.1 | K17: 2.55 | L17: =2.37/2.37*D17 -> 0.1 | M17: =2.56/F17*D17 -> 0.05577342 | N17: =2.16/2.16*D17 -> 0.1 | O17: =I17/H17*D17 -> 0.098353909 | Q17: 2.34 | R17: 2.36
C18: Calidad Investigación | D18: 0.08 | E18: 0.66 | F18: 0.788 | G18: 0.79 | H18: 0.7467 | I18: 0.85 | J18: =+I18*D18 -> 0.068 | K18: 0.7473 | L18: =+$D$18*E18 -> 0.0528 | M18: =+$D$18*F18 -> 0.06304 | N18: =+$D$18*G18 -> 0.0632 | O18: =+$D$18*H18 -> 0.059736 | R18: 0.743
C19: %Levantamiento ROM´s | D19: 0.08 | E19: 0.63 | F19: 0.567 | G19: 0.5652 | H19: 0.5962 | I19: 0.95 | J19: =+I19*D19 -> 0.076 | K19: 0.9129 | L19: =+E19*D19 -> 0.0504 | M19: =+F19*D19 -> 0.04536 | N19: =+G19*D19 -> 0.045216 | O19: =+H19*D19 -> 0.047696 | R19: 0.934
C20: %Identif.Actos Sub.ROM´s | D20: 0 | E20: 0.49 | F20: 0.58 | G20: 0.39 | H20: 0.5 | I20: 0.85 | J20: =+I20*D20 -> 0 | K20: 0.7812 | L20: =+E20*D20 -> 0 | M20: =+F20*D20 -> 0 | N20: =+G20*D20 -> 0 | O20: =+H20*D20 -> 0 | R20: 0.57
C21: %Particip.ROM´s (en el Semestre) | D21: 0 | E21: 0.37 | F21: 0.35 | G21: 0.09 | H21: 0.3 | I21: 0.6 | J21: =+I21*D21 -> 0 | K21: 0.7 | L21: =+E21*D21 -> 0 | M21: =+F21*D21 -> 0 | N21: =+G21*D21 -> 0 | O21: =+H21*D21 -> 0 | R21: 0.64
C22: %ROM´s Autofinalizadas | D22: 0 | E22: 0.48 | F22: 0.3 | G22: 0.24 | H22: 0.37 | I22: 0.55 | J22: =+I22*D22 -> 0 | K22: 0.7169 | L22: =+E22*D22 -> 0 | M22: =+F22*D22 -> 0 | N22: =+G22*D22 -> 0 | O22: =+H22*D22 -> 0
B23: E6 | C23: Cumplimiento Prog.Observ | D23: 0.04 | E23: 1 | F23: 1 | G23: 1 | H23: 1 | I23: 0.95 | J23: =+I23*D23 -> 0.038 | K23: 1 | L23: =+E23*D23 -> 0.04 | M23: =+F23*D23 -> 0.04 | N23: =+G23*D23 -> 0.04 | O23: =+H23*D23 -> 0.04 | R23: 0.95
C24: %Comportam.Seguro | D24: 0.08 | E24: 1 | F24: 0.94 | G24: 1 | H24: 0.99 | I24: 1 | J24: =+I24*D24 -> 0.08 | K24: 0.99 | L24: =+E24*D24 -> 0.08 | M24: =+F24*D24 -> 0.0752 | N24: =+G24*D24 -> 0.08 | O24: =+H24*D24 -> 0.0792 | R24: 0.968
B25: E7 | C25: Evaluación Simulacros | D25: 0.05 | E25: 0.66 | F25: 0.82 | G25: 0.79 | H25: 0.69 | I25: 0.8 | J25: =+I25*D25 -> 0.04 | K25: 0.69 | L25: =+E25*D25 -> 0.033 | M25: =+F25*D25 -> 0.041 | N25: =+G25*D25 -> 0.0395 | O25: =+H25*D25 -> 0.0345 | R25: 0.89
C26: Participación Brigadas Niv.Liderazgo | D26: 0.02 | E26: 0.9 | F26: 0.77 | G26: 1 | H26: 0.92 | I26: 0.95 | J26: =+I26*D26 -> 0.019 | K26: 0.76 | L26: =+$H$26*$D$26 -> 0.0184 | M26: =+$H$26*$D$26 -> 0.0184 | N26: =+$H$26*$D$26 -> 0.0184 | O26: =+$H$26*$D$26 -> 0.0184 | R26: 0.75
B27: E8 | C27: Efectividad Perm.Trabajo | D27: 0.05 | E27: 1 | F27: 1 | G27: 0.99 | H27: 0.99 | I27: 1 | J27: =+I27*D27 -> 0.05 | K27: 1 | L27: =+E27*D27 -> 0.05 | M27: =+F27*D27 -> 0.05 | N27: =+G27*D27 -> 0.0495 | O27: =+H27*D27 -> 0.0495 | R27: 0.977
C28: %Particip.Fiscalización Permisos | D28: 0 | E28: 0.19 | F28: 0.51 | H28: 0.43 | I28: 0.7 | J28: =+I28*D28 -> 0 | K28: 0.6 | L28: =+E28*D28 -> 0 | M28: =+F28*D28 -> 0 | N28: =+G28*D28 -> 0 | O28: =+H28*D28 -> 0
B29: E11 | C29: %Cumplim.EPP | D29: 0.05 | E29: 0.91 | F29: 0.99 | G29: 0.91 | H29: 0.93 | I29: 1 | J29: =+I29*D29 -> 0.05 | K29: 0.99 | L29: =+E29*D29 -> 0.0455 | M29: =+F29*D29 -> 0.0495 | N29: =+G29*D29 -> 0.0455 | O29: =+H29*D29 -> 0.0465 | R29: 0.98
B30: E12 | C30: Examen médico Ingresantes | D30: 0.03 | H30: 0.96 | I30: 0.95 | J30: =+I30*D30 -> 0.0285 | K30: 0.96 | L30: =+$H$30*$D$30 -> 0.0288 | M30: =+$H$30*$D$30 -> 0.0288 | N30: =+$H$30*$D$30 -> 0.0288 | O30: =+$H$30*$D$30 -> 0.0288 | R30: 0.92
C31: Examen preventivo | D31: 0.02 | H31: 0.97 | I31: 0.95 | J31: =+I31*D31 -> 0.019 | K31: 0.97 | L31: =+O31 -> 0.0194 | M31: =+O31 -> 0.0194 | N31: =+O31 -> 0.0194 | O31: =+H31*D31 -> 0.0194 | R31: 0.98
B32: E19 | C32: Homologación Proveedores | D32: 0.08 | H32: 0.79 | I32: 0.9 | J32: =+I32*D32 -> 0.072 | K32: 0.79 | L32: =+O32 -> 0.0632 | M32: =+O32 -> 0.0632 | N32: =+O32 -> 0.0632 | O32: =+H32*D32 -> 0.0632 | R32: 0.8
C33: Total %TSPM | D33: =SUM(D4:D32) -> 1 | E33: =+L33 -> 0.75785126 | F33: =+M33 -> 0.78931199 | G33: =+N33 -> 0.899116 | H33: =+O33 -> 0.77546712 | I33: =+J33 -> 0.9545 | J33: =SUM(J4:J32) -> 0.9545 | K33: 0.83395402 | L33: =SUM(L4:L32) -> 0.75785126 | M33: =SUM(M4:M32) -> 0.78931199 | N33: =SUM(N4:N32) -> 0.899116 | O33: =SUM(O4:O32)+0.004 -> 0.77546712 | R33: 0.718
D35: Sin IF, IS | E35: 0.5823 | F35: 0.5879 | G35: 0.599116 | H35: 0.59056 | I35: 0.6545

Sheet MAR
B1: TSPM A MARZO 2010
B3: Elem | C3: Indicador | D3: Peso Ponderado | E3: MCA | F3: MFA | G3: MSR | H3: Molinos Lima | I3: OBJ MAX | K3: Mol Lima 2009 | L3: MCA | M3: MFA | N3: MSR | O3: Molinos Lima | Q3: Alicorp | R3: OBJ MAX | S3: 2009 | U3: Comentarios Mol.Lima
B4: E2 | C4: Asistencia Capacitación | D4: 0.04 | E4: 0.72 | F4: 0.53 | G4: 0.86 | H4: 0.7 | I4: 0.9 | J4: =+I4*D4 -> 0.036 | K4: 0.91 | L4: =+E4*$D$4 -> 0.0288 | M4: =+F4*$D$4 -> 0.0212 | N4: =+G4*$D$4 -> 0.0344 | O4: =+H4*$D$4 -> 0.028 | R4: 0.9 | S4: 0.9
B5: E3 | C5: %Cumplimiento IGP´s | D5: 0.04 | E5: 0.8333 | F5: 0.9444 | G5: 0.9375 | H5: 0.9038 | I5: 0.95 | J5: =+I5*D5 -> 0.038 | K5: 0.9754 | L5: =+E5*D5 -> 0.033332 | M5: =+F5*D5 -> 0.037776 | N5: =+G5*D5 -> 0.0375 | O5: =+H5*D5 -> 0.036152 | Q5: 0.781 | R5: 0.95 | S5: 0.9822
C6: %Identif.Actos Sub.IGP | D6: 0 | E6: 0.3255 | F6: 0.206 | G6: 0.4324 | H6: 0.3245 | I6: 0.4 | J6: =+I6*D6 -> 0 | K6: 0.3549 | L6: =+E6*D6 -> 0 | M6: =+F6*D6 -> 0 | N6: =+G6*D6 -> 0 | O6: =+H6*D6 -> 0 | Q6: 0.324 | R6: 0.4 | S6: 0.358
B7: E4 | C7: %Cumplimiento ITAR | D7: 0 | E7: 1 | F7: 1 | G7: 1 | H7: 1 | I7: 0.95 | J7: =+I7*D7 -> 0 | K7: 1 | L7: =+E7*D7 -> 0 | M7: =+F7*D7 -> 0 | N7: =+G7*D7 -> 0 | O7: =+H7*D7 -> 0 | R7: 0.95
C8: %Implementación CV | D8: 0 | I8: 1 | J8: =+I8*D8 -> 0 | K8: 1 | L8: =+E8*D8 -> 0 | M8: =+F8*D8 -> 0 | N8: =+G8*D8 -> 0 | O8: =+H8*D8 -> 0 | R8: 1
C9: Mapa de riesgo | D9: 0.04 | E9: 1 | F9: 1 | G9: 1 | H9: 1 | I9: 0.95 | J9: =+I9*D9 -> 0.038 | K9: 1 | L9: =+$D$9*E9 -> 0.04 | M9: =+$D$9*F9 -> 0.04 | N9: =+$D$9*G9 -> 0.04 | O9: =+$D$9*H9 -> 0.04 | R9: 0.95 | S9: 0.97
B10: E5 | C10: Accid.Incapacitantes 2010 | E10: 1 | F10: 1 | G10: 0 | H10: 2 | I10: 6 | K10: 7 | Q10: 13 | R10: 30 | S10: 36
C11: Accid.DMR 2010 | E11: 0 | F11: 0 | G11: 0 | H11: 0 | I11: 0 | K11: 0 | Q11: 1 | S11: 9
C12: Lesión Menor 2010 | E12: 1 | F12: 0 | G12: 0 | H12: 1 | I12: 9 | K12: 8 | Q12: 16 | R12: 97 | S12: 94
C13: Días de Descanso 2010 | E13: 30 | F13: 54 | G13: 0 | H13: 84 | I13: 150 | K13: 6068 | Q13: 271 | R13: 925 | S13: 8202
C14: HH trabajadas 2010 | E14: 153040 | F14: 108528 | G14: 61658 | H14: =SUM(E14:G14) -> 323226 | Q14: 2971176
C15: Ind.Frecuencia 2010 | E15: =+E10*1000000/E14 -> 6.5342394 | F15: =+F10*1000000/F14 -> 9.214212 | G15: =+G10*1000000/G14 -> 0 | H15: =+H10*1000000/H14 -> 6.187621 | I15: 4.77 | Q15: =+Q10*1000000/Q14 -> 4.3753719 | R15: 2.5
C16: Ind.Severidad 2010 | E16: =+E13*1000000/E14 -> 196.02718 | F16: =+F13*1000000/F14 -> 497.56745 | G16: =+G13*1000000/G14 -> 0 | H16: =+H13*1000000/H14 -> 259.88008 | I16: 119.3 | Q16: =+Q13*1000000/Q14 -> 91.209676 | R16: 78.22
C17: OSHA incident rate 2010 | E17: =(+E10+E11+E12)*200000/E14 -> 2.6136958 | F17: =(+F10+F11+F12)*200000/F14 -> 1.8428424 | G17: =(+G10+G11+G12)*200000/G14 -> 0 | H17: =(+H10+H11+H12)*200000/H14 -> 1.8562863 | I17: 2.39 | Q17: =+(Q10+Q11+Q12)*200000/Q14 -> 2.0194024 | R17: 2.2
C18: Accid.Incapacitantes (1 año) | E18: 5 | F18: 3 | G18: 0 | H18: 8 | Q18: 39
C19: Días de Descanso (1 año) | E19: 6049 | F19: 88 | G19: 0 | H19: =SUM(E19:G19) -> 6137 | Q19: 8389
C20: Total accidentes (1 año) | E20: 7 | F20: 7 | G20: 1 | H20: =SUM(E20:G20) -> 15 | Q20: =39+7+80 -> 126
C21: Ind.Frecuencia (1 año) | D21: 0.1 | E21: =5*1000000/E24 -> 8.3368765 | F21: =3*1000000/F24 -> 7.552813 | G21: =0*1000000/G24 -> 0 | H21: =+H18*1000000/H24 -> 6.2943357 | I21: 4.77 | J21: =+D21 -> 0.1 | K21: 5.57 | L21: =5.09/E21*D21 -> 0.061054041 | M21: =5.13/F21*D21 -> 0.067921713 | N21: =3.61/3.61*D21 -> 0.1 | O21: =I21/H21*D21 -> 0.075782421 | Q21: 3.3 | R21: 2.5 | S21: 3.05
C22: Ind.Severidad (1 año) | D22: 0.1 | E22: =6049*1000000/E24 -> 10085.953 | F22: =88*1000000/F24 -> 221.54918 | G22: =0*1000000/G24 -> 0 | H22: 4828.5 | I22: 119.3 | J22: =+D22 -> 0.1 | K22: 4828.05 | L22: =17.17/E22*D22 -> 0.00017023676 | M22: =128.25/F22*D22 -> 0.057887824 | N22: =90.19/90.19*D22 -> 0.1 | O22: =I22/H22*D22 -> 0.0024707466 | Q22: 710.8 | R22: 78.22 | S22: 694.94
C23: OSHA incident rate (1 año) | D23: 0.1 | E23: =E20*200000/E24 -> 2.3343254 | F23: =F20*200000/F24 -> 3.5246461 | G23: =G20*200000/G24 -> 0.72983112 | H23: 2.36 | I23: 2.39 | J23: =+D23 -> 0.1 | K23: 2.55 | L23: =2.37/2.37*D23 -> 0.1 | M23: =2.56/F23*D23 -> 0.072631406 | N23: =2.16/2.16*D23 -> 0.1 | O23: =I23/H23*D23 -> 0.10127119 | Q23: 2.1 | R23: 2.2 | S23: 2.36
C24: HH trabajadas (1 año) | E24: 599745 | F24: 397203 | G24: 274036 | H24: =SUM(E24:G24) -> 1270984 | Q24: 11801705
C25: Dias sin accidentes | E25: 8 | F25: 64 | G25: 507 | H25: 8 | Q25: 2
C26: Calidad Investigación | D26: 0.08 | E26: 0.8 | F26: 0.788 | G26: 1 | H26: 0.8 | I26: 0.85 | J26: =+I26*D26 -> 0.068 | K26: 0.7473 | L26: =+$D$26*E26 -> 0.064 | M26: =+$D$26*F26 -> 0.06304 | N26: =+$D$26*G26 -> 0.08 | O26: =+$D$26*H26 -> 0.064 | S26: 0.743
C27: %Levantamiento ROM´s | D27: 0.08 | E27: 0.75 | F27: 0.7714 | G27: 1 | H27: 0.7826 | I27: 0.95 | J27: =+I27*D27 -> 0.076 | K27: 0.9129 | L27: =+E27*D27 -> 0.06 | M27: =+F27*D27 -> 0.061712 | N27: =+G27*D27 -> 0.08 | O27: =+H27*D27 -> 0.062608 | Q27: 0.724 | R27: 0.95 | S27: 0.934
C28: %Identif.Actos Sub.ROM´s | D28: 0 | E28: 0.447 | F28: 0.8 | G28: 0.467 | H28: 0.5962 | I28: 0.5 | J28: =+I28*D28 -> 0 | K28: 0.7812 | L28: =+E28*D28 -> 0 | M28: =+F28*D28 -> 0 | N28: =+G28*D28 -> 0 | O28: =+H28*D28 -> 0 | R28: 0.5 | S28: 0.57
C29: %Particip.ROM´s (en el Semestre) | D29: 0 | E29: 0.4545 | F29: 0.4545 | G29: 0.22 | H29: 0.4047 | I29: 0.5 | J29: =+I29*D29 -> 0 | K29: 0.7 | L29: =+E29*D29 -> 0 | M29: =+F29*D29 -> 0 | N29: =+G29*D29 -> 0 | O29: =+H29*D29 -> 0 | Q29: 0.57 | R29: 0.5 | S29: 0.64
C30: %ROM´s Autofinalizadas | D30: 0 | E30: 0.43 | F30: 0.51 | G30: 0.25 | H30: 0.4506 | I30: 0.55 | J30: =+I30*D30 -> 0 | K30: 0.7169 | L30: =+E30*D30 -> 0 | M30: =+F30*D30 -> 0 | N30: =+G30*D30 -> 0 | O30: =+H30*D30 -> 0
B31: E6 | C31: Cumplimiento Prog.Observ | D31: 0.04 | E31: 1 | F31: 1 | G31: 1 | H31: 1 | I31: 0.95 | J31: =+I31*D31 -> 0.038 | K31: 1 | L31: =+E31*D31 -> 0.04 | M31: =+F31*D31 -> 0.04 | N31: =+G31*D31 -> 0.04 | O31: =+H31*D31 -> 0.04 | Q31: 0.88 | S31: 0.95
C32: %Comportam.Seguro | D32: 0.08 | E32: 1 | F32: 1 | G32: 0.95 | H32: 0.988 | I32: 0.9 | J32: =+I32*D32 -> 0.072 | K32: 0.99 | L32: =+E32*D32 -> 0.08 | M32: =+F32*D32 -> 0.08 | N32: =+G32*D32 -> 0.076 | O32: =+H32*D32 -> 0.07904 | Q32: 0.967 | R32: 0.9 | S32: 0.968
B33: E7 | C33: Evaluación Simulacros | D33: 0.05 | E33: 0.66 | F33: 0.82 | G33: 0.79 | H33: 0.69 | I33: 0.8 | J33: =+I33*D33 -> 0.04 | K33: 0.69 | L33: =+E33*D33 -> 0.033 | M33: =+F33*D33 -> 0.041 | N33: =+G33*D33 -> 0.0395 | O33: =+H33*D33 -> 0.0345 | S33: 0.89
C34: Participación Brigadas Niv.Liderazgo | D34: 0.02 | E34: 0.88 | F34: 0.64 | G34: 0.83 | H34: 0.78 | I34: 0.8 | J34: =+I34*D34 -> 0.016 | K34: 0.76 | L34: =+$H$34*$D$34 -> 0.0156 | M34: =+$H$34*$D$34 -> 0.0156 | N34: =+$H$34*$D$34 -> 0.0156 | O34: =+$H$34*$D$34 -> 0.0156 | R34: 0.8 | S34: 0.75
B35: E8 | C35: Efectividad Perm.Trabajo | D35: 0.05 | E35: 0.9881 | F35: 1 | G35: 0.9951 | H35: 0.9936 | I35: 0.95 | J35: =+I35*D35 -> 0.0475 | K35: 1 | L35: =+E35*D35 -> 0.049405 | M35: =+F35*D35 -> 0.05 | N35: =+G35*D35 -> 0.049755 | O35: =+H35*D35 -> 0.04968 | Q35: 0.964 | R35: 0.95 | S35: 0.977
C36: %Particip.Fiscalización Permisos | D36: 0 | E36: 0.27 | F36: 0.3636 | G36: 0.38 | H36: 0.3367 | I36: 0.7 | J36: =+I36*D36 -> 0 | K36: 0.6 | L36: =+E36*D36 -> 0 | M36: =+F36*D36 -> 0 | N36: =+G36*D36 -> 0 | O36: =+H36*D36 -> 0
B37: E11 | C37: %Cumplim.EPP | D37: 0.05 | E37: 0.9474 | F37: 0.9837 | G37: 0.909 | H37: 0.9399 | I37: 1 | J37: =+I37*D37 -> 0.05 | K37: 0.99 | L37: =+E37*D37 -> 0.04737 | M37: =+F37*D37 -> 0.049185 | N37: =+G37*D37 -> 0.04545 | O37: =+H37*D37 -> 0.046995 | S37: 0.98
B38: E12 | C38: Examen médico Ingresantes | D38: 0.03 | H38: 0.96 | I38: 0.95 | J38: =+I38*D38 -> 0.0285 | K38: 0.96 | L38: =+$H$38*$D$38 -> 0.0288 | M38: =+$H$38*$D$38 -> 0.0288 | N38: =+$H$38*$D$38 -> 0.0288 | O38: =+$H$38*$D$38 -> 0.0288 | S38: 0.92
C39: Examen preventivo | D39: 0.02 | H39: 0.97 | I39: 0.95 | J39: =+I39*D39 -> 0.019 | K39: 0.97 | L39: =+O39 -> 0.0194 | M39: =+O39 -> 0.0194 | N39: =+O39 -> 0.0194 | O39: =+H39*D39 -> 0.0194 | S39: 0.98
B40: E19 | C40: Homologación Proveedores | D40: 0.08 | H40: 0.79 | I40: 0.9 | J40: =+I40*D40 -> 0.072 | K40: 0.79 | L40: =+O40 -> 0.0632 | M40: =+O40 -> 0.0632 | N40: =+O40 -> 0.0632 | O40: =+H40*D40 -> 0.0632 | R40: 0.9 | S40: 0.8
C41: Total %TSPM | D41: =SUM(D4:D40) -> 1 | E41: =+L41 -> 0.76413128 | F41: =+M41 -> 0.80935394 | G41: =+N41 -> 0.949605 | H41: =+O41 -> 0.79149935 | I41: 0.95 | J41: =SUM(J4:J40) -> 0.939 | K41: 0.83395402 | L41: =SUM(L4:L40) -> 0.76413128 | M41: =SUM(M4:M40) -> 0.80935394 | N41: =SUM(N4:N40) -> 0.949605 | O41: =SUM(O4:O40)+0.004 -> 0.79149935 | R41: 0.9455 | S41: 0.718

Sheet NVO IOM
J1: ACUMULADO 2010 | N1: PROYECTADO 2010 | R1: DIC09 - NOV10
A2: MOL | C2: INCAPACIT | D2: DMR | E2: MENOR | F2: TOTAL | H2: DÍAS PERDIDOS | J2: IF | K2: IS | L2: OSHA | N2: IF | O2: IS | P2: OSHA | R2: IF | S2: IS | T2: OSHA | U2: Var.HH vs 2009
A3: MSR | B3: Dic | C3: 0 | D3: 0 | E3: 0 | F3: =+C3+D3+E3 -> 0 | H3: 0
B4: Acumulado | C4: 1 | D4: 0 | E4: 0 | F4: =+C4+D4+E4 -> 1 | H4: 30 | J4: 3.5334815 | K4: 106.00445 | L4: 0.7066963 | U4: 0.02
B5: obj 2010 | C5: 1 | D5: 0 | E5: 2 | F5: =+C5+D5+E5 -> 3 | H5: 25 | J5: 0.00 - 3.61 | K5: 0.00 - 90.19 | L5: 0.72 - 2.16
B6: 2009 | C6: 0 | D6: 0 | E6: 1 | F6: =+C6+D6+E6 -> 1 | H6: 0 | J6: 0 | K6: 0 | L6: 0.72
A7: MFA | B7: =+B3 -> Dic | C7: 1 | D7: 0 | E7: 0 | F7: =+E7+D7+C7 -> 1 | H7: 2
B8: Acumulado | C8: 4 | D8: 0 | E8: 1 | F8: =+C8+D8+E8 -> 5 | H8: 60 | J8: 8.77 | K8: 131.51 | L8: 2.19 | U8: 0.17
B9: obj 2010 | C9: 2 | D9: 0 | E9: 3 | F9: =+C9+D9+E9 -> 5 | H9: 50 | J9: 2.56 - 7.69 | K9: 64.1 - 192.4 | L9: 2.56 - 5.13
B10: 2009 | C10: 3 | D10: 0 | E10: 7 | F10: =+C10+D10+E10 -> 10 | H10: 49 | J10: 7.69 | K10: 125.68 | L10: 5.13
A11: MCA | B11: =+B3 -> Dic | C11: 0 | D11: 0 | E11: 1 | F11: =+C11+D11+E11 -> 1 | H11: 0
B12: Acumulado | C12: 4 | D12: 0 | E12: 4 | F12: =+C12+D12+E12 -> 8 | H12: 129 | J12: 6.29 | K12: 202.89 | L12: 2.52 | U12: 0.08
B13: obj 2010 | C13: 3 | D13: 0 | E13: 4 | F13: =+C13+D13+E13 -> 7 | H13: 75 | J13: 3.39 - 6.78 | K13: 84.8 - 169.6 | L13: 1.7 - 2.37
B14: 2009 | C14: 4 | D14: 0 | E14: 1 | F14: =+C14+D14+E14 -> 5 | H14: 6019 | J14: 6.78 | K14: 10205.67 | L14: 1.7
A15: Mol.Lima | B15: =+B3 -> Dic | C15: =+C11+C7+C3 -> 1 | D15: =+D11+D7+D3 -> 0 | E15: =+E11+E7+E3 -> 1 | F15: =+F11+F7+F3 -> 2 | H15: =+H11+H7+H3 -> 2
B16: Acumulado | C16: =+C12+C8+C4 -> 9 | D16: =+D12+D8+D4 -> 0 | E16: =+E4+E8+E12 -> 5 | F16: =+C16+D16+E16 -> 14 | H16: =+H12+H8+H4 -> 219 | J16: 6.55 | K16: 159.27 | L16: 2.04 | U16: 0.09
B17: obj 2010 | C17: =+C13+C9+C5 -> 6 | D17: =+D13+D9+D5 -> 0 | E17: =+E5+E9+E13 -> 9 | F17: =+C17+D17+E17 -> 15 | H17: =+H13+H9+H5 -> 150 | J17: 4.77 - 5.57 | K17: 54.10 - 119.3 | L17: 2.39 - 2.55
B18: 2009 | C18: =+C14+C10+C6 -> 7 | D18: =+D14+D10+D6 -> 0 | E18: =+E6+E10+E14 -> 9 | F18: =+C18+D18+E18 -> 16 | H18: =+H14+H10+H6 -> 6068 | J18: 5.57 | K18: 4828.1 | L18: 2.55

Sheet HISTORICO ACCIDENTES
A1: ROM | B1: PROGRAMA | C1: LUGAR | D1: AREA RESPONSABILIDAD | E1: NOMBRE | F1: Edad | G1: Puesto de Trabajo | H1: SEXO | I1: TURNO | J1: Experiencia en el Puesto Trabajo | K1: Fecha | L1: GG | M1: Descripción del Accidente de Trabajo | N1: Parte Cuerpo | O1: Año | P1: Mes | Q1: Días Perdidos x Lesión | R1: Cargo ANSI | S1: Dias + ansi | T1: FUENTE PELIGRO | U1: Actividad | V1: TIPO DE CONTACTO | W1: DAÑO | X1: Contrata | Y1: NOTA MIDOT | Z1: MODALIDAD
B2: SIDSUR | C2: SIDSUR | D2: DISTRIBUCIÓN | E2: Oswaldo Andrade Torres | F2: 46 | G2: Operador Montacarga Eléctrico Supervisor | H2: M | I2: 2do | K2: 28/04/2015 20:30 | L2: Accidente Incapacitante | M2: Esguince de tobillo durante un cambio de batería de elevador eléctrico | N2: PIE | O2: 2015 | P2: Abril | Q2: 7 | S2: 7 | T2: Batería | U2: Maniobras de equipos | W2: Esguince
B3: MOLINO SANTA ROSA | C3: MOLINO SANTA ROSA | D3: PROYECTOS | E3: Eder García Isla | F3: 29 | G3: TERCERO | H3: M | I3: 1ro | K3: 29/09/2015 13:30 | L3: Accidente Incapacitante | M3: Escobilla metálica impacta contra structura ocasionándo corte de guante y herida en el dedo índice durante limpieza mecánica. | N3: MANO | O3: 2015 | P3: Setiembre | Q3: 1 | S3: 1 | T3: Escobilla metálica | U3: proyectos | W3: Corte | X3: AC y M
B4: MOLINO FAC | C4: MOLINO FAUCETT | D4: MANTENIMIENTO | E4: Robert Anaya Esteban | F4: 42 | G4: Ayudante de Planta | H4: M | I4: 1ro | K4: 23/04/2015 13:30 | L4: Accidente Incapacitante | M4: Corte de antepalma mano izquierda por caída de vidrio. | N4: MANO | O4: 2015 | P4: Abril | Q4: 84 | S4: 84 | T4: Vidrio | U4: Durante operación productiva | W4: Corte
B5: TEAL | C5: CARAMELOS | D5: PRODUCCIÓN | E5: James Robert Choquehuanca Montalvo | F5: 50 | G5: Maquinista | H5: M | I5: 2do | K5: 17/04/2015 18:18 | L5: Accidente Incapacitante | M5: Herida cortante abierta 1ra falange dedo pulgar mano derecha | N5: MANO | O5: 2015 | P5: Abril | Q5: 51 | S5: 51 | T5: Equipo | U5: Calibrando/Regulando | W5: Corte
B6: si | C6: APT CERCADO | D6: DISTRIBUCIÓN | E6: Matías Alva Soto | F6: 55 | G6: TERCERO | H6: M | I6: 1ro | K6: 09/11/2015 13:45 | L6: Accidente Incapacitante | M6: Manipulación de stocka durante estiba en contenedor produce golpe en la pierna del accidentado. Herida abierta. | N6: PIERNA | O6: 2015 | P6: Noviembre | Q6: 3 | S6: 3 | T6: Stocka | U6: carga/descarga de camión | W6: Golpe | X6: IOLSA
B7: si | C7: CDC | D7: DISTRIBUCIÓN | E7: Edwin Roy Cabrera Chuquihuaccha | F7: 26 | G7: Ayudande de almacén B | H7: M | I7: 3ro | K7: 14/08/2015 04:05 | L7: Accidente Incapacitante | M7: Golpe en la pierna y tobillo por order piker | N7: PIE | O7: 2015 | P7: Agosto | Q7: 16 | S7: 16 | T7: Order Piker | U7: Manejando traspaleta/Montacarga | W7: Golpe
B8: si | C8: FIDEERIA LIMA | D8: PRODUCCIÓN | E8: Miguel Tolentino Escudero | F8: 45 | G8: Mecánico | H8: M | I8: 1ro | K8: 24/08/2015 09:05 | L8: Accidente Incapacitante | M8: Amputación tercio distal del dedo índice por cambio de rótula del regulador de fideos. | N8: MANO | O8: 2015 | P8: Agosto | Q8: 139 | R8: 100 | S8: 239 | T8: Equipo | U8: Mantenimiento | W8: Pérdida Falanges
B9: TEAL | C9: CARAMELO | D9: PRODUCCIÓN | E9: Julio Cesar Muñoz Garfias | F9: 32 | G9: Operario de producción | H9: M | I9: 1ro | K9: 05/08/2015 09:20 | L9: Accidente Incapacitante | M9: Herida contusa abierta en la 1ra y 2da falange del segundo dedo de la mano por atrapamiento en su intento de acomodar la masa de caramelo en la guia de la maquina | N9: MANO | O9: 2015 | P9: Agosto | Q9: 33 | S9: 33 | T9: Equipo | U9: Mantenimiento | W9: Corte
B10: TEAL | C10: PANETONES | D10: PRODUCCIÓN | E10: Precy Cesar Ruiz Secaira | F10: 41 | G10: Operario de producción | H10: M | I10: 2do | K10: 14/08/2015 15:20 | L10: Accidente Incapacitante | M10: Herida cortante abierta en 3er dedo de la mano derecha por contacto con cuchillo, mientras se manipulaba la masa de panetón hacia la olla. | N10: MANO | O10: 2015 | P10: Agosto | Q10: 15 | S10: 15 | T10: cuchillo | U10: Durante operación productiva | W10: Corte
B11: TEAL | C11: CARAMELOS | D11: PRODUCCIÓN | E11: Alex Mateo Aguilar Estrella | F11: 31 | G11: Operario de producción | H11: M | I11: 2do | K11: 24/08/2015 15:05 | L11: Accidente Incapacitante | M11: Amputación traumática parcial de la falange distal del tercer dedo de la mano izquierda por atrapamiento de dedo por mordaza accionada accidentalmente por el mismo accidentado. | N11: MANO | O11: 2015 | P11: Agosto | Q11: 144 | R11: 75 | S11: 219 | T11: Equipo | U11: Mantenimiento | W11: Pérdida Falanges
B12: si | C12: GALLETERA LIMA | D12: PROYECTOS | E12: Nicolás Mauricio Toledo Pachas | F12: 23 | G12: TERCERO | H12: M | I12: 1ro | K12: 10/06/2015 14:50 | L12: Accidente Incapacitante | M12: Baranda del primer nivel de andamio cae sobre casco del trabajador mientras retiraba una soga. | N12: CABEZA | O12: 2015 | P12: Junio | Q12: 1 | S12: 1 | T12: Andamio | U12: proyectos | W12: Golpe | X12: BUILMEP
B13: si | C13: NUTRICION ANIMAL TRUJILLO | D13: PRODUCCIÓN | E13: Juan Carlos Horna Bocanegra | G13: Operador de rociado | H13: M | I13: 3ro | K13: 20/08/2015 11:05 | L13: Accidente Incapacitante | M13: Esguince en el tobillo izquierdo al bajar de un montacargas | N13: PIE | O13: 2015 | P13: Agosto | Q13: 7 | S13: 7 | T13: Altura | U13: Manejando traspaleta/Montacarga | W13: Esguince
B14: TEAL | C14: GALLETAS | D14: OTROS | E14: Omar Jesus Silva Leyton | F14: 36 | G14: TERCERO | H14: M | I14: 1ro | J14: Accidente Incapacitante | K14: 18/04/2015 15:00 | L14: Accidente Incapacitante | M14: Herida contusa abierta en la frente, contusión parte posterior de la cabeza y luxación dedo medio de la mano derecha. | N14: CUERPO | O14: 2015 | P14: Abril | Q14: 21 | S14: 21 | T14: Andamio | U14: Mantenimiento | W14: Golpe
B15: si | C15: MOLINO SANTA ROSA | D15: PROYECTOS | E15: Rafael Fermin Rosales Mendoza | F15: 36 | G15: TERCERO | H15: M | I15: 1ro | K15: 09/07/2015 15:00 | L15: Accidente Incapacitante | M15: Fractura en 2°, 3° y 4° metacarpiano de la mano derecha y laceración del brazo izquierdo por impacto con listón de madera desprendida. | N15: BRAZO/HOMBRO | O15: 2015 | P15: Julio | Q15: 35 | S15: 35 | T15: Madero | U15: proyectos | W15: Golpe | X15: AC&M
B16: si | C16: COPSA | D16: PRODUCCIÓN | E16: Constante Mendocilla Diestra | F16: 63 | G16: LIDER LINEA EXTRACCION MECANICA | H16: M | I16: 1ro | K16: 27/08/2015 11:10 | L16: Accidente Incapacitante | M16: Traumatismo en cabeza y heridas en el rostro por choque con parte posterior de camión mientras manejaba bicicleta. | N16: CABEZA | O16: 2015 | P16: Agosto | Q16: 16 | S16: 16 | T16: Bicicleta | U16: Trasladandose | W16: Golpe
B17: si | C17: NUTRICION ANIMAL TRUJILLO | D17: VITAPRO | K17: 42356 | L17: Accidente Incapacitante | M17: Esquince en el hombro derecho durante el repaletizado de sacos de harina | N17: BRAZO/HOMBRO | O17: 2015 | P17: Diciembre | Q17: 5 | S17: 5 | T17: Sacos | U17: Durante operación productiva | W17: Esguince
B18: si | C18: DETERGENTES | D18: PRODUCCIÓN | E18: Benigno Huamán Corillo | F18: 29 | G18: Ayudante de Planta | H18: M | I18: 3ro | K18: 17/12/2015 05:46 | L18: Accidente Incapacitante | M18: Durante conducción en reversa de tranpaleta eléctrico, el trabajador se baja y su pie queda atrapado entre plataforma y ruma de paletas | N18: PIE | O18: 2015 | P18: Diciembre | Q18: 11 | S18: 11 | T18: ERE | U18: Manejando traspaleta/Montacarga | W18: Golpe
B19: si | C19: INSTANTANEOS | D19: PRODUCCIÓN | E19: Jhon Janic Vela Sandoval | F19: 32 | G19: Mezclador Instantáneos | H19: M | I19: 2do | J19: 7 años y 10 meses | K19: 17/01/2015 19:20 | L19: Accidente Incapacitante | M19: Contusión en pie derecho por aplastamiento con plataforma de acero (equipo de mezclado). Breña | N19: PIE | O19: 2015 | P19: Enero | Q19: 20 | S19: 20 | T19: Plataforma de acero | U19: Durante operación productiva | W19: Golpe
B20: si | C20: DETERGENTES | D20: ALMACEN DE INSUMOS | E20: Andrés Avelino Quispe Carhuaz | F20: 51 | G20: TERCERO | H20: M | I20: 1ro | J20: 3 años | K20: 14/01/2015 10:59 | L20: Accidente Incapacitante | M20: Golpe e inflamación de pierna izquierda por estoca de montacargas. Detergentes | N20: PIERNA | O20: 2015 | P20: Enero | Q20: 2 | S20: 2 | T20: Stocka | U20: Maniobras de equipos | W20: Golpe | X20: BAS PERUANA TRANSPORTES GIRASOLES
B21: si | C21: VITAPRO | D21: CENTRO EXPERIMENTAL - TUMBES | E21: Juan Pablo Moreno Peña | H21: M | K21: 42276.698 | L21: Accidente Incapacitante | M21: cintas metálicas del alimentador enrolladas a presión se rompe y se expande súbitamente, ocasionándole un corte en la parte superior de la mano derecha | N21: MANO | O21: 2015 | P21: Setiembre | Q21: 15 | S21: 15 | T21: Equipo | U21: Durante operación productiva | W21: Corte
B22: TEAL | C22: APT | D22: DISTRIBUCIÓN | E22: Eujenio Baldeon Cosme | F22: 0 | G22: TERCERO | H22: M | I22: 1ro | K22: 17/10/2015 16:10 | L22: Accidente Incapacitante | M22: Contusión en el hombro izquiero por impacto con liston de metal durante estibado de producto terminado | N22: BRAZO/HOMBRO | O22: 2015 | P22: Octubre | Q22: 4 | S22: 4 | T22: Camión | U22: carga/descarga de camión | W22: Golpe | X22: IOLSA
B23: si | C23: PROYECTOS | D23: PROYECTOS | E23: Freddy Rodriguez Chinchay | G23: TERCERO | H23: M | I23: 1ro | K23: 42353 | L23: Accidente Incapacitante | M23: Quemadura en dedo durante trabajo de soldadura | N23: MANO | O23: 2015 | P23: Diciembre | Q23: 16 | S23: 16 | T23: Soldadura | U23: proyectos | W23: Quemadura | X23: MANPAN
B24: si | C24: MOLINCA | D24: PRODUCCIÓN | E24: Pedro Ynfantes Vasquez | F24: 36 | G24: Preparador de Cremas | H24: M | I24: 2do | K24: 03/12/2015 20:05 | L24: Accidente Incapacitante | M24: Atrapamiento de mano y antebrazo derecho mientras realiza labores de dosificador de sal en máquina esparcidora | N24: MANO | O24: 2015 | P24: Diciembre | Q24: 60 | S24: 60 | T24: Equipo en Movimiento | U24: Limpiando equipo | W24: Fractura
B25: si | C25: SIDSUR | D25: PRODUCCIÓN | E25: Vitaliano Silloca Silloca | F25: 41 | G25: Pesador de ingredientes | H25: M | I25: 1ro | J25: 12 años y 8 meses | K25: 27/01/2015 08:30 | L25: Accidente Incapacitante | M25: Luxación-hombro por resbalón durante la limpieza y lavado de escalera de emergencia. Galletera | N25: BRAZO/HOMBRO | O25: 2015 | P25: Enero | Q25: 30 | S25: 30 | T25: Instalación | U25: Limpiando instalaciones | W25: Luxación
B26: si | C26: CDC | D26: DISTRIBUCIÓN | E26: Juan Jibaja Rojas | F26: 42 | G26: TERCERO | H26: M | I26: 1ro | J26: 10 años | K26: 30/01/2015 14:20 | L26: Accidente Incapacitante | M26: Impacto con neumático de montacargas en el tobillo genera una contusión. CDC | N26: PIERNA | O26: 2015 | P26: Enero | Q26: 261 | S26: 261 | T26: Montacargas | U26: Manejando traspaleta/Montacarga | W26: Golpe | X26: Transportes Pacífico
B27: si | C27: DETERGENTES | D27: MANTENIMIENTO | E27: José Danilo Llanos Mego | F27: 28 | G27: Técnico Mecánico | H27: M | I27: 1ro | K27: 17/01/2015 09:30 | L27: Accidente Incapacitante | M27: Fractura y corte de ligamento dedo meñique de mano derecha por atratamiento con compuerta de acero; máquina HH N°5 | N27: MANO | O27: 2015 | P27: Enero | Q27: 110 | S27: 110 | T27: Equipo | U27: Mantenimiento | W27: Fractura
B28: si | C28: COPSA | D28: PROYECTOS | E28: Samuel Chávez Tinoco | F28: 34 | G28: TERCERO | H28: M | I28: 1ro | K28: 28/01/2015 11:10 | L28: Accidente Incapacitante | M28: Exposición a gas (amoniaco) genera una afección respiratoria en azotea de planta Margarinas | N28: AFECCIÓN RESPIRATORIA | O28: 2015 | P28: Enero | Q28: 2 | S28: 2 | T28: Sustancia Quimica | U28: proyectos | W28: Contacto sustancia Quimica | X28: ALTA
B29: si | C29: COPSA | D29: PROYECTOS | E29: Cristian Javier Arias Medina | F29: 39 | G29: TERCERO | H29: M | I29: 1ro | K29: 28/01/2015 11:10 | L29: Accidente Incapacitante | M29: Exposición a gas (amoniaco) genera una cefalea en azotea de planta Margarinas | N29: AFECCIÓN RESPIRATORIA | O29: 2015 | P29: Enero | Q29: 1 | S29: 1 | T29: Sustancia Quimica | U29: proyectos | W29: Contacto sustancia Quimica | X29: ALTA
B30: si | C30: DETERGENTES | D30: PRODUCCIÓN | E30: Bruno Díaz | F30: 26 | G30: Ayudante | H30: M | I30: 3ro | K30: 04/02/2015 02:20 am | L30: Accidente Incapacitante | M30: Fractura de muñequa. Trabajador resbala y todo su peso cae sobre su cadera y muñequa. | N30: MANO | O30: 2015 | P30: Febrero | Q30: 24 | S30: 24 | T30: Piso | U30: Trasladandose | W30: Fractura
B31: si | C31: MOLINO CALLAO | D31: DISTRIBUCIÓN | E31: Joaquin Oscco Chati | F31: 47 | G31: TERCERO | H31: M | I31: 2do | K31: 22/12/2015 20:15 | L31: Accidente Incapacitante | M31: Durante operación de repaletizado trabajador siente un fuerte dolor en la rodilla izquierda. Esguince en menisco. | N31: PIERNA | O31: 2015 | P31: Diciembre | Q31: 8 | S31: 8 | T31: Saco | U31: Durante operación productiva | W31: Esguince | X31: IOLSA
C32: GALLETERA LIMA | D32: ADMINISTRACIÓN | E32: Hilda Vásquez Segovia | G32: TERCERO | H32: F | I32: 2do | K32: 17/03/2015 21:20 | L32: Accidente Incapacitante | M32: Policontusa al resbalarse en los SSHH | N32: CUERPO | O32: 2015 | P32: Marzo | Q32: 2 | S32: 2 | T32: Piso | U32: Trasladandose | W32: policontusa | X32: LIMTEK
B33: si | C33: DETERGENTES | D33: PRODUCCIÓN | E33: Percy Antonio Carranza Izaguirre | F33: 40 | G33: Operador de Máquina Envasadora | H33: M | I33: 3ro | K33: 25/02/2015 03:20 | L33: Accidente Incapacitante | M33: Atrapamiento con mordaza horizontal de máquina envasadora. Corte y quemadura 2do grado | N33: MANO | O33: 2015 | P33: Febrero | Q33: 59 | S33: 59 | T33: Equipo | U33: Calibrando/Regulando | W33: Atricción
B34: si | C34: NUTRICION ANIMAL TRUJILLO | D34: VITAPRO | E34: Iván Fuentes De La Cruz | F34: 19 | G34: TERCERO | H34: M | I34: 1ro | K34: 10/03/2015 13:45 | L34: Accidente Incapacitante | M34: Esguince 2do Grado Pulgar Mano Derecho durante limpieza en Lavatorio | N34: MANO | O34: 2015 | P34: Marzo | Q34: 7 | S34: 7 | T34: Equipo | U34: Limpiando equipo | W34: Esguince | X34: LIMTEK
B35: si | C35: CDC | D35: DISTRIBUCIÓN | E35: Franque Leonel Reluz Sosa | F35: 29 | G35: Ayudante de paletizador | H35: M | I35: 1ro | K35: 04/06/2015 14:20 | L35: Accidente Incapacitante | M35: coge uno de los fardos de detergentes apoyando el dorso de la mano derecha sobre la faja, esto ocasionó que la faja arrastre su mano en dirección del movimiento y quede atrapada entre el protector del rodillo y la faja | N35: MANO | O35: 2015 | P35: Junio | Q35: 26 | S35: 26 | T35: Faja en movimiento | U35: Durante operación productiva | W35: Quemadura
B36: si | C36: COPSA | D36: PRODUCCIÓN | E36: Hector Albites Neyra | F36: 41 | G36: Operador volante de aceites | H36: M | I36: 1ro | K36: 08/06/2015 15:00 | L36: Accidente Incapacitante | M36: corte en los dedos índice y medio de la mano izquierda con una cuchilla retráctil, debido a que la tenía sujetada con la hoja de corte expuesta, al momento de entregarla al Sr. Rojas. | N36: MANO | O36: 2015 | P36: Junio | Q36: 48 | S36: 48 | T36: Cuchilla | U36: Otros | W36: Corte
B37: si | C37: MOLINCA | D37: PRODUCCIÓN | E37: Anselmo Mendoza Acevedo | F37: 58 | H37: M | I37: 1ro | K37: 25/03/2015 07:35 | L37: Accidente Incapacitante | M37: Pérdida de falanges distales de dedo Índice y dedo medio de la mano derecha al intentar asegurar visor del volumétrico | N37: MANO | O37: 2015 | P37: Marzo | Q37: 90 | R37: 175 | S37: 265 | T37: Equipo | U37: Mantenimiento | W37: Pérdida Falanges
B38: si | C38: MOLINO CALLAO | D38: DISTRIBUCIÓN | E38: Juan José Chinguel Carhuayocllo | F38: 27 | G38: TERCERO | H38: M | I38: 2do | J38: Accidente Incapacitante | K38: 22/04/2015 16:00 | L38: Accidente Incapacitante | M38: Esguince Tobillo derecho (IOLSA) por golpe con montacarga durante carga del contenedor | N38: PIE | O38: 2015 | P38: Abril | Q38: 4 | S38: 4 | T38: Montacargas | U38: Manejando traspaleta/Montacarga | W38: Esguince | X38: IOLSA
B39: TEAL | C39: APT | D39: DISTRIBUCIÓN | E39: Edgar Gaber Turpo Quispe | F39: 41 | G39: TERCERO | H39: M | I39: 2do | K39: 05/06/2015 15:45 | L39: Accidente Incapacitante | M39: Chofer desplaza las puertas horizontalmente y dedo meñique queda atrapado entre puertas laterales. | N39: MANO | O39: 2015 | P39: Junio | Q39: 16 | S39: 16 | T39: Camión | U39: carga/descarga de camión | W39: Golpe | X39: Transportes CR
B40: TEAL | C40: CARAMELOS | D40: PRODUCCIÓN | E40: Augusto Vladimir Córdova | F40: 34 | G40: Operario de producción | H40: M | I40: 1ro | K40: 08/06/2015 12:18 | L40: Accidente Incapacitante | M40: Baja la compuerta con la mano izquierda dejando el dedo medio de la mano derecha expuesto en el marco de la compuerta aprisionando dicho dedo y causándole la lesión . | N40: MANO | O40: 2015 | P40: Junio | Q40: 95 | S40: 95 | T40: Equipo | U40: Durante operación productiva | W40: Golpe
...

Sheet HH 3EROS
A1: SEDES | B1: Ene | C1: Feb | D1: Mar | E1: Abr | F1: May | G1: Jun | H1: Jul | I1: Ago | J1: Set | K1: Oct | L1: Nov | M1: Dic
A2: Almacén Suc.Pucallpa | B2: 890 | C2: 1020 | D2: 960 | E2: 916 | F2: 924 | G2: 0 | H2: 0 | I2: 0 | J2: 0 | K2: 0 | L2: 0 | M2: 0 | N2: Los Jefes de DC
A3: Almacén Suc.Tarapoto | B3: 182 | C3: 168 | D3: 182 | E3: 632 | F3: 650 | G3: 0 | H3: 0 | I3: 0 | J3: 0 | K3: 0 | L3: 0 | M3: 0
A4: Almacén Suc.Chiclayo | B4: 9918 | C4: 8999 | D4: 9772 | E4: 9454 | F4: 10090 | G4: 9837 | H4: 9550 | I4: 9877 | J4: 9877 | K4: 9379 | L4: 9487 | M4: 9487
A5: Almacén Suc.Trujillo | B5: 6474 | C5: 6148 | D5: 6022 | E5: 5357 | F5: 5499 | G5: 5297 | H5: 5184 | I5: 5456 | J5: 5456 | K5: 4796 | L5: 4767 | M5: 4537
A6: Almacén Suc.Cusco | B6: 10000 | C6: 12000 | D6: 12200 | E6: 12200 | F6: 12200 | G6: 12200 | H6: 12200 | I6: 12200 | J6: 12200 | K6: 12200 | L6: 12200 | M6: 11500
A7: Almacén Suc.Huánuco | B7: 0 | C7: 0 | D7: 0 | E7: 0 | F7: 0 | G7: 0 | H7: 0 | I7: 0 | J7: 0 | K7: 0 | L7: 0 | M7: 0
A8: Almacén Suc.Piura | B8: 4542 | C8: 4648 | D8: 6003 | E8: 4973 | F8: 5729 | G8: 6215 | H8: 5937 | I8: 6188 | J8: 5997 | K8: 6039 | L8: 7641 | M8: 6648
A9: Almacén Suc.Iquitos | B9: 584 | C9: 645 | D9: 540 | E9: 584 | F9: 610 | G9: 610 | H9: 610 | I9: 0 | J9: 0 | K9: 0 | L9: 0
A10: Sidsur - Adm (SCAST) | B10: 0 | C10: 0 | D10: 0 | E10: 0 | F10: 0 | G10: 0 | H10: 0 | I10: 0 | J10: 0 | K10: 0 | L10: 0 | M10: 0
A11: Sidsur - RRLL (SCAST) | B11: 0 | C11: 0 | D11: 0 | E11: 0 | F11: 0 | G11: 0 | H11: 0 | I11: 0 | J11: 0 | K11: 0 | L11: 0 | M11: 0
A12: Sidsur - Producción (SCAST) | B12: 0 | C12: 0 | D12: 0 | E12: 0 | F12: 0 | G12: 0 | H12: 0 | I12: 0 | J12: 0 | K12: 0 | L12: 0 | M12: 0 | N12: X
A13: Sidsur - Proyectos (SCAST) | B13: 0 | C13: 0 | D13: 0 | E13: 0 | F13: 0 | G13: 0 | H13: 0 | I13: 0 | J13: 0 | K13: 0 | L13: 0 | M13: 0
A14: Sidsur - Distribución (SCAST) | B14: 0 | C14: 0 | D14: 0 | E14: 0 | F14: 0 | G14: 0 | H14: 0 | I14: 0 | J14: 0 | K14: 0 | L14: 0 | M14: 0
A15: Predio Central - Adm (SCAST) | B15: 35169.06 | C15: 28920.71 | D15: 33982.76 | E15: 35523.34 | F15: 32470.82 | G15: 44835.14 | H15: 38872.76 | I15: 45661.08 | J15: 52570.61 | K15: 56459.16 | L15: 47023.81 | M15: =22030.28+370+1097+726+7493 -> 31716.28 | N15: Nuevo SCAST 2.0
A16: Predio Central - RRLL (SCAST) | B16: 0 | C16: 0 | D16: 0 | E16: 0 | F16: 0 | G16: 0 | H16: 311.63 | I16: 264.74 | J16: 316.07 | K16: 409.58 | L16: 416.51 | M16: =182.13+613 -> 795.13
A17: Predio Central - Galleteria (SCAST) | B17: 7892.81 | C17: 7360.16 | D17: 10810.17 | E17: 10018.19 | F17: 18201.05 | G17: 17141.38 | H17: 18601.79 | I17: 16404.26 | J17: 10865.7 | K17: 14501.42 | L17: 9205.04 | M17: =4767.36+2806 -> 7573.36
A18: Predio Central - MFA (SCAST) | B18: 7043.87 | C18: 4818.61 | D18: 5749.88 | E18: 6576.86 | F18: 9054.64 | G18: 6909.47 | H18: 14315.56 | I18: 7197.9 | J18: 19320.1 | K18: 4943.91 | L18: 7161.62 | M18: =3292.03+5423 -> 8715.03
A19: Predio Central - Fideeria (SCAST) | B19: 7565.71 | C19: 11566.96 | D19: 12050.61 | E19: 13854.92 | F19: 11464.27 | G19: 15203.68 | H19: 7712.79 | I19: 10453.69 | J19: 11299.53 | K19: 7714.67 | L19: 9828.21 | M19: =4789.98+430 -> 5219.98
A20: Predio Central - Copsa (SCAST) | B20: 39399.65 | C20: 32294.81 | D20: 30396.56 | E20: 33838.53 | F20: 57060 | G20: 19013.49 | H20: 27679.37 | I20: 13181.85 | J20: 12234.48 | K20: 22938.93 | L20: 17675.27 | M20: =11911.9+11043 -> 22954.9
A21: Predio Central - Detergentes (SCAST) | B21: 7523.3 | C21: 6719.16 | D21: 7208.3 | E21: 8325.64 | F21: 8749.75 | G21: 8639.79 | H21: 6857.84 | I21: 3682.37 | J21: 5172.23 | K21: 6811.89 | L21: 3864.5 | M21: =114.35+552 -> 666.35
A22: Predio Central - Jaboneria (SCAST) | B22: 5.51 | C22: 0 | D22: 42.72 | E22: 1963.45 | F22: 44.65 | G22: 64.16 | H22: 2127.81 | I22: 1831.15 | J22: 30.31 | K22: 48.68 | L22: 1844.96 | M22: 221.36
A23: Predio Central - Proyectos (SCAST) | B23: 32478.94 | C23: 26241.3 | D23: 33890.53 | E23: 34188.98 | F23: 15053.48 | G23: 38346.18 | H23: 32240.63 | I23: 39739.84 | J23: 46508.94 | K23: 36744.2 | L23: 20489.6 | M23: =7906.31+90+5855+443+5890 -> 20184.31
A24: Predio Central - Distribución (SCAST) | B24: 9144.5 | C24: 9921.12 | D24: 12201.03 | E24: =401.23+6262.15 -> 6663.38 | F24: =220.03+8645.16 -> 8865.19 | G24: =223.84+13964.81 -> 14188.65 | H24: =351.75+9250.49 -> 9602.24 | I24: =912.48+704.43 -> 1616.91 | J24: =6514.44+435.27 -> 6949.71 | K24: =5963.54+572.92 -> 6536.46 | L24: =2009.61+8002.15 -> 10011.76 | M24: =860.33+4753.57+105+365+87 -> 6170.9
A25: MSR - Adm (SCAST) | B25: 2591 | C25: 3177.79 | D25: 3598.47 | E25: 3601.91 | F25: 1968.56 | G25: 5176.15 | H25: 5704.97 | I25: 4968.03 | J25: 6161.68 | K25: 6684.38 | L25: 6229.86 | M25: =3630.9+606 -> 4236.9
A26: MSR - RRLL (SCAST) | B26: 0 | C26: 0 | D26: 0 | E26: 0 | F26: 0 | G26: 0 | H26: 0 | I26: 0 | J26: 0 | K26: 0 | L26: 0 | M26: 0
A27: MSR - Producción (SCAST) | B27: 1930.57 | C27: 1366.81 | D27: 2341.97 | E27: 2380.62 | F27: 5314.12 | G27: 1657.07 | H27: 1023.12 | I27: 1848.74 | J27: 2275.66 | K27: 1595.54 | L27: 2410.88 | M27: =1556.86+302 -> 1858.86
A28: MSR - Proyectos (SCAST) | B28: 0 | C28: 1.66 | D28: 20.05 | E28: 6.1 | F28: 56.05 | G28: 0 | H28: 61.99 | I28: 15.61 | J28: 0 | K28: 2.09 | L28: 0 | M28: 768
A29: MSR - Distribución (SCAST) | B29: 1090.71 | C29: 1300.03 | D29: 1582.41 | E29: 1472.28 | F29: 1221.1 | G29: 1717.18 | H29: 1405.66 | I29: 1445.88 | J29: 1577.69 | K29: 1217.48 | L29: 1333.9 | M29: =804.78+48 -> 852.78
A30: MCA - Adm (SCAST) | B30: 4794.17 | C30: 3879.2 | D30: 5439.09 | E30: 6893.39 | F30: 5861.07 | G30: 4418.82 | H30: 7651.55 | I30: 7611.89 | J30: 8274.43 | K30: 9274.2 | L30: 8645.18 | M30: =4650.06+3745 -> 8395.06
A31: MCA - RRLL (SCAST) | B31: 0 | C31: 0 | D31: 0 | E31: 0 | F31: 0 | G31: 0 | H31: 7.77 | I31: 44.77 | J31: 0 | K31: 24.77 | L31: 3.36 | M31: 0
A32: MCA - Producción (SCAST) | B32: 10463.12 | C32: 10861.54 | D32: 12978.18 | E32: 15685.1 | F32: 18397.81 | G32: 17706.45 | H32: 13459.4 | I32: 11426.02 | J32: 7068.01 | K32: 7468.44 | L32: 8283.75 | M32: =4529.43+5771 -> 10300.43
A33: MCA - Proyectos (SCAST) | B33: 6069.09 | C33: 4636.23 | D33: 4544.34 | E33: 3706.49 | F33: 6777.7 | G33: 3253.68 | H33: 3835.74 | I33: 2450.92 | J33: 4118.57 | K33: 1795.41 | L33: 5513.47 | M33: =4467.77+3319 -> 7786.77
A34: MCA - Distribución (SCAST) | B34: 5007.22 | C34: 3836.94 | D34: 5291.45 | E34: 4330.09 | F34: 5942.41 | G34: 5865.25 | H34: 5707.58 | I34: 5243.12 | J34: 6010.15 | K34: 6246.08 | L34: 4954.3 | M34: =2586.24+186 -> 2772.24
A35: CD HUACHIPA - Adm (SCAST) | B35: 2316.15 | C35: 7376.68 | D35: 3536.29 | E35: 6134.41 | F35: 6224.01 | G35: 7591.66 | H35: 8726.02 | I35: 8533.81 | J35: 6980.84 | K35: 7612.63 | L35: 6329.11 | M35: 4184.95
A36: CD HUACHIPA - RRLL (SCAST) | B36: 0 | C36: 0 | D36: 0 | E36: 0 | F36: 0 | G36: 0 | H36: 0 | I36: 46.27 | J36: 0 | K36: 0 | L36: 0 | M36: 0
A37: CD HUACHIPA - Producción (SCAST) | B37: 0 | C37: 56.48 | D37: 115.73 | E37: 0 | F37: 263.43 | G37: 2882.59 | H37: 207.07 | I37: 0 | J37: 12.64 | K37: 629.54 | L37: 159.4 | M37: 0
A38: CD HUACHIPA - Proyectos (SCAST) | B38: 0 | C38: 0 | D38: 77.46 | E38: 0 | F38: 7.16 | G38: 0 | H38: 0 | I38: 24.34 | J38: 453.61 | K38: 0 | L38: 0 | M38: 0
A39: CD HUACHIPA - Distribución (SCAST) | B39: 3585.44 | C39: 1088.24 | D39: 3234.88 | E39: 3723.64 | F39: 3130.3 | G39: 2624.08 | H39: 6082.39 | I39: 5159.91 | J39: 9847.16 | K39: 6869.38 | L39: 7191.71 | M39: 4557.62
A40: VIG MCA - VISITAS | B40: 584 | C40: 458 | D40: 384 | E40: 377 | F40: 671 | G40: 394 | H40: 393 | I40: 411 | J40: 360 | K40: 348 | L40: 379 | M40: 347 | N40: Enviado por vigilancia 5
...

Sheet HH ALICORP
A2: Sede | B2: Enero | C2: Febrero | D2: Marzo | E2: Abril | F2: Mayo | G2: Junio | H2: Julio | I2: Agosto | J2: Setiembre | K2: Octubre | L2: Noviembre | M2: Diciembre
A3: MOL. STA. ROSA | N3: Equipo de Gloria Maza
A4: MOL. FAUCETT | B4: 24796.5 | C4: 24634.5 | D4: 26511 | E4: 24890 | F4: 27204 | G4: 27075.5 | H4: 23368.5 | I4: 25739 | J4: 25870.5 | K4: 25839 | L4: 25207 | M4: 25286
A5: MOL. CALLAO | B5: 28198.5 | C5: 25303.33 | D5: 30074 | E5: 29095 | F5: 31260 | G5: 29938 | H5: 27813.95 | I5: 29947.35 | J5: 28619.77 | K5: 27409 | L5: 26309 | M5: 26620
A6: FIDEERIA LIMA | B6: 23226 | C6: 21309.5 | D6: 23675.5 | E6: 21809 | F6: 23963.5 | G6: 24721.5 | H6: 21160 | I6: 23829 | J6: 23275 | K6: 22075 | L6: 23900 | M6: 22458
A7: FIDEERIA ALIANZA
A8: DETERGENTES | B8: 26353 | C8: 21935 | D8: 27289 | E8: 23576 | F8: 26466 | G8: 27811 | H8: 26207.5 | I8: 27985 | J8: 25943 | K8: 26693 | L8: 25683 | M8: 26078
A9: SIDSUR | B9: 37583.5 | C9: 30917.5 | D9: 40576 | E9: 36556.5 | F9: 42297.5 | G9: 41371.3 | H9: 45526 | I9: 47979 | J9: 47529 | K9: 46601 | L9: 44652 | M9: 46791
A10: GALLETERA CALLAO | B10: 68717.6 | C10: 52553.65 | D10: 69514.02 | E10: 53527 | F10: 70541.05 | G10: 61611.74 | H10: 66082.5 | I10: 83672 | J10: 80963.41 | K10: 79662 | L10: 75868 | M10: 65877
A11: BAL. LIMA
A12: BAL. TRUJILLO
A13: BAL. TUMBES
A14: COPSA | B14: 156121.92 | C14: 144662.85 | D14: 166573.3 | E14: 149238.45 | F14: 167711.35 | G14: 160490.55 | H14: 147957.95 | I14: 148480.25 | J14: 156737.72 | K14: 150586 | L14: 149171 | M14: 152542
A15: CDC | B15: 120873.32 | C15: 111404.67 | D15: 123690 | E15: 116773 | F15: 126212.58 | G15: 109746.01 | H15: 114328.75 | I15: 119207.67 | J15: 124279.02 | K15: 125367 | L15: 124519 | M15: 125180
A16: CDR AREQUIPA | B16: 19316.3 | C16: 18066 | D16: 19160.25 | E16: 16959 | F16: 18965.25 | G16: 18928.5 | H16: 17740.5 | I16: 18109 | J16: 17948 | K16: 17546 | L16: 17237 | M16: 17108
A17: CDR PIURA | B17: 4520 | C17: 4510 | D17: 4797 | E17: 4707 | F17: 4822 | G17: 4754 | H17: 4674 | I17: 5239 | J17: 2466 | K17: 4556 | L17: 4410 | M17: 4990
A18: CDR TRUJILLO | B18: 7192 | C18: 6730 | D18: 7020 | E18: 6217 | F18: 6762 | G18: 6857 | H18: 6635 | I18: 6742 | J18: 7010 | K18: 7099 | L18: 6461 | M18: 6761
A19: Otras Sucursales | B19: 19850.5 | C19: 18348 | D19: 19551 | E19: 19217 | F19: 18783.5 | G19: 19022 | H19: 18391.1 | I19: 17915 | J19: 18336.55 | K19: 17739 | L19: 17363 | M19: 18279
A20: Ventas | B20: 1064 | C20: 1064 | D20: 1064 | E20: 864 | F20: 864 | G20: 1064 | H20: 1196 | I20: 1064 | J20: 1064 | K20: 1064 | L20: 1064 | M20: 1064
A21: Marketing | B21: 1800 | C21: 1600 | D21: 2200 | E21: 2000 | F21: 2000 | H21: 1800 | I21: 1932 | J21: 1732 | K21: 1732 | L21: 1732 | M21: 1732
A22: Oficina Central | B22: 276508 | C22: 277368 | D22: 279628 | E22: 281424 | F22: 284956 | G22: 289488 | H22: 288680 | I22: 288148 | J22: 289820 | K22: 288330 | L22: 274740 | M22: 276857
A25: Total | B25: =SUM(B3:B24) -> 816121.14 | C25: =SUM(C3:C24) -> 760407 | D25: =SUM(D3:D24) -> 841323.07 | E25: =SUM(E3:E24) -> 786852.95 | F25: =SUM(F3:F24) -> 852808.73 | G25: =SUM(G3:G24) -> 822879.1 | H25: =SUM(H3:H24) -> 811561.75 | I25: =SUM(I3:I24) -> 845988.27 | ... M25: =SUM(M3:M24) -> 817623 | N25: Copiar tal cual archivo de Gloria . No descontar Detergentes
A27: Jaboneria | B27: 8353 | C27: 8353 | D27: 8353 | E27: 8353 | F27: 8353 | G27: 8353 | H27: 8353 | I27: 8353 | J27: 8353 | K27: 8353 | L27: 8353 | M27: 8353
A28: Almacenes | B28: 15371.25 | C28: 13784.75 | D28: 16963.1 | E28: 14391 | F28: 16481.5 | G28: 15582 | H28: 14164.6 | I28: 14618 | J28: 14872.8 | K28: 14872.8 | L28: 13569 | M28: 14970 | N28: =SUM(B28:M28) -> 179640.8
N29: total
A30: VITAPRO TUMBES | N30: =SUM(B30:M30) -> 0
N31: total
A32: DISTRIBUCION PAITA | B32: 1543.17 | C32: 1330.67 | D32: 1592.7 | E32: 1403.93 | F32: 1600.83 | G32: 1725.47 | H32: 1538.83 | I32: 1547.15 | J32: 1448.66 | K32: 1393.2 | L32: 1492.94 | M32: 1516.8 | N32: =SUM(B32:M32) -> 18134.35
A34: Almacen Insumos&Envases-MB | B34: 230 | C34: 202 | D34: 216 | E34: 216 | F34: 0 | G34: 0 | H34: 0 | I34: 0 | J34: 0 | K34: 0 | L34: 0 | M34: 0 | N34: =SUM(B34:M34) -> 864 | O34: =+N34+N35 -> 21479.04 | P34: =+O34*6 -> 128874.24
A35: Almacen Insumos&Envases-TEAL | B35: 1714.48 | C35: 1445.83 | D35: 145.5 | E35: 1165.38 | F35: 1736.08 | G35: 2263.3 | H35: 2171.73 | I35: 2263.3 | J35: 1948.78 | K35: 2023.07 | L35: 1869 | M35: 1868.59 | N35: =SUM(B35:M35) -> 20615.04
A36: DISTRIBUCION TEAL | B36: 3623.77 | C36: 2663.25 | D36: 205.52 | E36: 2102.61 | F36: 3133.37 | G36: 2906.52 | H36: 2442.82 | I36: 2906.52 | J36: 2609.15 | K36: 2719.16 | L36: 1687 | M36: 1687 | N36: =SUM(B36:M36) -> 28686.69 | O36: =+N36*6 -> 172120.14
A37: DISTRIBUCION ITDC | B37: 6252 | C37: 6252 | D37: 6872 | E37: 6872 | F37: 6872 | G37: 6872 | H37: 6872 | I37: 6872 | J37: 6872 | K37: 6872 | L37: 6872 | M37: 6872 | N37: =SUM(B37:M37) -> 81224
A38: Almacen Insumos&Envases-ITDC | B38: 41054.93 | C38: 40646.93 | D38: 39913.2 | E38: 39913.2 | F38: 39913.2 | G38: 39913.2 | H38: 39913.2 | I38: 39913.2 | J38: 39913.2 | K38: 39913.2 | L38: 39913.2 | M38: 39913.2 | N38: =SUM(B38:M38) -> 480833.86
A39: APUDEX | B39: 14984 | C39: 15689 | D39: 15689 | E39: 15689 | F39: 15689 | G39: 15689 | H39: 15689 | I39: 15689 | J39: 15689 | K39: 15689 | L39: 15689 | M39: 15689 | N39: =SUM(B39:M39) -> 187563

Sheet HORAS HOMBRE
B1: T O T A L | BO1: P E R S O N A L T E R C E R O S (SCAST + Registros Vigilancia)
